Workbook
Name ColumnTitle13: EmployeeName[[#Headers],[ALUMNOS ]]
Name Titulo1: Enero[[#Headers],[NOMBRE Y APELLIDO]]
Name Titulo10: Octubre[[#Headers],[Nombre del empleado]]
Name Titulo11: Noviembre[[#Headers],[Nombre del empleado]]
Name Titulo12: Diciembre[[#Headers],[Nombre del empleado]]
Name Titulo2: Febrero[[#Headers],[NOMBRE Y APELLIDOS]]
Name Titulo3: Marzo[[#Headers],[Nombre del empleado]]
Name Titulo4: Abril[[#Headers],[Nombre del empleado]]
Name Titulo5: Mayo[[#Headers],[Nombre del empleado]]
Name Titulo6: Junio[[#Headers],[Nombre del empleado]]
Name Titulo7: Julio[[#Headers],[Nombre del empleado]]
Name Titulo8: Agosto[[#Headers],[Nombre del empleado]]
Name Titulo9: Septiembre[[#Headers],[Nombre del empleado]]
Name Employee_Absence_Title: Enero!$B$1
Name MonthName: Abril!$B$4
Name MonthName: Enero!$B$4
Name MonthName: Mayo!$B$4
Name MonthName: Octubre!$B$4
Name KeySick: Enero!$K$2
Name KeyVacation: Enero!$C$2
Name KeyPersonal: Enero!$G$2
Name KeyCustom2: Enero!$T$2
Name MonthName: Setiembre!$B$4
Name KeyVacationLabel: Enero!$D$2
Name KeyCustom1: Enero!$O$2
Name CalendarioAño: Enero!$AH$4
Name Key_name: Enero!$B$2
Name KeyCustom1Label: Enero!$P$2
Name KeyPersonalLabel: Enero!$H$2
Name MonthName: Noviembre!$B$4
Name MonthName: Diciembre!$B$4
Name MonthName: Febrero!$B$4
Name KeyCustom2Label: Enero!$U$2
Name MonthName: Marzo!$B$4
Name MonthName: Junio!$B$4
Name KeySickLabel: Enero!$L$2
Name MonthName: Agosto!$B$4
Name MonthName: Julio!$B$4

Sheet Enero
B1: ASISTENCIA DE ALUMNOS
B2: Claves de los tipos de Asistencia | C2: F | D2: FALTAS | G2: J | H2: JUSTIFICADA | K2: A | L2: ASISTENCIA | O2: R | P2: RECUPERACION | T2: E | U2: EVENTOS
B4: Enero | C4: MEGA SUPER BABY WOLF 3:00 | AH4: 2025
C5: =TEXT(WEEKDAY(DATE(CalendarioAño,1,1),1),"ddd") -> mié | D5: =TEXT(WEEKDAY(DATE(CalendarioAño,1,2),1),"ddd") -> jue | E5: =TEXT(WEEKDAY(DATE(CalendarioAño,1,3),1),"ddd") -> vie | F5: =TEXT(WEEKDAY(DATE(CalendarioAño,1,4),1),"ddd") -> sáb | G5: =TEXT(WEEKDAY(DATE(CalendarioAño,1,5),1),"ddd") -> dom | H5: =TEXT(WEEKDAY(DATE(CalendarioAño,1,6),1),"ddd") -> lun | I5: =TEXT(WEEKDAY(DATE(CalendarioAño,1,7),1),"ddd") -> mar | J5: =TEXT(WEEKDAY(DATE(CalendarioAño,1,8),1),"ddd") -> mié | K5: =TEXT(WEEKDAY(DATE(CalendarioAño,1,9),1),"ddd") -> jue | L5: =TEXT(WEEKDAY(DATE(CalendarioAño,1,10),1),"ddd") -> vie | M5: =TEXT(WEEKDAY(DATE(CalendarioAño,1,11),1),"ddd") -> sáb | N5: =TEXT(WEEKDAY(DATE(CalendarioAño,1,12),1),"ddd") -> dom | O5: =TEXT(WEEKDAY(DATE(CalendarioAño,1,13),1),"ddd") -> lun | P5: =TEXT(WEEKDAY(DATE(CalendarioAño,1,14),1),"ddd") -> mar | Q5: =TEXT(WEEKDAY(DATE(CalendarioAño,1,15),1),"ddd") -> mié | R5: =TEXT(WEEKDAY(DATE(CalendarioAño,1,16),1),"ddd") -> jue | S5: =TEXT(WEEKDAY(DATE(CalendarioAño,1,17),1),"ddd") -> vie | T5: =TEXT(WEEKDAY(DATE(CalendarioAño,1,18),1),"ddd") -> sáb | U5: =TEXT(WEEKDAY(DATE(CalendarioAño,1,19),1),"ddd") -> dom | V5: =TEXT(WEEKDAY(DATE(CalendarioAño,1,20),1),"ddd") -> lun | W5: =TEXT(WEEKDAY(DATE(CalendarioAño,1,21),1),"ddd") -> mar | X5: =TEXT(WEEKDAY(DATE(CalendarioAño,1,22),1),"ddd") -> mié | Y5: =TEXT(WEEKDAY(DATE(CalendarioAño,1,23),1),"ddd") -> jue | Z5: =TEXT(WEEKDAY(DATE(CalendarioAño,1,24),1),"ddd") -> vie | AA5: =TEXT(WEEKDAY(DATE(CalendarioAño,1,25),1),"ddd") -> sáb | AB5: =TEXT(WEEKDAY(DATE(CalendarioAño,1,26),1),"ddd") -> dom | AC5: =TEXT(WEEKDAY(DATE(CalendarioAño,1,27),1),"ddd") -> lun | AD5: =TEXT(WEEKDAY(DATE(CalendarioAño,1,28),1),"ddd") -> mar | AE5: =TEXT(WEEKDAY(DATE(CalendarioAño,1,29),1),"ddd") -> mié | AF5: =TEXT(WEEKDAY(DATE(CalendarioAño,1,30),1),"ddd") -> jue | AG5: =TEXT(WEEKDAY(DATE(CalendarioAño,1,31),1),"ddd") -> vie
B6: NOMBRE Y APELLIDO | C6: 1 | D6: 2 | E6: 3 | F6: 4 | G6: 5 | H6: 6 | I6: 7 | J6: 8 | K6: 9 | L6: 10 | M6: 11 | N6: 12 | O6: 13 | P6: 14 | Q6: 15 | R6: 16 | S6: 17 | T6: 18 | U6: 19 | V6: 20 | W6: 21 | X6: 22 | Y6: 23 | Z6: 24 | AA6: 25 | AB6: 26 | AC6: 27 | AD6: 28 | AE6: 29 | AF6: 30 | AG6: 31 | AH6: Número total de días
B7: ALEXANDRA GABRIELA BAUTISTA JUSTINIANO | M7: A | V7: A | AC7: A | AD7: A | AE7: A | AH7: =(COUNTA(C7:AG7)) -> 5
B8: THIAGO ABRAHAM MATIENZO TELLO | AH8: =(COUNTA(C8:AG8)) -> 0
B9: =Enero!MonthName&" Total" -> Enero Total | C9: =SUBTOTAL(103,Enero!$C$7:$C$8) -> 0 | D9: =SUBTOTAL(103,Enero!$D$7:$D$8) -> 0 | E9: =SUBTOTAL(103,Enero!$E$7:$E$8) -> 0 | F9: =SUBTOTAL(103,Enero!$F$7:$F$8) -> 0 | G9: =SUBTOTAL(103,Enero!$G$7:$G$8) -> 0 | H9: =SUBTOTAL(103,Enero!$H$7:$H$8) -> 0 | I9: =SUBTOTAL(103,Enero!$I$7:$I$8) -> 0 | J9: =SUBTOTAL(103,Enero!$J$7:$J$8) -> 0 | K9: =SUBTOTAL(103,Enero!$K$7:$K$8) -> 0 | L9: =SUBTOTAL(103,Enero!$L$7:$L$8) -> 0 | M9: =SUBTOTAL(103,Enero!$M$7:$M$8) -> 1 | N9: =SUBTOTAL(103,Enero!$N$7:$N$8) -> 0 | O9: =SUBTOTAL(103,Enero!$O$7:$O$8) -> 0 | P9: =SUBTOTAL(103,Enero!$P$7:$P$8) -> 0 | Q9: =SUBTOTAL(103,Enero!$Q$7:$Q$8) -> 0 | R9: =SUBTOTAL(103,Enero!$R$7:$R$8) -> 0 | S9: =SUBTOTAL(103,Enero!$S$7:$S$8) -> 0 | T9: =SUBTOTAL(103,Enero!$T$7:$T$8) -> 0 | U9: =SUBTOTAL(103,Enero!$U$7:$U$8) -> 0 | V9: =SUBTOTAL(103,Enero!$V$7:$V$8) -> 1 | W9: =SUBTOTAL(103,Enero!$W$7:$W$8) -> 0 | X9: =SUBTOTAL(103,Enero!$X$7:$X$8) -> 0 | Y9: =SUBTOTAL(103,Enero!$Y$7:$Y$8) -> 0 | Z9: =SUBTOTAL(103,Enero!$Z$7:$Z$8) -> 0 | AA9: =SUBTOTAL(103,Enero!$AA$7:$AA$8) -> 0 | AB9: =SUBTOTAL(103,Enero!$AB$7:$AB$8) -> 0 | AC9: =SUBTOTAL(103,Enero!$AC$7:$AC$8) -> 1 | AD9: =SUBTOTAL(103,Enero!$AD$7:$AD$8) -> 1 | AE9: =SUBTOTAL(103,Enero!$AE$7:$AE$8) -> 1 | AF9: =SUBTOTAL(103,Enero!$AF$7:$AF$8) -> 0 | AG9: =SUBTOTAL(103,Enero!$AG$7:$AG$8) -> 0
B11: Enero | C11: SUPER BABY WOLF 3:30 | AH11: 2025
C12: =TEXT(WEEKDAY(DATE(CalendarioAño,1,1),1),"ddd") -> mié | D12: =TEXT(WEEKDAY(DATE(CalendarioAño,1,2),1),"ddd") -> jue | E12: =TEXT(WEEKDAY(DATE(CalendarioAño,1,3),1),"ddd") -> vie | F12: =TEXT(WEEKDAY(DATE(CalendarioAño,1,4),1),"ddd") -> sáb | G12: =TEXT(WEEKDAY(DATE(CalendarioAño,1,5),1),"ddd") -> dom | H12: =TEXT(WEEKDAY(DATE(CalendarioAño,1,6),1),"ddd") -> lun | I12: =TEXT(WEEKDAY(DATE(CalendarioAño,1,7),1),"ddd") -> mar | J12: =TEXT(WEEKDAY(DATE(CalendarioAño,1,8),1),"ddd") -> mié | K12: =TEXT(WEEKDAY(DATE(CalendarioAño,1,9),1),"ddd") -> jue | L12: =TEXT(WEEKDAY(DATE(CalendarioAño,1,10),1),"ddd") -> vie | M12: =TEXT(WEEKDAY(DATE(CalendarioAño,1,11),1),"ddd") -> sáb | N12: =TEXT(WEEKDAY(DATE(CalendarioAño,1,12),1),"ddd") -> dom | O12: =TEXT(WEEKDAY(DATE(CalendarioAño,1,13),1),"ddd") -> lun | P12: =TEXT(WEEKDAY(DATE(CalendarioAño,1,14),1),"ddd") -> mar | Q12: =TEXT(WEEKDAY(DATE(CalendarioAño,1,15),1),"ddd") -> mié | R12: =TEXT(WEEKDAY(DATE(CalendarioAño,1,16),1),"ddd") -> jue | S12: =TEXT(WEEKDAY(DATE(CalendarioAño,1,17),1),"ddd") -> vie | T12: =TEXT(WEEKDAY(DATE(CalendarioAño,1,18),1),"ddd") -> sáb | U12: =TEXT(WEEKDAY(DATE(CalendarioAño,1,19),1),"ddd") -> dom | V12: =TEXT(WEEKDAY(DATE(CalendarioAño,1,20),1),"ddd") -> lun | W12: =TEXT(WEEKDAY(DATE(CalendarioAño,1,21),1),"ddd") -> mar | X12: =TEXT(WEEKDAY(DATE(CalendarioAño,1,22),1),"ddd") -> mié | Y12: =TEXT(WEEKDAY(DATE(CalendarioAño,1,23),1),"ddd") -> jue | Z12: =TEXT(WEEKDAY(DATE(CalendarioAño,1,24),1),"ddd") -> vie | AA12: =TEXT(WEEKDAY(DATE(CalendarioAño,1,25),1),"ddd") -> sáb | AB12: =TEXT(WEEKDAY(DATE(CalendarioAño,1,26),1),"ddd") -> dom | AC12: =TEXT(WEEKDAY(DATE(CalendarioAño,1,27),1),"ddd") -> lun | AD12: =TEXT(WEEKDAY(DATE(CalendarioAño,1,28),1),"ddd") -> mar | AE12: =TEXT(WEEKDAY(DATE(CalendarioAño,1,29),1),"ddd") -> mié | AF12: =TEXT(WEEKDAY(DATE(CalendarioAño,1,30),1),"ddd") -> jue | AG12: =TEXT(WEEKDAY(DATE(CalendarioAño,1,31),1),"ddd") -> vie
B13: NOMBRE Y APELLIDO | C13: 1 | D13: 2 | E13: 3 | F13: 4 | G13: 5 | H13: 6 | I13: 7 | J13: 8 | K13: 9 | L13: 10 | M13: 11 | N13: 12 | O13: 13 | P13: 14 | Q13: 15 | R13: 16 | S13: 17 | T13: 18 | U13: 19 | V13: 20 | W13: 21 | X13: 22 | Y13: 23 | Z13: 24 | AA13: 25 | AB13: 26 | AC13: 27 | AD13: 28 | AE13: 29 | AF13: 30 | AG13: 31 | AH13: Número total de días
B14: EMANUEL DAVID RIVAS PAETAN | I14: A | M14: A | T14: A | W14: A | AA14: A | AF14: A | AH14: =(COUNTA(C14:AG14)) -> 6
B15: LUA GIANELLA RODRIGUEZ CASTRO | K15: A | P15: A | R15: A | W15: A | AF15: A | AH15: =(COUNTA(C15:AG15)) -> 5
B16: MABEL TOMAS PEDRAZA | P16: A | R16: A | W16: A | Y16: A | AD16: A | AF16: A | AH16: =(COUNTA(C16:AG16)) -> 6
B17: TADEO BASTIAN REYES RAMIREZ | K17: A | M17: A | R17: A | T17: A | W17: A | Y17: A | AD17: A | AF17: A | AH17: =(COUNTA(C17:AG17)) -> 8
B18: MATEO AUGUSTO RIVAS MERINO | I18: A | K18: A | M18: A | P18: A | R18: A | W18: A | Y18: A | AF18: A | AH18: =(COUNTA(C18:AG18)) -> 8
B19: GiANELLA NICOLE CALDERON AGUIRRE | I19: A | P19: A | W19: A | AH19: =(COUNTA(C19:AG19)) -> 3
B20: FABIAN FABRIZIO ABARCA ANGELES | AF20: A
B21: ALBA LUCIA CABALLERO SORIANO | AD21: A | AH21: 1
B22: =Enero!MonthName&" Total" -> Enero Total | C22: =SUBTOTAL(103,Enero!$C$7:$C$8) -> 0 | D22: =SUBTOTAL(103,Enero!$D$7:$D$8) -> 0 | E22: =SUBTOTAL(103,Enero!$E$7:$E$8) -> 0 | G22: =SUBTOTAL(103,Enero!$G$7:$G$8) -> 0 | H22: =SUBTOTAL(103,Enero!$H$7:$H$8) -> 0 | I22: 3 | J22: =SUBTOTAL(103,Enero!$J$7:$J$8) -> 0 | K22: 3 | L22: =SUBTOTAL(103,Enero!$L$7:$L$8) -> 0 | M22: 3 | N22: =SUBTOTAL(103,Enero!$N$7:$N$8) -> 0 | O22: =SUBTOTAL(103,Enero!$O$7:$O$8) -> 0 | P22: 4 | Q22: =SUBTOTAL(103,Enero!$Q$7:$Q$8) -> 0 | R22: 4 | S22: =SUBTOTAL(103,Enero!$S$7:$S$8) -> 0 | T22: 2 | U22: =SUBTOTAL(103,Enero!$U$7:$U$8) -> 0 | W22: 6 | X22: =SUBTOTAL(103,Enero!$X$7:$X$8) -> 0 | Y22: 3 | Z22: =SUBTOTAL(103,Enero!$Z$7:$Z$8) -> 0 | AA22: 1 | AB22: =SUBTOTAL(103,Enero!$AB$7:$AB$8) -> 0 | AC22: =SUBTOTAL(103,Enero!$AC$7:$AC$8) -> 1 | AD22: =SUBTOTAL(103,Enero!$AD$7:$AD$8) -> 1 | AE22: =SUBTOTAL(103,Enero!$AE$7:$AE$8) -> 1 | AF22: =SUBTOTAL(103,Enero!$AF$7:$AF$8) -> 0 | AG22: =SUBTOTAL(103,Enero!$AG$7:$AG$8) -> 0 | AH22: =SUM(C22:AG22) -> 32
B25: Enero | C25: SUPER BABY WOLF 4:00 | AH25: 2025
C26: =TEXT(WEEKDAY(DATE(CalendarioAño,1,1),1),"ddd") -> mié | D26: =TEXT(WEEKDAY(DATE(CalendarioAño,1,2),1),"ddd") -> jue | E26: =TEXT(WEEKDAY(DATE(CalendarioAño,1,3),1),"ddd") -> vie | F26: =TEXT(WEEKDAY(DATE(CalendarioAño,1,4),1),"ddd") -> sáb | G26: =TEXT(WEEKDAY(DATE(CalendarioAño,1,5),1),"ddd") -> dom | H26: =TEXT(WEEKDAY(DATE(CalendarioAño,1,6),1),"ddd") -> lun | I26: =TEXT(WEEKDAY(DATE(CalendarioAño,1,7),1),"ddd") -> mar | J26: =TEXT(WEEKDAY(DATE(CalendarioAño,1,8),1),"ddd") -> mié | K26: =TEXT(WEEKDAY(DATE(CalendarioAño,1,9),1),"ddd") -> jue | L26: =TEXT(WEEKDAY(DATE(CalendarioAño,1,10),1),"ddd") -> vie | M26: =TEXT(WEEKDAY(DATE(CalendarioAño,1,11),1),"ddd") -> sáb | N26: =TEXT(WEEKDAY(DATE(CalendarioAño,1,12),1),"ddd") -> dom | O26: =TEXT(WEEKDAY(DATE(CalendarioAño,1,13),1),"ddd") -> lun | P26: =TEXT(WEEKDAY(DATE(CalendarioAño,1,14),1),"ddd") -> mar | Q26: =TEXT(WEEKDAY(DATE(CalendarioAño,1,15),1),"ddd") -> mié | R26: =TEXT(WEEKDAY(DATE(CalendarioAño,1,16),1),"ddd") -> jue | S26: =TEXT(WEEKDAY(DATE(CalendarioAño,1,17),1),"ddd") -> vie | T26: =TEXT(WEEKDAY(DATE(CalendarioAño,1,18),1),"ddd") -> sáb | U26: =TEXT(WEEKDAY(DATE(CalendarioAño,1,19),1),"ddd") -> dom | V26: =TEXT(WEEKDAY(DATE(CalendarioAño,1,20),1),"ddd") -> lun | W26: =TEXT(WEEKDAY(DATE(CalendarioAño,1,21),1),"ddd") -> mar | X26: =TEXT(WEEKDAY(DATE(CalendarioAño,1,22),1),"ddd") -> mié | Y26: =TEXT(WEEKDAY(DATE(CalendarioAño,1,23),1),"ddd") -> jue | Z26: =TEXT(WEEKDAY(DATE(CalendarioAño,1,24),1),"ddd") -> vie | AA26: =TEXT(WEEKDAY(DATE(CalendarioAño,1,25),1),"ddd") -> sáb | AB26: =TEXT(WEEKDAY(DATE(CalendarioAño,1,26),1),"ddd") -> dom | AC26: =TEXT(WEEKDAY(DATE(CalendarioAño,1,27),1),"ddd") -> lun | AD26: =TEXT(WEEKDAY(DATE(CalendarioAño,1,28),1),"ddd") -> mar | AE26: =TEXT(WEEKDAY(DATE(CalendarioAño,1,29),1),"ddd") -> mié | AF26: =TEXT(WEEKDAY(DATE(CalendarioAño,1,30),1),"ddd") -> jue | AG26: =TEXT(WEEKDAY(DATE(CalendarioAño,1,31),1),"ddd") -> vie
B27: NOMBRE Y APELLIDO | C27: 1 | D27: 2 | E27: 3 | F27: 4 | G27: 5 | H27: 6 | I27: 7 | J27: 8 | K27: 9 | L27: 10 | M27: 11 | N27: 12 | O27: 13 | P27: 14 | Q27: 15 | R27: 16 | S27: 17 | T27: 18 | U27: 19 | V27: 20 | W27: 21 | X27: 22 | Y27: 23 | Z27: 24 | AA27: 25 | AB27: 26 | AC27: 27 | AD27: 28 | AE27: 29 | AF27: 30 | AG27: 31 | AH27: Número total de días
B28: ALESSIO VEGARA EZETA | I28: A | O28: A | S28: A | V28: A | Z28: A | AC28: A | AG28: A | AH28: =(COUNTA(C28:AG28)) -> 7
B29: ALEJANDRO OCTAVIO ALEGRIA YUPANQUI | I29: A | K29: A | P29: A | R29: A | W29: A | Y29: A | AD29: A | AF29: A | AH29: =(COUNTA(C29:AG29)) -> 8
B30: MARCELO SANTOS URBANO | I30: A | M30: A | P30: A | T30: A | W30: A | AE30: A | AH30: =(COUNTA(C30:AG30)) -> 6
B31: NAELAH SOLIS CORDEÑA | I31: A | K31: A | P31: A | R31: A | AH31: =(COUNTA(C31:AG31)) -> 4
B32: LIAM GAEL PABLO CUEVA | I32: A | M32: A | P32: A | R32: A | T32: A | W32: A | Y32: A | AD32: A | AF32: A | AH32: =(COUNTA(C32:AG32)) -> 9
B33: ISABELLA VALENTINA GUINEA CERDAN | I33: A | K33: A | P33: A | W33: A | Y33: A | AD33: A | AF33: A | AH33: =(COUNTA(C33:AG33)) -> 7
B34: VALENTINA FLAVIA VALDIVIESZO ROMAN | J34: A | L34: A | P34: A | S34: A | W34: A | Z34: A | AC34: A | AD34: A | AH34: =(COUNTA(C34:AG34)) -> 8
B35: FERNANDA ALEXA SOLES GUTIERREZ | J35: A | L35: A | AE35: A | AH35: =(COUNTA(C35:AG35)) -> 3
B36: CAMILA MAUREEN GARCIA VEGA | J36: A | L36: A | O36: A | Q36: A | V36: A | X36: A | AD36: A | AH36: =(COUNTA(C36:AG36)) -> 7
B37: CATALINA MARIA ROMERO MALPICA | K37: A | M37: A | P37: A | S37: A | W37: A | AH37: =(COUNTA(C37:AG37)) -> 5
B38: JULIETA BELLIDO HUAPAYA | K38: A | P38: A | R38: A | Y38: A | AH38: =(COUNTA(C38:AG38)) -> 4
B39: KENSHIN GUILLERMO ALVA TAKAYAMA | K39: A | R39: A | T39: A | Y39: A | AH39: =(COUNTA(C39:AG39)) -> 4
B40: DARIUS ABEL ALEMAN SAVEDRA | L40: A | S40: A | T40: A | Z40: A | AG40: A | AH40: =(COUNTA(C40:AG40)) -> 5
B41: JUAN SALVADOR VALAQNIA CEVEDOR | M41: A | T41: A | AH41: =(COUNTA(C41:AG41)) -> 2
B42: DANNA GAELA BACA HUAMANI | S42: A | AH42: =(COUNTA(C42:AG42)) -> 1
B43: =Enero!MonthName&" Total" -> Enero Total | C43: =SUBTOTAL(103,Enero!$C$7:$C$8) -> 0 | D43: =SUBTOTAL(103,Enero!$D$7:$D$8) -> 0 | E43: =SUBTOTAL(103,Enero!$E$7:$E$8) -> 0 | G43: =SUBTOTAL(103,Enero!$G$7:$G$8) -> 0 | H43: =SUBTOTAL(103,Enero!$H$7:$H$8) -> 0 | I43: 6 | J43: 3 | K43: 6 | L43: 4 | M43: 4 | N43: =SUBTOTAL(103,Enero!$N$7:$N$8) -> 0 | O43: 2 | P43: 8 | Q43: 1 | R43: 5 | S43: 5 | T43: 5 | U43: =SUBTOTAL(103,Enero!$U$7:$U$8) -> 0 | V43: 2 | W43: 6 | X43: 1 | Y43: 5 | Z43: 3 | AA43: =SUBTOTAL(103,Enero!$AA$7:$AA$8) -> 0 | AB43: =SUBTOTAL(103,Enero!$AB$7:$AB$8) -> 0 | AC43: =SUBTOTAL(103,Enero!$AC$7:$AC$8) -> 1 | AD43: =SUBTOTAL(103,Enero!$AD$7:$AD$8) -> 1 | AE43: =SUBTOTAL(103,Enero!$AE$7:$AE$8) -> 1 | AF43: =SUBTOTAL(103,Enero!$AF$7:$AF$8) -> 0 | AG43: =SUBTOTAL(103,Enero!$AG$7:$AG$8) -> 0 | AH43: =SUM(C43:AG43) -> 69
B45: Enero | C45: BABY WOLF 4:30 | AH45: 2025
...

Sheet Febrero
B1: ASISTENCIA DE ALUMNOS
B2: Claves de los tipos de Asistencias | C2: F | D2: FALTAS | G2: J | H2: JUSTIFICADAS | K2: A | L2: ASISTENCIA | O2: R | P2: RECUPERACION | T2: E | U2: EVENTOS
B4: Febrero | C4: MEGA SUPER BABY WOLF 3:00 | AH4: 2025
C5: =TEXT(WEEKDAY(DATE(CalendarioAño,2,1),1),"ddd") -> sáb | D5: =TEXT(WEEKDAY(DATE(CalendarioAño,2,2),1),"ddd") -> dom | E5: =TEXT(WEEKDAY(DATE(CalendarioAño,2,3),1),"ddd") -> lun | F5: =TEXT(WEEKDAY(DATE(CalendarioAño,2,4),1),"ddd") -> mar | G5: =TEXT(WEEKDAY(DATE(CalendarioAño,2,5),1),"ddd") -> mié | H5: =TEXT(WEEKDAY(DATE(CalendarioAño,2,6),1),"ddd") -> jue | I5: =TEXT(WEEKDAY(DATE(CalendarioAño,2,7),1),"ddd") -> vie | J5: =TEXT(WEEKDAY(DATE(CalendarioAño,2,8),1),"ddd") -> sáb | K5: =TEXT(WEEKDAY(DATE(CalendarioAño,2,9),1),"ddd") -> dom | L5: =TEXT(WEEKDAY(DATE(CalendarioAño,2,10),1),"ddd") -> lun | M5: =TEXT(WEEKDAY(DATE(CalendarioAño,2,11),1),"ddd") -> mar | N5: =TEXT(WEEKDAY(DATE(CalendarioAño,2,12),1),"ddd") -> mié | O5: =TEXT(WEEKDAY(DATE(CalendarioAño,2,13),1),"ddd") -> jue | P5: =TEXT(WEEKDAY(DATE(CalendarioAño,2,14),1),"ddd") -> vie | Q5: =TEXT(WEEKDAY(DATE(CalendarioAño,2,15),1),"ddd") -> sáb | R5: =TEXT(WEEKDAY(DATE(CalendarioAño,2,16),1),"ddd") -> dom | S5: =TEXT(WEEKDAY(DATE(CalendarioAño,2,17),1),"ddd") -> lun | T5: =TEXT(WEEKDAY(DATE(CalendarioAño,2,18),1),"ddd") -> mar | U5: =TEXT(WEEKDAY(DATE(CalendarioAño,2,19),1),"ddd") -> mié | V5: =TEXT(WEEKDAY(DATE(CalendarioAño,2,20),1),"ddd") -> jue | W5: =TEXT(WEEKDAY(DATE(CalendarioAño,2,21),1),"ddd") -> vie | X5: =TEXT(WEEKDAY(DATE(CalendarioAño,2,22),1),"ddd") -> sáb | Y5: =TEXT(WEEKDAY(DATE(CalendarioAño,2,23),1),"ddd") -> dom | Z5: =TEXT(WEEKDAY(DATE(CalendarioAño,2,24),1),"ddd") -> lun | AA5: =TEXT(WEEKDAY(DATE(CalendarioAño,2,25),1),"ddd") -> mar | AB5: =TEXT(WEEKDAY(DATE(CalendarioAño,2,26),1),"ddd") -> mié | AC5: =TEXT(WEEKDAY(DATE(CalendarioAño,2,27),1),"ddd") -> jue | AD5: =TEXT(WEEKDAY(DATE(CalendarioAño,2,28),1),"ddd") -> vie | AE5: =TEXT(WEEKDAY(DATE(CalendarioAño,2,29),1),"ddd") -> sáb
B6: NOMBRE Y APELLIDOS | C6: 1 | D6: 2 | E6: 3 | F6: 4 | G6: 5 | H6: 6 | I6: 7 | J6: 8 | K6: 9 | L6: 10 | M6: 11 | N6: 12 | O6: 13 | P6: 14 | Q6: 15 | R6: 16 | S6: 17 | T6: 18 | U6: 19 | V6: 20 | W6: 21 | X6: 22 | Y6: 23 | Z6: 24 | AA6: 25 | AB6: 26 | AC6: 27 | AD6: 28 | AE6: 29 | AH6: Número total de días
B7: DARIO | O7: A | Q7: A | T7: A | X7: A | AH7: 4
B8: THIAGO ABRAHAM MATIENZO TELLO | O8: A | T8: A | V8: A | X8: A | AH8: 4
B9: MATEO JOSEPH HUATAY | W9: A | AD9: A | AH9: 2
B16: =Febrero!MonthName&" Total" -> Febrero Total | AH16: =SUM(C16:AG16) -> 0
B18: Febrero | C18: SUPER BABY WOLF 3:30 | AH18: 2025
C19: =TEXT(WEEKDAY(DATE(CalendarioAño,2,1),1),"ddd") -> sáb | D19: =TEXT(WEEKDAY(DATE(CalendarioAño,2,2),1),"ddd") -> dom | E19: =TEXT(WEEKDAY(DATE(CalendarioAño,2,3),1),"ddd") -> lun | F19: =TEXT(WEEKDAY(DATE(CalendarioAño,2,4),1),"ddd") -> mar | G19: =TEXT(WEEKDAY(DATE(CalendarioAño,2,5),1),"ddd") -> mié | H19: =TEXT(WEEKDAY(DATE(CalendarioAño,2,6),1),"ddd") -> jue | I19: =TEXT(WEEKDAY(DATE(CalendarioAño,2,7),1),"ddd") -> vie | J19: =TEXT(WEEKDAY(DATE(CalendarioAño,2,8),1),"ddd") -> sáb | K19: =TEXT(WEEKDAY(DATE(CalendarioAño,2,9),1),"ddd") -> dom | L19: =TEXT(WEEKDAY(DATE(CalendarioAño,2,10),1),"ddd") -> lun | M19: =TEXT(WEEKDAY(DATE(CalendarioAño,2,11),1),"ddd") -> mar | N19: =TEXT(WEEKDAY(DATE(CalendarioAño,2,12),1),"ddd") -> mié | O19: =TEXT(WEEKDAY(DATE(CalendarioAño,2,13),1),"ddd") -> jue | P19: =TEXT(WEEKDAY(DATE(CalendarioAño,2,14),1),"ddd") -> vie | Q19: =TEXT(WEEKDAY(DATE(CalendarioAño,2,15),1),"ddd") -> sáb | R19: =TEXT(WEEKDAY(DATE(CalendarioAño,2,16),1),"ddd") -> dom | S19: =TEXT(WEEKDAY(DATE(CalendarioAño,2,17),1),"ddd") -> lun | T19: =TEXT(WEEKDAY(DATE(CalendarioAño,2,18),1),"ddd") -> mar | U19: =TEXT(WEEKDAY(DATE(CalendarioAño,2,19),1),"ddd") -> mié | V19: =TEXT(WEEKDAY(DATE(CalendarioAño,2,20),1),"ddd") -> jue | W19: =TEXT(WEEKDAY(DATE(CalendarioAño,2,21),1),"ddd") -> vie | X19: =TEXT(WEEKDAY(DATE(CalendarioAño,2,22),1),"ddd") -> sáb | Y19: =TEXT(WEEKDAY(DATE(CalendarioAño,2,23),1),"ddd") -> dom | Z19: =TEXT(WEEKDAY(DATE(CalendarioAño,2,24),1),"ddd") -> lun | AA19: =TEXT(WEEKDAY(DATE(CalendarioAño,2,25),1),"ddd") -> mar | AB19: =TEXT(WEEKDAY(DATE(CalendarioAño,2,26),1),"ddd") -> mié | AC19: =TEXT(WEEKDAY(DATE(CalendarioAño,2,27),1),"ddd") -> jue | AD19: =TEXT(WEEKDAY(DATE(CalendarioAño,2,28),1),"ddd") -> vie | AE19: =TEXT(WEEKDAY(DATE(CalendarioAño,2,29),1),"ddd") -> sáb
B20: NOMBRE Y APELLIDOS | C20: 1 | D20: 2 | E20: 3 | F20: 4 | G20: 5 | H20: 6 | I20: 7 | J20: 8 | K20: 9 | L20: 10 | M20: 11 | N20: 12 | O20: 13 | P20: 14 | Q20: 15 | R20: 16 | S20: 17 | T20: 18 | U20: 19 | V20: 20 | W20: 21 | X20: 22 | Y20: 23 | Z20: 24 | AA20: 25 | AB20: 26 | AC20: 27 | AD20: 28 | AE20: 29 | AH20: Número total de días
B21: EMANUEL DAVID RIVAS PAETAN | C21: A | J21: A | M21: A | Q21: A | V21: A | X21: A | Z21: A | AB21: A | AC21: A | AD21: A
B22: LUA GIANELLA RODRIGUEZ CASTRO | H22: A | M22: A | T22: A | V22: A | AC22: A | AH22: 5
B23: TADEO BASTIAN REYES RAMIREZ | H23: A | M23: A | V23: A | X23: A | AH23: 4
B24: MATEO AUGUSTO RIVAS MERINO | H24: A | M24: A | O24: A | T24: A | V24: A | AC24: A
B25: MAR PORTOCARRERO BERNAOLA | I25: A | J25: A | N25: A | P25: A | X25: A | AH25: 5
B26: MICAELA PORTOCARRERO BERNAOLA | I26: A | J26: A | N26: A | P26: A | X26: A | AH26: 5
B27: MABEL TOMAS PEDRAZA | M27: A | O27: A
B28: ALEXANDRA GABRIELA BAUTISTA JUSTINIANO | AB28: A | AD28: A | AH28: 2
B29: MARIA FERNANDA ORBEGOSO LOPEZ | AC29: A
B30: =Febrero!MonthName&" Total" -> Febrero Total | AH30: =SUM(C30:AG30) -> 0
B32: Febrero | C32: SUPER BABY WOLF 4:00 | AH32: 2025
C33: =TEXT(WEEKDAY(DATE(CalendarioAño,2,1),1),"ddd") -> sáb | D33: =TEXT(WEEKDAY(DATE(CalendarioAño,2,2),1),"ddd") -> dom | E33: =TEXT(WEEKDAY(DATE(CalendarioAño,2,3),1),"ddd") -> lun | F33: =TEXT(WEEKDAY(DATE(CalendarioAño,2,4),1),"ddd") -> mar | G33: =TEXT(WEEKDAY(DATE(CalendarioAño,2,5),1),"ddd") -> mié | H33: =TEXT(WEEKDAY(DATE(CalendarioAño,2,6),1),"ddd") -> jue | I33: =TEXT(WEEKDAY(DATE(CalendarioAño,2,7),1),"ddd") -> vie | J33: =TEXT(WEEKDAY(DATE(CalendarioAño,2,8),1),"ddd") -> sáb | K33: =TEXT(WEEKDAY(DATE(CalendarioAño,2,9),1),"ddd") -> dom | L33: =TEXT(WEEKDAY(DATE(CalendarioAño,2,10),1),"ddd") -> lun | M33: =TEXT(WEEKDAY(DATE(CalendarioAño,2,11),1),"ddd") -> mar | N33: =TEXT(WEEKDAY(DATE(CalendarioAño,2,12),1),"ddd") -> mié | O33: =TEXT(WEEKDAY(DATE(CalendarioAño,2,13),1),"ddd") -> jue | P33: =TEXT(WEEKDAY(DATE(CalendarioAño,2,14),1),"ddd") -> vie | Q33: =TEXT(WEEKDAY(DATE(CalendarioAño,2,15),1),"ddd") -> sáb | R33: =TEXT(WEEKDAY(DATE(CalendarioAño,2,16),1),"ddd") -> dom | S33: =TEXT(WEEKDAY(DATE(CalendarioAño,2,17),1),"ddd") -> lun | T33: =TEXT(WEEKDAY(DATE(CalendarioAño,2,18),1),"ddd") -> mar | U33: =TEXT(WEEKDAY(DATE(CalendarioAño,2,19),1),"ddd") -> mié | V33: =TEXT(WEEKDAY(DATE(CalendarioAño,2,20),1),"ddd") -> jue | W33: =TEXT(WEEKDAY(DATE(CalendarioAño,2,21),1),"ddd") -> vie | X33: =TEXT(WEEKDAY(DATE(CalendarioAño,2,22),1),"ddd") -> sáb | Y33: =TEXT(WEEKDAY(DATE(CalendarioAño,2,23),1),"ddd") -> dom | Z33: =TEXT(WEEKDAY(DATE(CalendarioAño,2,24),1),"ddd") -> lun | AA33: =TEXT(WEEKDAY(DATE(CalendarioAño,2,25),1),"ddd") -> mar | AB33: =TEXT(WEEKDAY(DATE(CalendarioAño,2,26),1),"ddd") -> mié | AC33: =TEXT(WEEKDAY(DATE(CalendarioAño,2,27),1),"ddd") -> jue | AD33: =TEXT(WEEKDAY(DATE(CalendarioAño,2,28),1),"ddd") -> vie | AE33: =TEXT(WEEKDAY(DATE(CalendarioAño,2,29),1),"ddd") -> sáb
B34: NOMBRE Y APELLIDOS | C34: 1 | D34: 2 | E34: 3 | F34: 4 | G34: 5 | H34: 6 | I34: 7 | J34: 8 | K34: 9 | L34: 10 | M34: 11 | N34: 12 | O34: 13 | P34: 14 | Q34: 15 | R34: 16 | S34: 17 | T34: 18 | U34: 19 | V34: 20 | W34: 21 | X34: 22 | Y34: 23 | Z34: 24 | AA34: 25 | AB34: 26 | AC34: 27 | AD34: 28 | AE34: 29 | AH34: Número total de días
B35: ALESSIO VEGARA EZETA | E35: A | H35: A | I35: A | L35: A | N35: A | S35: A | W35: A | Z35: A | AC35: A | AH35: 9
B36: CAMILA MAUREEN GARCIA VEGA | E36: A | G36: A | L36: A | N36: A | S36: A | U36: A | AB36: A | AH36: 7
B37: KENSHIN GUILLERMO ALVA TAKAYAMA | C37: A | F37: A | H37: A | M37: A | AA37: A | AC37: A | AH37: 6
B38: JUAN SALVADOR VALAQNIA CEVEDOR | C38: A
B39: LIAM GAEL PABLO CUEVA | C39: A | J39: A | M39: A | O39: A | Q39: A | V39: A | X39: A | AC39: A
B40: DARIUS ABEL ALEMAN SAVEDRA | C40: A
B41: ALBA LUCIA CABALLERO SORIANO | F41: A | H41: A | O41: A | T41: A | V41: A | AA41: A | AC41: A | AH41: 7
B42: VALENTINA FLAVIA VALDIVIESZO ROMAN | G42: A | H42: A | M42: A | N42: A | S42: A | U42: A | Z42: A | AB42: A | AC42: A | AD42: A
B43: CATALINA MARIA ROMERO MALPICA | I43: A | M43: A | T43: A | AD43: A | AH43: 4
B44: MARCELO SANTOS URBANO | I44: A | J44: A | M44: A | Q44: A | T44: A
B45: ISABELLA VALENTINA GUINEA CERDAN | M45: A | T45: A | V45: A
B46: FABIAN FABRIZIO ABARCA ANGELES | H46: A | M46: A | O46: A | T46: A | V46: A
B47: ALEJANDRO OCTAVIO ALEGRIA YUPANQUI | G47: A | H47: A | M47: A | O47: A | AA47: A | AC47: A
B48: GiANELLA NICOLE CALDERON AGUIRRE | T48: A | AC48: A | AH48: 2
B49: SALVADOR EFRAIN BUSTAMANTE PEREZ | Q49: A | X49: A | AH49: 2
...

Sheet Marzo
B1: ASISTENCIA DE ALUMNOS
B2: Claves de los tipos de Asistencia | C2: V | D2: Vacaciones | G2: P | H2: Personal | K2: A | L2: Asistencia | O2: R | P2: Recuperacion | T2: E | U2: Eventos
B4: Marzo | C4: MEGA SUPER BABY WOLF 3:00 PM | AH4: =CalendarioAño -> 2025
C5: =TEXT(WEEKDAY(DATE(CalendarioAño,3,1),1),"ddd") -> sáb | D5: =TEXT(WEEKDAY(DATE(CalendarioAño,3,2),1),"ddd") -> dom | E5: =TEXT(WEEKDAY(DATE(CalendarioAño,3,3),1),"ddd") -> lun | F5: =TEXT(WEEKDAY(DATE(CalendarioAño,3,4),1),"ddd") -> mar | G5: =TEXT(WEEKDAY(DATE(CalendarioAño,3,5),1),"ddd") -> mié | H5: =TEXT(WEEKDAY(DATE(CalendarioAño,3,6),1),"ddd") -> jue | I5: =TEXT(WEEKDAY(DATE(CalendarioAño,3,7),1),"ddd") -> vie | J5: =TEXT(WEEKDAY(DATE(CalendarioAño,3,8),1),"ddd") -> sáb | K5: =TEXT(WEEKDAY(DATE(CalendarioAño,3,9),1),"ddd") -> dom | L5: =TEXT(WEEKDAY(DATE(CalendarioAño,3,10),1),"ddd") -> lun | M5: =TEXT(WEEKDAY(DATE(CalendarioAño,3,11),1),"ddd") -> mar | N5: =TEXT(WEEKDAY(DATE(CalendarioAño,3,12),1),"ddd") -> mié | O5: =TEXT(WEEKDAY(DATE(CalendarioAño,3,13),1),"ddd") -> jue | P5: =TEXT(WEEKDAY(DATE(CalendarioAño,3,14),1),"ddd") -> vie | Q5: =TEXT(WEEKDAY(DATE(CalendarioAño,3,15),1),"ddd") -> sáb | R5: =TEXT(WEEKDAY(DATE(CalendarioAño,3,16),1),"ddd") -> dom | S5: =TEXT(WEEKDAY(DATE(CalendarioAño,3,17),1),"ddd") -> lun | T5: =TEXT(WEEKDAY(DATE(CalendarioAño,3,18),1),"ddd") -> mar | U5: =TEXT(WEEKDAY(DATE(CalendarioAño,3,19),1),"ddd") -> mié | V5: =TEXT(WEEKDAY(DATE(CalendarioAño,3,20),1),"ddd") -> jue | W5: =TEXT(WEEKDAY(DATE(CalendarioAño,3,21),1),"ddd") -> vie | X5: =TEXT(WEEKDAY(DATE(CalendarioAño,3,22),1),"ddd") -> sáb | Y5: =TEXT(WEEKDAY(DATE(CalendarioAño,3,23),1),"ddd") -> dom | Z5: =TEXT(WEEKDAY(DATE(CalendarioAño,3,24),1),"ddd") -> lun | AA5: =TEXT(WEEKDAY(DATE(CalendarioAño,3,25),1),"ddd") -> mar | AB5: =TEXT(WEEKDAY(DATE(CalendarioAño,3,26),1),"ddd") -> mié | AC5: =TEXT(WEEKDAY(DATE(CalendarioAño,3,27),1),"ddd") -> jue | AD5: =TEXT(WEEKDAY(DATE(CalendarioAño,3,28),1),"ddd") -> vie | AE5: =TEXT(WEEKDAY(DATE(CalendarioAño,3,29),1),"ddd") -> sáb | AF5: =TEXT(WEEKDAY(DATE(CalendarioAño,3,30),1),"ddd") -> dom | AG5: =TEXT(WEEKDAY(DATE(CalendarioAño,3,31),1),"ddd") -> lun
B6: Nombre del empleado | C6: 1 | D6: 2 | E6: 3 | F6: 4 | G6: 5 | H6: 6 | I6: 7 | J6: 8 | K6: 9 | L6: 10 | M6: 11 | N6: 12 | O6: 13 | P6: 14 | Q6: 15 | R6: 16 | S6: 17 | T6: 18 | U6: 19 | V6: 20 | W6: 21 | X6: 22 | Y6: 23 | Z6: 24 | AA6: 25 | AB6: 26 | AC6: 27 | AD6: 28 | AE6: 29 | AF6: 30 | AG6: 31 | AH6: Número total de días
B7: THIAGO ABRAHAM MATIENZO TELLO | F7: A | J7: A | M7: A | Q7: A | T7: A | X7: A | AA7: A | AE7: A | AH7: 8
B8: DARIO DAVID FABIAN HERRERA | L8: A | S8: A | AH8: 2
B16: =Marzo!MonthName&" Total" -> Marzo Total | AH16: =SUM(C16:AG16) -> 0
B18: Marzo | C18: SUPER BABY WOLF 3:30 pm | AH18: =CalendarioAño -> 2025
C19: =TEXT(WEEKDAY(DATE(CalendarioAño,3,1),1),"ddd") -> sáb | D19: =TEXT(WEEKDAY(DATE(CalendarioAño,3,2),1),"ddd") -> dom | E19: =TEXT(WEEKDAY(DATE(CalendarioAño,3,3),1),"ddd") -> lun | F19: =TEXT(WEEKDAY(DATE(CalendarioAño,3,4),1),"ddd") -> mar | G19: =TEXT(WEEKDAY(DATE(CalendarioAño,3,5),1),"ddd") -> mié | H19: =TEXT(WEEKDAY(DATE(CalendarioAño,3,6),1),"ddd") -> jue | I19: =TEXT(WEEKDAY(DATE(CalendarioAño,3,7),1),"ddd") -> vie | J19: =TEXT(WEEKDAY(DATE(CalendarioAño,3,8),1),"ddd") -> sáb | K19: =TEXT(WEEKDAY(DATE(CalendarioAño,3,9),1),"ddd") -> dom | L19: =TEXT(WEEKDAY(DATE(CalendarioAño,3,10),1),"ddd") -> lun | M19: =TEXT(WEEKDAY(DATE(CalendarioAño,3,11),1),"ddd") -> mar | N19: =TEXT(WEEKDAY(DATE(CalendarioAño,3,12),1),"ddd") -> mié | O19: =TEXT(WEEKDAY(DATE(CalendarioAño,3,13),1),"ddd") -> jue | P19: =TEXT(WEEKDAY(DATE(CalendarioAño,3,14),1),"ddd") -> vie | Q19: =TEXT(WEEKDAY(DATE(CalendarioAño,3,15),1),"ddd") -> sáb | R19: =TEXT(WEEKDAY(DATE(CalendarioAño,3,16),1),"ddd") -> dom | S19: =TEXT(WEEKDAY(DATE(CalendarioAño,3,17),1),"ddd") -> lun | T19: =TEXT(WEEKDAY(DATE(CalendarioAño,3,18),1),"ddd") -> mar | U19: =TEXT(WEEKDAY(DATE(CalendarioAño,3,19),1),"ddd") -> mié | V19: =TEXT(WEEKDAY(DATE(CalendarioAño,3,20),1),"ddd") -> jue | W19: =TEXT(WEEKDAY(DATE(CalendarioAño,3,21),1),"ddd") -> vie | X19: =TEXT(WEEKDAY(DATE(CalendarioAño,3,22),1),"ddd") -> sáb | Y19: =TEXT(WEEKDAY(DATE(CalendarioAño,3,23),1),"ddd") -> dom | Z19: =TEXT(WEEKDAY(DATE(CalendarioAño,3,24),1),"ddd") -> lun | AA19: =TEXT(WEEKDAY(DATE(CalendarioAño,3,25),1),"ddd") -> mar | AB19: =TEXT(WEEKDAY(DATE(CalendarioAño,3,26),1),"ddd") -> mié | AC19: =TEXT(WEEKDAY(DATE(CalendarioAño,3,27),1),"ddd") -> jue | AD19: =TEXT(WEEKDAY(DATE(CalendarioAño,3,28),1),"ddd") -> vie | AE19: =TEXT(WEEKDAY(DATE(CalendarioAño,3,29),1),"ddd") -> sáb | AF19: =TEXT(WEEKDAY(DATE(CalendarioAño,3,30),1),"ddd") -> dom | AG19: =TEXT(WEEKDAY(DATE(CalendarioAño,3,31),1),"ddd") -> lun
B20: Nombre del empleado | C20: 1 | D20: 2 | E20: 3 | F20: 4 | G20: 5 | H20: 6 | I20: 7 | J20: 8 | K20: 9 | L20: 10 | M20: 11 | N20: 12 | O20: 13 | P20: 14 | Q20: 15 | R20: 16 | S20: 17 | T20: 18 | U20: 19 | V20: 20 | W20: 21 | X20: 22 | Y20: 23 | Z20: 24 | AA20: 25 | AB20: 26 | AC20: 27 | AD20: 28 | AE20: 29 | AF20: 30 | AG20: 31 | AH20: Número total de días
B21: EMANUEL DAVID RIVAS PAETAN | F21: A | J21: A | M21: A | Q21: A | V21: A | X21: A
B22: LUA GIANELLA RODRIGUEZ CASTRO | F22: A | H22: A | M22: A | O22: A | T22: A | V22: A | Z22: A | AA22: A | AC22: A
B23: ALEXANDRA GABRIELA BAUTISTA JUSTINIANO | G23: A | N23: A | T23: A | U23: A | V23: A | X23: A | AA23: A | AD23: A | AE23: A | AG23: A
B24: MATEO AUGUSTO RIVAS MERINO
B25: ALEJANDRO OCTAVIO ALEGRIA YUPANQUI | H25: A | I25: A | P25: A | Q25: A | T25: A | AE25: A
B26: FELIPE PUÑO NUÑEZ | H26: A | J26: A | L26: A
B27: MATEO JOSEPH HUATAY | G27: A | I27: A | N27: A | O27: A | AH27: 4
B28: ISABELLA QUISPE LUCAS | J28: A | N28: A | AA28: A | AC28: A | AH28: 4
B29: AMANDA VILLACORTA | AG29: A
B31: =Marzo!MonthName&" Total" -> Marzo Total | AH31: =SUM(C31:AG31) -> 0
B33: Marzo | C33: SUPER BABY WOLF 4:00 | AH33: =CalendarioAño -> 2025
C34: =TEXT(WEEKDAY(DATE(CalendarioAño,3,1),1),"ddd") -> sáb | D34: =TEXT(WEEKDAY(DATE(CalendarioAño,3,2),1),"ddd") -> dom | E34: =TEXT(WEEKDAY(DATE(CalendarioAño,3,3),1),"ddd") -> lun | F34: =TEXT(WEEKDAY(DATE(CalendarioAño,3,4),1),"ddd") -> mar | G34: =TEXT(WEEKDAY(DATE(CalendarioAño,3,5),1),"ddd") -> mié | H34: =TEXT(WEEKDAY(DATE(CalendarioAño,3,6),1),"ddd") -> jue | I34: =TEXT(WEEKDAY(DATE(CalendarioAño,3,7),1),"ddd") -> vie | J34: =TEXT(WEEKDAY(DATE(CalendarioAño,3,8),1),"ddd") -> sáb | K34: =TEXT(WEEKDAY(DATE(CalendarioAño,3,9),1),"ddd") -> dom | L34: =TEXT(WEEKDAY(DATE(CalendarioAño,3,10),1),"ddd") -> lun | M34: =TEXT(WEEKDAY(DATE(CalendarioAño,3,11),1),"ddd") -> mar | N34: =TEXT(WEEKDAY(DATE(CalendarioAño,3,12),1),"ddd") -> mié | O34: =TEXT(WEEKDAY(DATE(CalendarioAño,3,13),1),"ddd") -> jue | P34: =TEXT(WEEKDAY(DATE(CalendarioAño,3,14),1),"ddd") -> vie | Q34: =TEXT(WEEKDAY(DATE(CalendarioAño,3,15),1),"ddd") -> sáb | R34: =TEXT(WEEKDAY(DATE(CalendarioAño,3,16),1),"ddd") -> dom | S34: =TEXT(WEEKDAY(DATE(CalendarioAño,3,17),1),"ddd") -> lun | T34: =TEXT(WEEKDAY(DATE(CalendarioAño,3,18),1),"ddd") -> mar | U34: =TEXT(WEEKDAY(DATE(CalendarioAño,3,19),1),"ddd") -> mié | V34: =TEXT(WEEKDAY(DATE(CalendarioAño,3,20),1),"ddd") -> jue | W34: =TEXT(WEEKDAY(DATE(CalendarioAño,3,21),1),"ddd") -> vie | X34: =TEXT(WEEKDAY(DATE(CalendarioAño,3,22),1),"ddd") -> sáb | Y34: =TEXT(WEEKDAY(DATE(CalendarioAño,3,23),1),"ddd") -> dom | Z34: =TEXT(WEEKDAY(DATE(CalendarioAño,3,24),1),"ddd") -> lun | AA34: =TEXT(WEEKDAY(DATE(CalendarioAño,3,25),1),"ddd") -> mar | AB34: =TEXT(WEEKDAY(DATE(CalendarioAño,3,26),1),"ddd") -> mié | AC34: =TEXT(WEEKDAY(DATE(CalendarioAño,3,27),1),"ddd") -> jue | AD34: =TEXT(WEEKDAY(DATE(CalendarioAño,3,28),1),"ddd") -> vie | AE34: =TEXT(WEEKDAY(DATE(CalendarioAño,3,29),1),"ddd") -> sáb | AF34: =TEXT(WEEKDAY(DATE(CalendarioAño,3,30),1),"ddd") -> dom | AG34: =TEXT(WEEKDAY(DATE(CalendarioAño,3,31),1),"ddd") -> lun
B35: Nombre del empleado | C35: 1 | D35: 2 | E35: 3 | F35: 4 | G35: 5 | H35: 6 | I35: 7 | J35: 8 | K35: 9 | L35: 10 | M35: 11 | N35: 12 | O35: 13 | P35: 14 | Q35: 15 | R35: 16 | S35: 17 | T35: 18 | U35: 19 | V35: 20 | W35: 21 | X35: 22 | Y35: 23 | Z35: 24 | AA35: 25 | AB35: 26 | AC35: 27 | AD35: 28 | AE35: 29 | AF35: 30 | AG35: 31 | AH35: Número total de días
B36: MARIA FERNANDA ORBEGOSO LOPEZ | F36: A | H36: A | M36: A | O36: A | T36: A | V36: A | AA36: A | AC36: A | AH36: 8
B37: ALESSIO VEGARA EZETA | F37: A | H37: A | P37: A | Q37: A | W37: A | X37: A | AE37: A
B38: MARCELO SANTOS URBANO | F38: A | J38: A | L38: A | O38: A | Q38: A | X38: A | AA38: A
B39: VALENTINA FLAVIA VALDIVIESZO ROMAN | G39: A | H39: A | L39: A | N39: A | S39: A | U39: A | W39: A | AA39: A | AC39: A
B40: CAMILA MAUREEN GARCIA VEGA | G40: A | H40: A | S40: A | U40: A | W40: A | Z40: A | AB40: A | AG40: A
B41: ALBA LUCIA CABALLERO SORIANO | H41: A | M41: A | O41: A | V41: A | AA41: A | AC41: A
B42: FERNANDA SOCA MEDRARO | H42: A | J42: A | O42: A | Q42: A | V42: A | W42: A | X42: A | AC42: A | AE42: A | AH42: 9
B43: CATALINA MARIA ROMERO MALPICA | I43: A
B44: JOSE ANDRES VELIZ HAYTA | Q44: A | X44: A | AE44: A
B45: SALVADOR EFRAIN BUSTAMANTE PEREZ | Q45: A | X45: A | AE45: A | AH45: 3
B46: MAR PORTOCARRERO BERNAOLA | T46: A | V46: A | AA46: A | AE46: A | AH46: 4
B47: MICAELA PORTOCARRERO BERNAOLA | T47: A | V47: A | AA47: A | AE47: A | AH47: 4
B48: SANTIAGO ROJAS | X48: A | AB48: A | AE48: A | AH48: 3
B51: =Marzo!MonthName&" Total" -> Marzo Total | AH51: =SUM(C51:AG51) -> 0
B53: Marzo | C53: BABY WOLF 4:30 | AH53: =CalendarioAño -> 2025
C54: =TEXT(WEEKDAY(DATE(CalendarioAño,3,1),1),"ddd") -> sáb | D54: =TEXT(WEEKDAY(DATE(CalendarioAño,3,2),1),"ddd") -> dom | E54: =TEXT(WEEKDAY(DATE(CalendarioAño,3,3),1),"ddd") -> lun | F54: =TEXT(WEEKDAY(DATE(CalendarioAño,3,4),1),"ddd") -> mar | G54: =TEXT(WEEKDAY(DATE(CalendarioAño,3,5),1),"ddd") -> mié | H54: =TEXT(WEEKDAY(DATE(CalendarioAño,3,6),1),"ddd") -> jue | I54: =TEXT(WEEKDAY(DATE(CalendarioAño,3,7),1),"ddd") -> vie | J54: =TEXT(WEEKDAY(DATE(CalendarioAño,3,8),1),"ddd") -> sáb | K54: =TEXT(WEEKDAY(DATE(CalendarioAño,3,9),1),"ddd") -> dom | L54: =TEXT(WEEKDAY(DATE(CalendarioAño,3,10),1),"ddd") -> lun | M54: =TEXT(WEEKDAY(DATE(CalendarioAño,3,11),1),"ddd") -> mar | N54: =TEXT(WEEKDAY(DATE(CalendarioAño,3,12),1),"ddd") -> mié | O54: =TEXT(WEEKDAY(DATE(CalendarioAño,3,13),1),"ddd") -> jue | P54: =TEXT(WEEKDAY(DATE(CalendarioAño,3,14),1),"ddd") -> vie | Q54: =TEXT(WEEKDAY(DATE(CalendarioAño,3,15),1),"ddd") -> sáb | R54: =TEXT(WEEKDAY(DATE(CalendarioAño,3,16),1),"ddd") -> dom | S54: =TEXT(WEEKDAY(DATE(CalendarioAño,3,17),1),"ddd") -> lun | T54: =TEXT(WEEKDAY(DATE(CalendarioAño,3,18),1),"ddd") -> mar | U54: =TEXT(WEEKDAY(DATE(CalendarioAño,3,19),1),"ddd") -> mié | V54: =TEXT(WEEKDAY(DATE(CalendarioAño,3,20),1),"ddd") -> jue | W54: =TEXT(WEEKDAY(DATE(CalendarioAño,3,21),1),"ddd") -> vie | X54: =TEXT(WEEKDAY(DATE(CalendarioAño,3,22),1),"ddd") -> sáb | Y54: =TEXT(WEEKDAY(DATE(CalendarioAño,3,23),1),"ddd") -> dom | Z54: =TEXT(WEEKDAY(DATE(CalendarioAño,3,24),1),"ddd") -> lun | AA54: =TEXT(WEEKDAY(DATE(CalendarioAño,3,25),1),"ddd") -> mar | AB54: =TEXT(WEEKDAY(DATE(CalendarioAño,3,26),1),"ddd") -> mié | AC54: =TEXT(WEEKDAY(DATE(CalendarioAño,3,27),1),"ddd") -> jue | AD54: =TEXT(WEEKDAY(DATE(CalendarioAño,3,28),1),"ddd") -> vie | AE54: =TEXT(WEEKDAY(DATE(CalendarioAño,3,29),1),"ddd") -> sáb | AF54: =TEXT(WEEKDAY(DATE(CalendarioAño,3,30),1),"ddd") -> dom | AG54: =TEXT(WEEKDAY(DATE(CalendarioAño,3,31),1),"ddd") -> lun
...

Sheet Abril
B1: ASISTENCIA DE ALUMNOS
B2: Claves de los tipos de Asistencia | C2: V | D2: Vacaciones | G2: P | H2: Personal | K2: A | L2: Asistencia | O2: R | P2: Recuperacion | T2: E | U2: Eventos
B4: Abril | C4: MEGA SUPER BABY WOLF 3:00 PM | AH4: =CalendarioAño -> 2025
C5: =TEXT(WEEKDAY(DATE(CalendarioAño,4,1),1),"ddd") -> mar | D5: =TEXT(WEEKDAY(DATE(CalendarioAño,4,2),1),"ddd") -> mié | E5: =TEXT(WEEKDAY(DATE(CalendarioAño,4,3),1),"ddd") -> jue | F5: =TEXT(WEEKDAY(DATE(CalendarioAño,4,4),1),"ddd") -> vie | G5: =TEXT(WEEKDAY(DATE(CalendarioAño,4,5),1),"ddd") -> sáb | H5: =TEXT(WEEKDAY(DATE(CalendarioAño,4,6),1),"ddd") -> dom | I5: =TEXT(WEEKDAY(DATE(CalendarioAño,4,7),1),"ddd") -> lun | J5: =TEXT(WEEKDAY(DATE(CalendarioAño,4,8),1),"ddd") -> mar | K5: =TEXT(WEEKDAY(DATE(CalendarioAño,4,9),1),"ddd") -> mié | L5: =TEXT(WEEKDAY(DATE(CalendarioAño,4,10),1),"ddd") -> jue | M5: =TEXT(WEEKDAY(DATE(CalendarioAño,4,11),1),"ddd") -> vie | N5: =TEXT(WEEKDAY(DATE(CalendarioAño,4,12),1),"ddd") -> sáb | O5: =TEXT(WEEKDAY(DATE(CalendarioAño,4,13),1),"ddd") -> dom | P5: =TEXT(WEEKDAY(DATE(CalendarioAño,4,14),1),"ddd") -> lun | Q5: =TEXT(WEEKDAY(DATE(CalendarioAño,4,15),1),"ddd") -> mar | R5: =TEXT(WEEKDAY(DATE(CalendarioAño,4,16),1),"ddd") -> mié | S5: =TEXT(WEEKDAY(DATE(CalendarioAño,4,17),1),"ddd") -> jue | T5: =TEXT(WEEKDAY(DATE(CalendarioAño,4,18),1),"ddd") -> vie | U5: =TEXT(WEEKDAY(DATE(CalendarioAño,4,19),1),"ddd") -> sáb | V5: =TEXT(WEEKDAY(DATE(CalendarioAño,4,20),1),"ddd") -> dom | W5: =TEXT(WEEKDAY(DATE(CalendarioAño,4,21),1),"ddd") -> lun | X5: =TEXT(WEEKDAY(DATE(CalendarioAño,4,22),1),"ddd") -> mar | Y5: =TEXT(WEEKDAY(DATE(CalendarioAño,4,23),1),"ddd") -> mié | Z5: =TEXT(WEEKDAY(DATE(CalendarioAño,4,24),1),"ddd") -> jue | AA5: =TEXT(WEEKDAY(DATE(CalendarioAño,4,25),1),"ddd") -> vie | AB5: =TEXT(WEEKDAY(DATE(CalendarioAño,4,26),1),"ddd") -> sáb | AC5: =TEXT(WEEKDAY(DATE(CalendarioAño,4,27),1),"ddd") -> dom | AD5: =TEXT(WEEKDAY(DATE(CalendarioAño,4,28),1),"ddd") -> lun | AE5: =TEXT(WEEKDAY(DATE(CalendarioAño,4,29),1),"ddd") -> mar | AF5: =TEXT(WEEKDAY(DATE(CalendarioAño,4,30),1),"ddd") -> mié
B6: ALUMNOS | C6: 1 | D6: 2 | E6: 3 | F6: 4 | G6: 5 | H6: 6 | I6: 7 | J6: 8 | K6: 9 | L6: 10 | M6: 11 | N6: 12 | O6: 13 | P6: 14 | Q6: 15 | R6: 16 | S6: 17 | T6: 18 | U6: 19 | V6: 20 | W6: 21 | X6: 22 | Y6: 23 | Z6: 24 | AA6: 25 | AB6: 26 | AC6: 27 | AD6: 28 | AE6: 29 | AF6: 30 | AH6: Total de días
B7: JACK ANDIA RUIZ | J7: A | Q7: A | X7: A | Z7: A | AE7: A
B19: =Abril!MonthName&" Total" -> Abril Total | AH19: =SUM(C19:AG19) -> 0
B21: Abril | C21: SUPER BABY WOLF 3:30 pm
C22: =TEXT(WEEKDAY(DATE(CalendarioAño,4,1),1),"ddd") -> mar | D22: =TEXT(WEEKDAY(DATE(CalendarioAño,4,2),1),"ddd") -> mié | E22: =TEXT(WEEKDAY(DATE(CalendarioAño,4,3),1),"ddd") -> jue | F22: =TEXT(WEEKDAY(DATE(CalendarioAño,4,4),1),"ddd") -> vie | G22: =TEXT(WEEKDAY(DATE(CalendarioAño,4,5),1),"ddd") -> sáb | H22: =TEXT(WEEKDAY(DATE(CalendarioAño,4,6),1),"ddd") -> dom | I22: =TEXT(WEEKDAY(DATE(CalendarioAño,4,7),1),"ddd") -> lun | J22: =TEXT(WEEKDAY(DATE(CalendarioAño,4,8),1),"ddd") -> mar | K22: =TEXT(WEEKDAY(DATE(CalendarioAño,4,9),1),"ddd") -> mié | L22: =TEXT(WEEKDAY(DATE(CalendarioAño,4,10),1),"ddd") -> jue | M22: =TEXT(WEEKDAY(DATE(CalendarioAño,4,11),1),"ddd") -> vie | N22: =TEXT(WEEKDAY(DATE(CalendarioAño,4,12),1),"ddd") -> sáb | O22: =TEXT(WEEKDAY(DATE(CalendarioAño,4,13),1),"ddd") -> dom | P22: =TEXT(WEEKDAY(DATE(CalendarioAño,4,14),1),"ddd") -> lun | Q22: =TEXT(WEEKDAY(DATE(CalendarioAño,4,15),1),"ddd") -> mar | R22: =TEXT(WEEKDAY(DATE(CalendarioAño,4,16),1),"ddd") -> mié | S22: =TEXT(WEEKDAY(DATE(CalendarioAño,4,17),1),"ddd") -> jue | T22: =TEXT(WEEKDAY(DATE(CalendarioAño,4,18),1),"ddd") -> vie | U22: =TEXT(WEEKDAY(DATE(CalendarioAño,4,19),1),"ddd") -> sáb | V22: =TEXT(WEEKDAY(DATE(CalendarioAño,4,20),1),"ddd") -> dom | W22: =TEXT(WEEKDAY(DATE(CalendarioAño,4,21),1),"ddd") -> lun | X22: =TEXT(WEEKDAY(DATE(CalendarioAño,4,22),1),"ddd") -> mar | Y22: =TEXT(WEEKDAY(DATE(CalendarioAño,4,23),1),"ddd") -> mié | Z22: =TEXT(WEEKDAY(DATE(CalendarioAño,4,24),1),"ddd") -> jue | AA22: =TEXT(WEEKDAY(DATE(CalendarioAño,4,25),1),"ddd") -> vie | AB22: =TEXT(WEEKDAY(DATE(CalendarioAño,4,26),1),"ddd") -> sáb | AC22: =TEXT(WEEKDAY(DATE(CalendarioAño,4,27),1),"ddd") -> dom | AD22: =TEXT(WEEKDAY(DATE(CalendarioAño,4,28),1),"ddd") -> lun | AE22: =TEXT(WEEKDAY(DATE(CalendarioAño,4,29),1),"ddd") -> mar | AF22: =TEXT(WEEKDAY(DATE(CalendarioAño,4,30),1),"ddd") -> mié
B23: ALUMNOS | C23: 1 | D23: 2 | E23: 3 | F23: 4 | G23: 5 | H23: 6 | I23: 7 | J23: 8 | K23: 9 | L23: 10 | M23: 11 | N23: 12 | O23: 13 | P23: 14 | Q23: 15 | R23: 16 | S23: 17 | T23: 18 | U23: 19 | V23: 20 | W23: 21 | X23: 22 | Y23: 23 | Z23: 24 | AA23: 25 | AB23: 26 | AC23: 27 | AD23: 28 | AE23: 29 | AF23: 30
B24: THIAGO ABRAHAM MATIENZO TELLO | C24: A | J24: A | Q24: A | X24: A | AB24: A | AD24: A | AH24: 4
B25: ALEXANDRA GABRIELA BAUTISTA JUSTINIANO | C25: A | N25: A | W25: A
B26: EMANUEL DAVID RIVAS PAETAN | C26: A | J26: A | X26: A | AB26: AA | AE26: A
B27: ISABELLA QUISPE LUCAS | E27: A | F27: A | J27: A | N27: A | Q27: A | Z27: A | AH27: 6
B28: JOSE ANDRES VELIZ HAYTA | N28: A
B29: DANIELA AIATAMA CUEVA ZEVALLOS | X29: A
B36: =Abril!MonthName&" Total" -> Abril Total
B38: Abril | C38: SUPER BABY WOLF 4:00
C39: =TEXT(WEEKDAY(DATE(CalendarioAño,4,1),1),"ddd") -> mar | D39: =TEXT(WEEKDAY(DATE(CalendarioAño,4,2),1),"ddd") -> mié | E39: =TEXT(WEEKDAY(DATE(CalendarioAño,4,3),1),"ddd") -> jue | F39: =TEXT(WEEKDAY(DATE(CalendarioAño,4,4),1),"ddd") -> vie | G39: =TEXT(WEEKDAY(DATE(CalendarioAño,4,5),1),"ddd") -> sáb | H39: =TEXT(WEEKDAY(DATE(CalendarioAño,4,6),1),"ddd") -> dom | I39: =TEXT(WEEKDAY(DATE(CalendarioAño,4,7),1),"ddd") -> lun | J39: =TEXT(WEEKDAY(DATE(CalendarioAño,4,8),1),"ddd") -> mar | K39: =TEXT(WEEKDAY(DATE(CalendarioAño,4,9),1),"ddd") -> mié | L39: =TEXT(WEEKDAY(DATE(CalendarioAño,4,10),1),"ddd") -> jue | M39: =TEXT(WEEKDAY(DATE(CalendarioAño,4,11),1),"ddd") -> vie | N39: =TEXT(WEEKDAY(DATE(CalendarioAño,4,12),1),"ddd") -> sáb | O39: =TEXT(WEEKDAY(DATE(CalendarioAño,4,13),1),"ddd") -> dom | P39: =TEXT(WEEKDAY(DATE(CalendarioAño,4,14),1),"ddd") -> lun | Q39: =TEXT(WEEKDAY(DATE(CalendarioAño,4,15),1),"ddd") -> mar | R39: =TEXT(WEEKDAY(DATE(CalendarioAño,4,16),1),"ddd") -> mié | S39: =TEXT(WEEKDAY(DATE(CalendarioAño,4,17),1),"ddd") -> jue | T39: =TEXT(WEEKDAY(DATE(CalendarioAño,4,18),1),"ddd") -> vie | U39: =TEXT(WEEKDAY(DATE(CalendarioAño,4,19),1),"ddd") -> sáb | V39: =TEXT(WEEKDAY(DATE(CalendarioAño,4,20),1),"ddd") -> dom | W39: =TEXT(WEEKDAY(DATE(CalendarioAño,4,21),1),"ddd") -> lun | X39: =TEXT(WEEKDAY(DATE(CalendarioAño,4,22),1),"ddd") -> mar | Y39: =TEXT(WEEKDAY(DATE(CalendarioAño,4,23),1),"ddd") -> mié | Z39: =TEXT(WEEKDAY(DATE(CalendarioAño,4,24),1),"ddd") -> jue | AA39: =TEXT(WEEKDAY(DATE(CalendarioAño,4,25),1),"ddd") -> vie | AB39: =TEXT(WEEKDAY(DATE(CalendarioAño,4,26),1),"ddd") -> sáb | AC39: =TEXT(WEEKDAY(DATE(CalendarioAño,4,27),1),"ddd") -> dom | AD39: =TEXT(WEEKDAY(DATE(CalendarioAño,4,28),1),"ddd") -> lun | AE39: =TEXT(WEEKDAY(DATE(CalendarioAño,4,29),1),"ddd") -> mar | AF39: =TEXT(WEEKDAY(DATE(CalendarioAño,4,30),1),"ddd") -> mié
B40: ALUMNOS | C40: 1 | D40: 2 | E40: 3 | F40: 4 | G40: 5 | H40: 6 | I40: 7 | J40: 8 | K40: 9 | L40: 10 | M40: 11 | N40: 12 | O40: 13 | P40: 14 | Q40: 15 | R40: 16 | S40: 17 | T40: 18 | U40: 19 | V40: 20 | W40: 21 | X40: 22 | Y40: 23 | Z40: 24 | AA40: 25 | AB40: 26 | AC40: 27 | AD40: 28 | AE40: 29 | AF40: 30
B41: ISABELLA VALENTINA GUINEA CERDAN | C41: A
B42: MARCELO SANTOS URBANO | C42: A | F42: A | J42: A | M42: A
B43: ALBA LUCIA CABALLERO SORIANO | C43: A | E43: A | J43: A | Q43: A | X43: A
B44: AMANDA VILLACORTA | D44: A | Q44: A | X44: A
B45: JESUS MICHILOT | D45: A | J45: A | N45: A | Y45: A | AH45: 4
B46: FERNANDA SOCA MEDRARO | E46: A | Z46: A | AF46: A | AH46: 3
B47: MARIA FERNANDA ORBEGOSO LOPEZ | E47: A | F47: A | J47: A | Q47: A | AE47: A | AH47: 5
B48: MAR PORTOCARRERO BERNAOLA | F48: A
B49: MICAELA PORTOCARRERO BERNAOLA | F49: A
B50: ANTONELLA ESPERANZA OLANO CONTRERAS | I50: AAA | J50: A | N50: A | X50: A | Z50: A | AF50: A
B51: SALVADOR EFRAIN BUSTAMANTE PEREZ | N51: A | AB51: A | AH51: 2
B52: SANTIAGO ROJAS | N52: A | Y52: A | AB52: A | AF52: A | AH52: 4
B53: PIA TORERO MERINO | K53: A | N53: A | AB53: A | AF53: A | AH53: 4
B54: ALESSIO VEGARA EZETA
B57: =Abril!MonthName&" Total" -> Abril Total
B59: Abril | C59: BABY WOLF 4:30
C60: =TEXT(WEEKDAY(DATE(CalendarioAño,4,1),1),"ddd") -> mar | D60: =TEXT(WEEKDAY(DATE(CalendarioAño,4,2),1),"ddd") -> mié | E60: =TEXT(WEEKDAY(DATE(CalendarioAño,4,3),1),"ddd") -> jue | F60: =TEXT(WEEKDAY(DATE(CalendarioAño,4,4),1),"ddd") -> vie | G60: =TEXT(WEEKDAY(DATE(CalendarioAño,4,5),1),"ddd") -> sáb | H60: =TEXT(WEEKDAY(DATE(CalendarioAño,4,6),1),"ddd") -> dom | I60: =TEXT(WEEKDAY(DATE(CalendarioAño,4,7),1),"ddd") -> lun | J60: =TEXT(WEEKDAY(DATE(CalendarioAño,4,8),1),"ddd") -> mar | K60: =TEXT(WEEKDAY(DATE(CalendarioAño,4,9),1),"ddd") -> mié | L60: =TEXT(WEEKDAY(DATE(CalendarioAño,4,10),1),"ddd") -> jue | M60: =TEXT(WEEKDAY(DATE(CalendarioAño,4,11),1),"ddd") -> vie | N60: =TEXT(WEEKDAY(DATE(CalendarioAño,4,12),1),"ddd") -> sáb | O60: =TEXT(WEEKDAY(DATE(CalendarioAño,4,13),1),"ddd") -> dom | P60: =TEXT(WEEKDAY(DATE(CalendarioAño,4,14),1),"ddd") -> lun | Q60: =TEXT(WEEKDAY(DATE(CalendarioAño,4,15),1),"ddd") -> mar | R60: =TEXT(WEEKDAY(DATE(CalendarioAño,4,16),1),"ddd") -> mié | S60: =TEXT(WEEKDAY(DATE(CalendarioAño,4,17),1),"ddd") -> jue | T60: =TEXT(WEEKDAY(DATE(CalendarioAño,4,18),1),"ddd") -> vie | U60: =TEXT(WEEKDAY(DATE(CalendarioAño,4,19),1),"ddd") -> sáb | V60: =TEXT(WEEKDAY(DATE(CalendarioAño,4,20),1),"ddd") -> dom | W60: =TEXT(WEEKDAY(DATE(CalendarioAño,4,21),1),"ddd") -> lun | X60: =TEXT(WEEKDAY(DATE(CalendarioAño,4,22),1),"ddd") -> mar | Y60: =TEXT(WEEKDAY(DATE(CalendarioAño,4,23),1),"ddd") -> mié | Z60: =TEXT(WEEKDAY(DATE(CalendarioAño,4,24),1),"ddd") -> jue | AA60: =TEXT(WEEKDAY(DATE(CalendarioAño,4,25),1),"ddd") -> vie | AB60: =TEXT(WEEKDAY(DATE(CalendarioAño,4,26),1),"ddd") -> sáb | AC60: =TEXT(WEEKDAY(DATE(CalendarioAño,4,27),1),"ddd") -> dom | AD60: =TEXT(WEEKDAY(DATE(CalendarioAño,4,28),1),"ddd") -> lun | AE60: =TEXT(WEEKDAY(DATE(CalendarioAño,4,29),1),"ddd") -> mar | AF60: =TEXT(WEEKDAY(DATE(CalendarioAño,4,30),1),"ddd") -> mié
B61: ALUMNOS | C61: 1 | D61: 2 | E61: 3 | F61: 4 | G61: 5 | H61: 6 | I61: 7 | J61: 8 | K61: 9 | L61: 10 | M61: 11 | N61: 12 | O61: 13 | P61: 14 | Q61: 15 | R61: 16 | S61: 17 | T61: 18 | U61: 19 | V61: 20 | W61: 21 | X61: 22 | Y61: 23 | Z61: 24 | AA61: 25 | AB61: 26 | AC61: 27 | AD61: 28 | AE61: 29 | AF61: 30
B62: SERGIO JEREMY AGUIRRE MISIYAURI | C62: A | E62: A | J62: A | Q62: A | X62: A | Z62: A | AH62: 6
B63: MATEO AUGUSTO RIVAS MERINO | C63: A | Q63: A | Z63: A | AE63: A
...

Sheet Mayo
B1: ASISTENCIA DE ALUMNOS
B2: Claves de los tipos de Asistencia | C2: V | D2: Vacaciones | G2: P | H2: Personal | K2: A | L2: Asistencia | O2: R | P2: Recuperacion | T2: E | U2: Eventos
B4: Mayo | C4: MEGA SUPER BABY WOLF 3:00 PM | AH4: =CalendarioAño -> 2025
C5: =TEXT(WEEKDAY(DATE(CalendarioAño,5,1),1),"ddd") -> jue | D5: =TEXT(WEEKDAY(DATE(CalendarioAño,5,2),1),"ddd") -> vie | E5: =TEXT(WEEKDAY(DATE(CalendarioAño,5,3),1),"ddd") -> sáb | F5: =TEXT(WEEKDAY(DATE(CalendarioAño,5,4),1),"ddd") -> dom | G5: =TEXT(WEEKDAY(DATE(CalendarioAño,5,5),1),"ddd") -> lun | H5: =TEXT(WEEKDAY(DATE(CalendarioAño,5,6),1),"ddd") -> mar | I5: =TEXT(WEEKDAY(DATE(CalendarioAño,5,7),1),"ddd") -> mié | J5: =TEXT(WEEKDAY(DATE(CalendarioAño,5,8),1),"ddd") -> jue | K5: =TEXT(WEEKDAY(DATE(CalendarioAño,5,9),1),"ddd") -> vie | L5: =TEXT(WEEKDAY(DATE(CalendarioAño,5,10),1),"ddd") -> sáb | M5: =TEXT(WEEKDAY(DATE(CalendarioAño,5,11),1),"ddd") -> dom | N5: =TEXT(WEEKDAY(DATE(CalendarioAño,5,12),1),"ddd") -> lun | O5: =TEXT(WEEKDAY(DATE(CalendarioAño,5,13),1),"ddd") -> mar | P5: =TEXT(WEEKDAY(DATE(CalendarioAño,5,14),1),"ddd") -> mié | Q5: =TEXT(WEEKDAY(DATE(CalendarioAño,5,15),1),"ddd") -> jue | R5: =TEXT(WEEKDAY(DATE(CalendarioAño,5,16),1),"ddd") -> vie | S5: =TEXT(WEEKDAY(DATE(CalendarioAño,5,17),1),"ddd") -> sáb | T5: =TEXT(WEEKDAY(DATE(CalendarioAño,5,18),1),"ddd") -> dom | U5: =TEXT(WEEKDAY(DATE(CalendarioAño,5,19),1),"ddd") -> lun | V5: =TEXT(WEEKDAY(DATE(CalendarioAño,5,20),1),"ddd") -> mar | W5: =TEXT(WEEKDAY(DATE(CalendarioAño,5,21),1),"ddd") -> mié | X5: =TEXT(WEEKDAY(DATE(CalendarioAño,5,22),1),"ddd") -> jue | Y5: =TEXT(WEEKDAY(DATE(CalendarioAño,5,23),1),"ddd") -> vie | Z5: =TEXT(WEEKDAY(DATE(CalendarioAño,5,24),1),"ddd") -> sáb | AA5: =TEXT(WEEKDAY(DATE(CalendarioAño,5,25),1),"ddd") -> dom | AB5: =TEXT(WEEKDAY(DATE(CalendarioAño,5,26),1),"ddd") -> lun | AC5: =TEXT(WEEKDAY(DATE(CalendarioAño,5,27),1),"ddd") -> mar | AD5: =TEXT(WEEKDAY(DATE(CalendarioAño,5,28),1),"ddd") -> mié | AE5: =TEXT(WEEKDAY(DATE(CalendarioAño,5,29),1),"ddd") -> jue | AF5: =TEXT(WEEKDAY(DATE(CalendarioAño,5,30),1),"ddd") -> vie | AG5: =TEXT(WEEKDAY(DATE(CalendarioAño,5,31),1),"ddd") -> sáb
B6: Nombre del empleado | C6: 1 | D6: 2 | E6: 3 | F6: 4 | G6: 5 | H6: 6 | I6: 7 | J6: 8 | K6: 9 | L6: 10 | M6: 11 | N6: 12 | O6: 13 | P6: 14 | Q6: 15 | R6: 16 | S6: 17 | T6: 18 | U6: 19 | V6: 20 | W6: 21 | X6: 22 | Y6: 23 | Z6: 24 | AA6: 25 | AB6: 26 | AC6: 27 | AD6: 28 | AE6: 29 | AF6: 30 | AG6: 31 | AH6: Número total de días
B7: JACK ANDIA RUIZ | H7: A | O7: A | S7: A | X7: A | Z7: A | AC7: A
B16: =Mayo!MonthName&" Total" -> Mayo Total | AH16: =SUM(C16:AG16) -> 0
B18: Mayo | C18: SUPER BABY WOLF 3:30 PM | AH18: =CalendarioAño -> 2025
C19: =TEXT(WEEKDAY(DATE(CalendarioAño,5,1),1),"ddd") -> jue | D19: =TEXT(WEEKDAY(DATE(CalendarioAño,5,2),1),"ddd") -> vie | E19: =TEXT(WEEKDAY(DATE(CalendarioAño,5,3),1),"ddd") -> sáb | F19: =TEXT(WEEKDAY(DATE(CalendarioAño,5,4),1),"ddd") -> dom | G19: =TEXT(WEEKDAY(DATE(CalendarioAño,5,5),1),"ddd") -> lun | H19: =TEXT(WEEKDAY(DATE(CalendarioAño,5,6),1),"ddd") -> mar | I19: =TEXT(WEEKDAY(DATE(CalendarioAño,5,7),1),"ddd") -> mié | J19: =TEXT(WEEKDAY(DATE(CalendarioAño,5,8),1),"ddd") -> jue | K19: =TEXT(WEEKDAY(DATE(CalendarioAño,5,9),1),"ddd") -> vie | L19: =TEXT(WEEKDAY(DATE(CalendarioAño,5,10),1),"ddd") -> sáb | M19: =TEXT(WEEKDAY(DATE(CalendarioAño,5,11),1),"ddd") -> dom | N19: =TEXT(WEEKDAY(DATE(CalendarioAño,5,12),1),"ddd") -> lun | O19: =TEXT(WEEKDAY(DATE(CalendarioAño,5,13),1),"ddd") -> mar | P19: =TEXT(WEEKDAY(DATE(CalendarioAño,5,14),1),"ddd") -> mié | Q19: =TEXT(WEEKDAY(DATE(CalendarioAño,5,15),1),"ddd") -> jue | R19: =TEXT(WEEKDAY(DATE(CalendarioAño,5,16),1),"ddd") -> vie | S19: =TEXT(WEEKDAY(DATE(CalendarioAño,5,17),1),"ddd") -> sáb | T19: =TEXT(WEEKDAY(DATE(CalendarioAño,5,18),1),"ddd") -> dom | U19: =TEXT(WEEKDAY(DATE(CalendarioAño,5,19),1),"ddd") -> lun | V19: =TEXT(WEEKDAY(DATE(CalendarioAño,5,20),1),"ddd") -> mar | W19: =TEXT(WEEKDAY(DATE(CalendarioAño,5,21),1),"ddd") -> mié | X19: =TEXT(WEEKDAY(DATE(CalendarioAño,5,22),1),"ddd") -> jue | Y19: =TEXT(WEEKDAY(DATE(CalendarioAño,5,23),1),"ddd") -> vie | Z19: =TEXT(WEEKDAY(DATE(CalendarioAño,5,24),1),"ddd") -> sáb | AA19: =TEXT(WEEKDAY(DATE(CalendarioAño,5,25),1),"ddd") -> dom | AB19: =TEXT(WEEKDAY(DATE(CalendarioAño,5,26),1),"ddd") -> lun | AC19: =TEXT(WEEKDAY(DATE(CalendarioAño,5,27),1),"ddd") -> mar | AD19: =TEXT(WEEKDAY(DATE(CalendarioAño,5,28),1),"ddd") -> mié | AE19: =TEXT(WEEKDAY(DATE(CalendarioAño,5,29),1),"ddd") -> jue | AF19: =TEXT(WEEKDAY(DATE(CalendarioAño,5,30),1),"ddd") -> vie | AG19: =TEXT(WEEKDAY(DATE(CalendarioAño,5,31),1),"ddd") -> sáb
B20: Nombre del empleado | C20: 1 | D20: 2 | E20: 3 | F20: 4 | G20: 5 | H20: 6 | I20: 7 | J20: 8 | K20: 9 | L20: 10 | M20: 11 | N20: 12 | O20: 13 | P20: 14 | Q20: 15 | R20: 16 | S20: 17 | T20: 18 | U20: 19 | V20: 20 | W20: 21 | X20: 22 | Y20: 23 | Z20: 24 | AA20: 25 | AB20: 26 | AC20: 27 | AD20: 28 | AE20: 29 | AF20: 30 | AG20: 31 | AH20: Número total de días
B21: THIAGO ABRAHAM MATIENZO TELLO | E21: A | G21: A | H21: A | J21: A | N21: A | S21: A | U21: A | V21: A
B22: ALEXANDRA GABRIELA BAUTISTA JUSTINIANO | E22: A | L22: A | S22: A | AB22: A | AE22: A
B23: AMANDA VILLACORTA | H23: A | J23: A | Q23: A | AC23: A | AE23: A
B24: LUA GIANELLA RODRIGUEZ CASTRO | H24: A | J24: A | O24: A | Q24: A | V24: A | AC24: A | AE24: A
B25: EMANUEL DAVID RIVAS PAETAN | H25: A | L25: A | S25: A | X25: A | Z25: A | AC25: A
B26: MARTIN RUIZ CHU | AF26: A
B30: =Mayo!MonthName&" Total" -> Mayo Total | AH30: =SUM(C30:AG30) -> 0
B32: Mayo | C32: SUPER BABY WOLF 4:00 PM | AH32: =CalendarioAño -> 2025
C33: =TEXT(WEEKDAY(DATE(CalendarioAño,5,1),1),"ddd") -> jue | D33: =TEXT(WEEKDAY(DATE(CalendarioAño,5,2),1),"ddd") -> vie | E33: =TEXT(WEEKDAY(DATE(CalendarioAño,5,3),1),"ddd") -> sáb | F33: =TEXT(WEEKDAY(DATE(CalendarioAño,5,4),1),"ddd") -> dom | G33: =TEXT(WEEKDAY(DATE(CalendarioAño,5,5),1),"ddd") -> lun | H33: =TEXT(WEEKDAY(DATE(CalendarioAño,5,6),1),"ddd") -> mar | I33: =TEXT(WEEKDAY(DATE(CalendarioAño,5,7),1),"ddd") -> mié | J33: =TEXT(WEEKDAY(DATE(CalendarioAño,5,8),1),"ddd") -> jue | K33: =TEXT(WEEKDAY(DATE(CalendarioAño,5,9),1),"ddd") -> vie | L33: =TEXT(WEEKDAY(DATE(CalendarioAño,5,10),1),"ddd") -> sáb | M33: =TEXT(WEEKDAY(DATE(CalendarioAño,5,11),1),"ddd") -> dom | N33: =TEXT(WEEKDAY(DATE(CalendarioAño,5,12),1),"ddd") -> lun | O33: =TEXT(WEEKDAY(DATE(CalendarioAño,5,13),1),"ddd") -> mar | P33: =TEXT(WEEKDAY(DATE(CalendarioAño,5,14),1),"ddd") -> mié | Q33: =TEXT(WEEKDAY(DATE(CalendarioAño,5,15),1),"ddd") -> jue | R33: =TEXT(WEEKDAY(DATE(CalendarioAño,5,16),1),"ddd") -> vie | S33: =TEXT(WEEKDAY(DATE(CalendarioAño,5,17),1),"ddd") -> sáb | T33: =TEXT(WEEKDAY(DATE(CalendarioAño,5,18),1),"ddd") -> dom | U33: =TEXT(WEEKDAY(DATE(CalendarioAño,5,19),1),"ddd") -> lun | V33: =TEXT(WEEKDAY(DATE(CalendarioAño,5,20),1),"ddd") -> mar | W33: =TEXT(WEEKDAY(DATE(CalendarioAño,5,21),1),"ddd") -> mié | X33: =TEXT(WEEKDAY(DATE(CalendarioAño,5,22),1),"ddd") -> jue | Y33: =TEXT(WEEKDAY(DATE(CalendarioAño,5,23),1),"ddd") -> vie | Z33: =TEXT(WEEKDAY(DATE(CalendarioAño,5,24),1),"ddd") -> sáb | AA33: =TEXT(WEEKDAY(DATE(CalendarioAño,5,25),1),"ddd") -> dom | AB33: =TEXT(WEEKDAY(DATE(CalendarioAño,5,26),1),"ddd") -> lun | AC33: =TEXT(WEEKDAY(DATE(CalendarioAño,5,27),1),"ddd") -> mar | AD33: =TEXT(WEEKDAY(DATE(CalendarioAño,5,28),1),"ddd") -> mié | AE33: =TEXT(WEEKDAY(DATE(CalendarioAño,5,29),1),"ddd") -> jue | AF33: =TEXT(WEEKDAY(DATE(CalendarioAño,5,30),1),"ddd") -> vie | AG33: =TEXT(WEEKDAY(DATE(CalendarioAño,5,31),1),"ddd") -> sáb
B34: Nombre del empleado | C34: 1 | D34: 2 | E34: 3 | F34: 4 | G34: 5 | H34: 6 | I34: 7 | J34: 8 | K34: 9 | L34: 10 | M34: 11 | N34: 12 | O34: 13 | P34: 14 | Q34: 15 | R34: 16 | S34: 17 | T34: 18 | U34: 19 | V34: 20 | W34: 21 | X34: 22 | Y34: 23 | Z34: 24 | AA34: 25 | AB34: 26 | AC34: 27 | AD34: 28 | AE34: 29 | AF34: 30 | AG34: 31 | AH34: Número total de días
B35: CAMILA MAUREEN GARCIA VEGA | D35: A | G35: A | I35: A | N35: A | R35: A | W35: A | AD35: A | AF35: A
B36: FERNANDA SOCA MEDRARO | E36: A | J36: A | S36: A | X36: A | Z36: A | AE36: A
B37: MARIA FERNANDA ORBEGOSO LOPEZ | H37: A | J37: A | O37: A | Q37: A | X37: A
B38: PIA TORERO MERINO | E38: A | L38: A | S38: A | Z38: A | AH38: 4
B39: SALVADOR EFRAIN BUSTAMANTE PEREZ | E39: A
B40: JOSE ANDRES VELIZ HAYTA | E40: A | L40: A | S40: A
B41: JESUS MICHILOT | H41: A | L41: A | Q41: A | R41: A | S41: A | AD41: A | AE41: A | AF41: A | AH41: 8
B42: MAR PORTOCARRERO BERNAOLA | R42: A | S42: A
B43: MICAELA PORTOCARRERO BERNAOLA | R43: A | S43: A
B44: NICOLAS SULLON ANDAGUA | R44: A | U44: A | W44: A | AB44: A | AD44: A
B45: CAMILO ROSAMO | W45: A | AD45: A
B46: TADEO GOMEZ VASQUEZ | AD46: A
B49: =Mayo!MonthName&" Total" -> Mayo Total | AH49: =SUM(C49:AG49) -> 0
B51: Mayo | C51: BABY WOLF 4:30 PM | AH51: =CalendarioAño -> 2025
C52: =TEXT(WEEKDAY(DATE(CalendarioAño,5,1),1),"ddd") -> jue | D52: =TEXT(WEEKDAY(DATE(CalendarioAño,5,2),1),"ddd") -> vie | E52: =TEXT(WEEKDAY(DATE(CalendarioAño,5,3),1),"ddd") -> sáb | F52: =TEXT(WEEKDAY(DATE(CalendarioAño,5,4),1),"ddd") -> dom | G52: =TEXT(WEEKDAY(DATE(CalendarioAño,5,5),1),"ddd") -> lun | H52: =TEXT(WEEKDAY(DATE(CalendarioAño,5,6),1),"ddd") -> mar | I52: =TEXT(WEEKDAY(DATE(CalendarioAño,5,7),1),"ddd") -> mié | J52: =TEXT(WEEKDAY(DATE(CalendarioAño,5,8),1),"ddd") -> jue | K52: =TEXT(WEEKDAY(DATE(CalendarioAño,5,9),1),"ddd") -> vie | L52: =TEXT(WEEKDAY(DATE(CalendarioAño,5,10),1),"ddd") -> sáb | M52: =TEXT(WEEKDAY(DATE(CalendarioAño,5,11),1),"ddd") -> dom | N52: =TEXT(WEEKDAY(DATE(CalendarioAño,5,12),1),"ddd") -> lun | O52: =TEXT(WEEKDAY(DATE(CalendarioAño,5,13),1),"ddd") -> mar | P52: =TEXT(WEEKDAY(DATE(CalendarioAño,5,14),1),"ddd") -> mié | Q52: =TEXT(WEEKDAY(DATE(CalendarioAño,5,15),1),"ddd") -> jue | R52: =TEXT(WEEKDAY(DATE(CalendarioAño,5,16),1),"ddd") -> vie | S52: =TEXT(WEEKDAY(DATE(CalendarioAño,5,17),1),"ddd") -> sáb | T52: =TEXT(WEEKDAY(DATE(CalendarioAño,5,18),1),"ddd") -> dom | U52: =TEXT(WEEKDAY(DATE(CalendarioAño,5,19),1),"ddd") -> lun | V52: =TEXT(WEEKDAY(DATE(CalendarioAño,5,20),1),"ddd") -> mar | W52: =TEXT(WEEKDAY(DATE(CalendarioAño,5,21),1),"ddd") -> mié | X52: =TEXT(WEEKDAY(DATE(CalendarioAño,5,22),1),"ddd") -> jue | Y52: =TEXT(WEEKDAY(DATE(CalendarioAño,5,23),1),"ddd") -> vie | Z52: =TEXT(WEEKDAY(DATE(CalendarioAño,5,24),1),"ddd") -> sáb | AA52: =TEXT(WEEKDAY(DATE(CalendarioAño,5,25),1),"ddd") -> dom | AB52: =TEXT(WEEKDAY(DATE(CalendarioAño,5,26),1),"ddd") -> lun | AC52: =TEXT(WEEKDAY(DATE(CalendarioAño,5,27),1),"ddd") -> mar | AD52: =TEXT(WEEKDAY(DATE(CalendarioAño,5,28),1),"ddd") -> mié | AE52: =TEXT(WEEKDAY(DATE(CalendarioAño,5,29),1),"ddd") -> jue | AF52: =TEXT(WEEKDAY(DATE(CalendarioAño,5,30),1),"ddd") -> vie | AG52: =TEXT(WEEKDAY(DATE(CalendarioAño,5,31),1),"ddd") -> sáb
B53: Nombre del empleado | C53: 1 | D53: 2 | E53: 3 | F53: 4 | G53: 5 | H53: 6 | I53: 7 | J53: 8 | K53: 9 | L53: 10 | M53: 11 | N53: 12 | O53: 13 | P53: 14 | Q53: 15 | R53: 16 | S53: 17 | T53: 18 | U53: 19 | V53: 20 | W53: 21 | X53: 22 | Y53: 23 | Z53: 24 | AA53: 25 | AB53: 26 | AC53: 27 | AD53: 28 | AE53: 29 | AF53: 30 | AG53: 31 | AH53: Número total de días
B54: RODRIGO ALEJANDRO PALOMIO CAMPOS | D54: A | I54: A | J54: A | O54: A | R54: A | W54: A | X54: A | AE54: A | AF54: A
B55: VASCO DIAZ TAPIA | D55: A | E55: AA | U55: A | W55: A
B56: ANTONELLA ESPERANZA OLANO CONTRERAS | E56: A | J56: AA | L56: AA | N56: A | Q56: A | W56: A | Z56: A | AB56: A | AC56: A | AF56: A
B57: ARON CANAVAL FLORIAN | E57: A | L57: A | S57: A | Z57: A
...

Sheet Junio
B1: ASISTENCIA DE ALUMNOS
B2: Claves de los tipos de Asistencia | C2: V | D2: Vacaciones | G2: P | H2: Personal | K2: A | L2: Asistencia | O2: R | P2: Recuperacion | T2: E | U2: Eventos
B4: Junio | C4: SUPER BABY WOLF 3:00 PM | AH4: =CalendarioAño -> 2025
C5: =TEXT(WEEKDAY(DATE(CalendarioAño,6,1),1),"ddd") -> dom | D5: =TEXT(WEEKDAY(DATE(CalendarioAño,6,2),1),"ddd") -> lun | E5: =TEXT(WEEKDAY(DATE(CalendarioAño,6,3),1),"ddd") -> mar | F5: =TEXT(WEEKDAY(DATE(CalendarioAño,6,4),1),"ddd") -> mié | G5: =TEXT(WEEKDAY(DATE(CalendarioAño,6,5),1),"ddd") -> jue | H5: =TEXT(WEEKDAY(DATE(CalendarioAño,6,6),1),"ddd") -> vie | I5: =TEXT(WEEKDAY(DATE(CalendarioAño,6,7),1),"ddd") -> sáb | J5: =TEXT(WEEKDAY(DATE(CalendarioAño,6,8),1),"ddd") -> dom | K5: =TEXT(WEEKDAY(DATE(CalendarioAño,6,9),1),"ddd") -> lun | L5: =TEXT(WEEKDAY(DATE(CalendarioAño,6,10),1),"ddd") -> mar | M5: =TEXT(WEEKDAY(DATE(CalendarioAño,6,11),1),"ddd") -> mié | N5: =TEXT(WEEKDAY(DATE(CalendarioAño,6,12),1),"ddd") -> jue | O5: =TEXT(WEEKDAY(DATE(CalendarioAño,6,13),1),"ddd") -> vie | P5: =TEXT(WEEKDAY(DATE(CalendarioAño,6,14),1),"ddd") -> sáb | Q5: =TEXT(WEEKDAY(DATE(CalendarioAño,6,15),1),"ddd") -> dom | R5: =TEXT(WEEKDAY(DATE(CalendarioAño,6,16),1),"ddd") -> lun | S5: =TEXT(WEEKDAY(DATE(CalendarioAño,6,17),1),"ddd") -> mar | T5: =TEXT(WEEKDAY(DATE(CalendarioAño,6,18),1),"ddd") -> mié | U5: =TEXT(WEEKDAY(DATE(CalendarioAño,6,19),1),"ddd") -> jue | V5: =TEXT(WEEKDAY(DATE(CalendarioAño,6,20),1),"ddd") -> vie | W5: =TEXT(WEEKDAY(DATE(CalendarioAño,6,21),1),"ddd") -> sáb | X5: =TEXT(WEEKDAY(DATE(CalendarioAño,6,22),1),"ddd") -> dom | Y5: =TEXT(WEEKDAY(DATE(CalendarioAño,6,23),1),"ddd") -> lun | Z5: =TEXT(WEEKDAY(DATE(CalendarioAño,6,24),1),"ddd") -> mar | AA5: =TEXT(WEEKDAY(DATE(CalendarioAño,6,25),1),"ddd") -> mié | AB5: =TEXT(WEEKDAY(DATE(CalendarioAño,6,26),1),"ddd") -> jue | AC5: =TEXT(WEEKDAY(DATE(CalendarioAño,6,27),1),"ddd") -> vie | AD5: =TEXT(WEEKDAY(DATE(CalendarioAño,6,28),1),"ddd") -> sáb | AE5: =TEXT(WEEKDAY(DATE(CalendarioAño,6,29),1),"ddd") -> dom | AF5: =TEXT(WEEKDAY(DATE(CalendarioAño,6,30),1),"ddd") -> lun
