Workbook
Name ColumnTitle13: EmployeeName[[#Headers],[ALUMNOS ]]
Name Titulo1: Enero[[#Headers],[NOMBRE Y APELLIDO]]
Name Titulo10: Octubre[[#Headers],[Nombre del empleado]]
Name Titulo11: Noviembre[[#Headers],[Nombre del empleado]]
Name Titulo12: Diciembre[[#Headers],[Nombre del empleado]]
Name Titulo2: Febrero[[#Headers],[NOMBRE Y APELLIDOS]]
Name Titulo3: Marzo[[#Headers],[Nombre del empleado]]
Name Titulo4: Abril[[#Headers],[Nombre del empleado]]
Name Titulo5: Mayo[[#Headers],[Nombre del empleado]]
Name Titulo6: Junio[[#Headers],[Nombre del empleado]]
Name Titulo7: Julio[[#Headers],[Nombre del empleado]]
Name Titulo8: Agosto[[#Headers],[Nombre del empleado]]
Name Titulo9: Septiembre[[#Headers],[Nombre del empleado]]
Name KeySick: Setiembre!$K$2
Name KeyVacationLabel: Junio!$D$2
Name MonthName: Octubre!$B$4
Name KeyPersonalLabel: Abril!$H$2
Name CalendarioAño: Abril!$AG$4
Name Key_name: Octubre!$B$2
Name KeyVacation: Octubre!$C$2
Name KeyVacationLabel: Febrero!$D$2
Name MonthName: Abril!$B$4
Name KeyVacationLabel: Julio!$D$2
Name CalendarioAño: Octubre!$AH$4
Name Employee_Absence_Title: Julio!$B$1
Name KeyCustom1Label: Mayo!$P$2
Name KeyPersonalLabel: Marzo!$H$2
Name KeyVacationLabel: Octubre!$D$2
Name KeyVacationLabel: Marzo!$D$2
Name CalendarioAño: Noviembre!$AH$4
Name KeyPersonalLabel: Febrero!$H$2
Name KeySickLabel: Julio!$L$2
Name KeyVacation: Setiembre!$C$2
Name KeySickLabel: Marzo!$L$2
Name CalendarioAño: Junio!$AH$4
Name CalendarioAño: Febrero!$AD$4
Name KeyCustom1: Agosto!$O$2
Name KeySickLabel: Octubre!$L$2
Name KeySickLabel: Enero!$L$2
Name KeyPersonalLabel: Junio!$H$2
Name KeyCustom2: Marzo!$T$2
Name KeyPersonalLabel: Noviembre!$H$2
Name KeyCustom1: #REF!
Name KeySick: Enero!$K$2
Name KeyPersonal: Diciembre!$G$2
Name KeyCustom1Label: Diciembre!$P$2
Name KeyCustom2Label: Diciembre!$U$2
Name KeySick: Diciembre!$K$2
Name KeyCustom1Label: Febrero!$P$2
Name KeyCustom2: Mayo!$T$2
Name KeyVacation: Mayo!$C$2
Name KeyPersonal: Setiembre!$G$2
Name Key_name: #REF!
Name KeyCustom1Label: Agosto!$P$2
Name KeyCustom1: Diciembre!$O$2
Name KeyPersonalLabel: #REF!
Name KeyCustom2: Agosto!$T$2
Name Employee_Absence_Title: Diciembre!$B$1
Name KeyVacation: Junio!$C$2
Name KeyVacationLabel: Abril!$D$2

Sheet Enero
B1: ASISTENCIA DE ALUMNOS
B2: Claves de los tipos de Asistencia | C2: F | D2: FALTAS | G2: J | H2: JUSTIFICADA | K2: A | L2: ASISTENCIA | O2: R | P2: RECUPERACION | T2: E | U2: EVENTOS
B4: Enero | C4: MEGA SUPER BABY WOLF 3:00 PM/9:00 AM | AH4: 2026
C5: =TEXT(WEEKDAY(DATE(Enero!CalendarioAño,1,1),1),"ddd") -> jue | D5: =TEXT(WEEKDAY(DATE(Enero!CalendarioAño,1,2),1),"ddd") -> vie | E5: =TEXT(WEEKDAY(DATE(Enero!CalendarioAño,1,3),1),"ddd") -> sáb | F5: =TEXT(WEEKDAY(DATE(Enero!CalendarioAño,1,4),1),"ddd") -> dom | G5: =TEXT(WEEKDAY(DATE(Enero!CalendarioAño,1,5),1),"ddd") -> lun | H5: =TEXT(WEEKDAY(DATE(Enero!CalendarioAño,1,6),1),"ddd") -> mar | I5: =TEXT(WEEKDAY(DATE(Enero!CalendarioAño,1,7),1),"ddd") -> mié | J5: =TEXT(WEEKDAY(DATE(Enero!CalendarioAño,1,8),1),"ddd") -> jue | K5: =TEXT(WEEKDAY(DATE(Enero!CalendarioAño,1,9),1),"ddd") -> vie | L5: =TEXT(WEEKDAY(DATE(Enero!CalendarioAño,1,10),1),"ddd") -> sáb | M5: =TEXT(WEEKDAY(DATE(Enero!CalendarioAño,1,11),1),"ddd") -> dom | N5: =TEXT(WEEKDAY(DATE(Enero!CalendarioAño,1,12),1),"ddd") -> lun | O5: =TEXT(WEEKDAY(DATE(Enero!CalendarioAño,1,13),1),"ddd") -> mar | P5: =TEXT(WEEKDAY(DATE(Enero!CalendarioAño,1,14),1),"ddd") -> mié | Q5: =TEXT(WEEKDAY(DATE(Enero!CalendarioAño,1,15),1),"ddd") -> jue | R5: =TEXT(WEEKDAY(DATE(Enero!CalendarioAño,1,16),1),"ddd") -> vie | S5: =TEXT(WEEKDAY(DATE(Enero!CalendarioAño,1,17),1),"ddd") -> sáb | T5: =TEXT(WEEKDAY(DATE(Enero!CalendarioAño,1,18),1),"ddd") -> dom | U5: =TEXT(WEEKDAY(DATE(Enero!CalendarioAño,1,19),1),"ddd") -> lun | V5: =TEXT(WEEKDAY(DATE(Enero!CalendarioAño,1,20),1),"ddd") -> mar | W5: =TEXT(WEEKDAY(DATE(Enero!CalendarioAño,1,21),1),"ddd") -> mié | X5: =TEXT(WEEKDAY(DATE(Enero!CalendarioAño,1,22),1),"ddd") -> jue | Y5: =TEXT(WEEKDAY(DATE(Enero!CalendarioAño,1,23),1),"ddd") -> vie | Z5: =TEXT(WEEKDAY(DATE(Enero!CalendarioAño,1,24),1),"ddd") -> sáb | AA5: =TEXT(WEEKDAY(DATE(Enero!CalendarioAño,1,25),1),"ddd") -> dom | AB5: =TEXT(WEEKDAY(DATE(Enero!CalendarioAño,1,26),1),"ddd") -> lun | AC5: =TEXT(WEEKDAY(DATE(Enero!CalendarioAño,1,27),1),"ddd") -> mar | AD5: =TEXT(WEEKDAY(DATE(Enero!CalendarioAño,1,28),1),"ddd") -> mié | AE5: =TEXT(WEEKDAY(DATE(Enero!CalendarioAño,1,29),1),"ddd") -> jue | AF5: =TEXT(WEEKDAY(DATE(Enero!CalendarioAño,1,30),1),"ddd") -> vie | AG5: =TEXT(WEEKDAY(DATE(Enero!CalendarioAño,1,31),1),"ddd") -> sáb
B6: NOMBRE Y APELLIDO | C6: 1 | D6: 2 | E6: 3 | F6: 4 | G6: 5 | H6: 6 | I6: 7 | J6: 8 | K6: 9 | L6: 10 | M6: 11 | N6: 12 | O6: 13 | P6: 14 | Q6: 15 | R6: 16 | S6: 17 | T6: 18 | U6: 19 | V6: 20 | W6: 21 | X6: 22 | Y6: 23 | Z6: 24 | AA6: 25 | AB6: 26 | AC6: 27 | AD6: 28 | AE6: 29 | AF6: 30 | AG6: 31 | AH6: Número total de días
B8: =Enero!MonthName&" Total" -> Enero Total | C8: =SUBTOTAL(103,Enero!$C$7) -> 0 | D8: =SUBTOTAL(103,Enero!$D$7) -> 0 | E8: =SUBTOTAL(103,Enero!$E$7) -> 0 | F8: =SUBTOTAL(103,Enero!$F$7) -> 0 | G8: =SUBTOTAL(103,Enero!$G$7) -> 0 | H8: =SUBTOTAL(103,Enero!$H$7) -> 0 | I8: =SUBTOTAL(103,Enero!$I$7) -> 0 | J8: =SUBTOTAL(103,Enero!$J$7) -> 0 | K8: =SUBTOTAL(103,Enero!$K$7) -> 0 | L8: =SUBTOTAL(103,Enero!$L$7) -> 0 | M8: =SUBTOTAL(103,Enero!$M$7) -> 0 | N8: =SUBTOTAL(103,Enero!$N$7) -> 0 | O8: =SUBTOTAL(103,Enero!$O$7) -> 0 | P8: =SUBTOTAL(103,Enero!$P$7) -> 0 | Q8: =SUBTOTAL(103,Enero!$Q$7) -> 0 | R8: =SUBTOTAL(103,Enero!$R$7) -> 0 | S8: =SUBTOTAL(103,Enero!$S$7) -> 0 | T8: =SUBTOTAL(103,Enero!$T$7) -> 0 | U8: =SUBTOTAL(103,Enero!$U$7) -> 0 | V8: =SUBTOTAL(103,Enero!$V$7) -> 0 | W8: =SUBTOTAL(103,Enero!$W$7) -> 0 | X8: =SUBTOTAL(103,Enero!$X$7) -> 0 | Y8: =SUBTOTAL(103,Enero!$Y$7) -> 0 | Z8: =SUBTOTAL(103,Enero!$Z$7) -> 0 | AA8: =SUBTOTAL(103,Enero!$AA$7) -> 0 | AB8: =SUBTOTAL(103,Enero!$AB$7) -> 0 | AC8: =SUBTOTAL(103,Enero!$AC$7) -> 0 | AD8: =SUBTOTAL(103,Enero!$AD$7) -> 0 | AE8: =SUBTOTAL(103,Enero!$AE$7) -> 0 | AF8: =SUBTOTAL(103,Enero!$AF$7) -> 0 | AG8: =SUBTOTAL(103,Enero!$AG$7) -> 0
B10: Enero | C10: SUPER BABY WOLF 3:30 PM/9:30 AM | AH10: 2026
C11: =TEXT(WEEKDAY(DATE(Enero!CalendarioAño,1,1),1),"ddd") -> jue | D11: =TEXT(WEEKDAY(DATE(Enero!CalendarioAño,1,2),1),"ddd") -> vie | E11: =TEXT(WEEKDAY(DATE(Enero!CalendarioAño,1,3),1),"ddd") -> sáb | F11: =TEXT(WEEKDAY(DATE(Enero!CalendarioAño,1,4),1),"ddd") -> dom | G11: =TEXT(WEEKDAY(DATE(Enero!CalendarioAño,1,5),1),"ddd") -> lun | H11: =TEXT(WEEKDAY(DATE(Enero!CalendarioAño,1,6),1),"ddd") -> mar | I11: =TEXT(WEEKDAY(DATE(Enero!CalendarioAño,1,7),1),"ddd") -> mié | J11: =TEXT(WEEKDAY(DATE(Enero!CalendarioAño,1,8),1),"ddd") -> jue | K11: =TEXT(WEEKDAY(DATE(Enero!CalendarioAño,1,9),1),"ddd") -> vie | L11: =TEXT(WEEKDAY(DATE(Enero!CalendarioAño,1,10),1),"ddd") -> sáb | M11: =TEXT(WEEKDAY(DATE(Enero!CalendarioAño,1,11),1),"ddd") -> dom | N11: =TEXT(WEEKDAY(DATE(Enero!CalendarioAño,1,12),1),"ddd") -> lun | O11: =TEXT(WEEKDAY(DATE(Enero!CalendarioAño,1,13),1),"ddd") -> mar | P11: =TEXT(WEEKDAY(DATE(Enero!CalendarioAño,1,14),1),"ddd") -> mié | Q11: =TEXT(WEEKDAY(DATE(Enero!CalendarioAño,1,15),1),"ddd") -> jue | R11: =TEXT(WEEKDAY(DATE(Enero!CalendarioAño,1,16),1),"ddd") -> vie | S11: =TEXT(WEEKDAY(DATE(Enero!CalendarioAño,1,17),1),"ddd") -> sáb | T11: =TEXT(WEEKDAY(DATE(Enero!CalendarioAño,1,18),1),"ddd") -> dom | U11: =TEXT(WEEKDAY(DATE(Enero!CalendarioAño,1,19),1),"ddd") -> lun | V11: =TEXT(WEEKDAY(DATE(Enero!CalendarioAño,1,20),1),"ddd") -> mar | W11: =TEXT(WEEKDAY(DATE(Enero!CalendarioAño,1,21),1),"ddd") -> mié | X11: =TEXT(WEEKDAY(DATE(Enero!CalendarioAño,1,22),1),"ddd") -> jue | Y11: =TEXT(WEEKDAY(DATE(Enero!CalendarioAño,1,23),1),"ddd") -> vie | Z11: =TEXT(WEEKDAY(DATE(Enero!CalendarioAño,1,24),1),"ddd") -> sáb | AA11: =TEXT(WEEKDAY(DATE(Enero!CalendarioAño,1,25),1),"ddd") -> dom | AB11: =TEXT(WEEKDAY(DATE(Enero!CalendarioAño,1,26),1),"ddd") -> lun | AC11: =TEXT(WEEKDAY(DATE(Enero!CalendarioAño,1,27),1),"ddd") -> mar | AD11: =TEXT(WEEKDAY(DATE(Enero!CalendarioAño,1,28),1),"ddd") -> mié | AE11: =TEXT(WEEKDAY(DATE(Enero!CalendarioAño,1,29),1),"ddd") -> jue | AF11: =TEXT(WEEKDAY(DATE(Enero!CalendarioAño,1,30),1),"ddd") -> vie | AG11: =TEXT(WEEKDAY(DATE(Enero!CalendarioAño,1,31),1),"ddd") -> sáb
B12: NOMBRE Y APELLIDO | C12: 1 | D12: 2 | E12: 3 | F12: 4 | G12: 5 | H12: 6 | I12: 7 | J12: 8 | K12: 9 | L12: 10 | M12: 11 | N12: 12 | O12: 13 | P12: 14 | Q12: 15 | R12: 16 | S12: 17 | T12: 18 | U12: 19 | V12: 20 | W12: 21 | X12: 22 | Y12: 23 | Z12: 24 | AA12: 25 | AB12: 26 | AC12: 27 | AD12: 28 | AE12: 29 | AF12: 30 | AG12: 31 | AH12: Número total de días
B13: RAFAEL ALEJANDRO LUYO ALVARADO | G13: A | H13: A | I13: A | J13: A | K13: A | Y13: A | AB13: A | AD13: A | AE13: A
B14: OLIVIA GOÑES SERNA | G14: A | H14: A | J14: A | N14: A | Q14: A | AE14: A
B15: NOHA CASTILLO PRADO | G15: A | J15: A | N15: A | Q15: A | AB15: A | AE15: A
B16: ANIA SILVA CHÁVEZ | H16: A | J16: A | O16: A | Q16: A | AC16: A | AE16: A
B17: ADRIANA CLAUDIA ALVARADO ALVAREZ | I17: A | K17: A | N17: A | U17: A | W17: A | Y17: A | AD17: A | AE17: A
B18: ALESSIA VALENTINA ROJAS DÍAZ | H18: A | I18: A | K18: A | R18: A | W18: A | Y18: A | AD18: A
B19: JULEN EZEQUIEL GORAN RAMÍREZ MAQUERS | J19: A | L19: A | Q19: A | S19: A | V19: A | X19: A | AE19: A | AG19: A
B20: ADRIEL RAZEK ALFARO HUAMANI | J20: A
B21: VASCO ALEJANDRO QUEVEDO OROZ | J21: A | O21: A | Q21: A | V21: A | Y21: A | AC21: A
B22: MATTHEW GAEL ORTIZ OLAYA | H22: A | J22: A | O22: A | Q22: A | V22: A | X22: A | AC22: A | AE22: A
B23: LUCIANA CELESTE BERNIS SAMAME | I23: A | O23: A | Q23: A
B24: ISSAC DARITH ALVARADO OLIVARES | L24: A | R24: A | Y24: A | Z24: A | AG24: A
B25: ALHANNA ATHENEA HUAMANI CORTIJO | H25: A | O25: A | Q25: A | V25: A | X25: A | AE25: A
B26: GABRIEL ANDRÉS CASTAÑEDA CÁCERES | H26: A | O26: A | V26: A
B27: AARON ALESSANDRO INGA ARZAPALO | H27: A | S27: A | V27: A | Z27: A | AD27: A | AG27: A
B28: JULIETA MALDONADO GUEVARA | X28: A | AB28: A | AE28: A
B29: MARCELO SUAREZ FLORES | Z29: A | AG29: A
B30: ANTONELLA ZEA ESPINOZA | AB30: A
B31: MATT JESÚS AURES GUTIÉRREZ | AC31: A | AE31: A
B34: =Enero!MonthName&" Total" -> Enero Total | C34: =SUBTOTAL(103,Enero!$C$7) -> 0 | D34: =SUBTOTAL(103,Enero!$D$7) -> 0 | E34: =SUBTOTAL(103,Enero!$E$7) -> 0 | G34: =SUBTOTAL(103,Enero!$G$7) -> 0 | H34: =SUBTOTAL(103,Enero!$H$7) -> 0
B37: Enero | C37: SUPER BABY WOLF 4:00 PM /10:00 AM | AH37: 2026
C38: =TEXT(WEEKDAY(DATE(Enero!CalendarioAño,1,1),1),"ddd") -> jue | D38: =TEXT(WEEKDAY(DATE(Enero!CalendarioAño,1,2),1),"ddd") -> vie | E38: =TEXT(WEEKDAY(DATE(Enero!CalendarioAño,1,3),1),"ddd") -> sáb | F38: =TEXT(WEEKDAY(DATE(Enero!CalendarioAño,1,4),1),"ddd") -> dom | G38: =TEXT(WEEKDAY(DATE(Enero!CalendarioAño,1,5),1),"ddd") -> lun | H38: =TEXT(WEEKDAY(DATE(Enero!CalendarioAño,1,6),1),"ddd") -> mar | I38: =TEXT(WEEKDAY(DATE(Enero!CalendarioAño,1,7),1),"ddd") -> mié | J38: =TEXT(WEEKDAY(DATE(Enero!CalendarioAño,1,8),1),"ddd") -> jue | K38: =TEXT(WEEKDAY(DATE(Enero!CalendarioAño,1,9),1),"ddd") -> vie | L38: =TEXT(WEEKDAY(DATE(Enero!CalendarioAño,1,10),1),"ddd") -> sáb | M38: =TEXT(WEEKDAY(DATE(Enero!CalendarioAño,1,11),1),"ddd") -> dom | N38: =TEXT(WEEKDAY(DATE(Enero!CalendarioAño,1,12),1),"ddd") -> lun | O38: =TEXT(WEEKDAY(DATE(Enero!CalendarioAño,1,13),1),"ddd") -> mar | P38: =TEXT(WEEKDAY(DATE(Enero!CalendarioAño,1,14),1),"ddd") -> mié | Q38: =TEXT(WEEKDAY(DATE(Enero!CalendarioAño,1,15),1),"ddd") -> jue | R38: =TEXT(WEEKDAY(DATE(Enero!CalendarioAño,1,16),1),"ddd") -> vie | S38: =TEXT(WEEKDAY(DATE(Enero!CalendarioAño,1,17),1),"ddd") -> sáb | T38: =TEXT(WEEKDAY(DATE(Enero!CalendarioAño,1,18),1),"ddd") -> dom | U38: =TEXT(WEEKDAY(DATE(Enero!CalendarioAño,1,19),1),"ddd") -> lun | V38: =TEXT(WEEKDAY(DATE(Enero!CalendarioAño,1,20),1),"ddd") -> mar | W38: =TEXT(WEEKDAY(DATE(Enero!CalendarioAño,1,21),1),"ddd") -> mié | X38: =TEXT(WEEKDAY(DATE(Enero!CalendarioAño,1,22),1),"ddd") -> jue | Y38: =TEXT(WEEKDAY(DATE(Enero!CalendarioAño,1,23),1),"ddd") -> vie | Z38: =TEXT(WEEKDAY(DATE(Enero!CalendarioAño,1,24),1),"ddd") -> sáb | AA38: =TEXT(WEEKDAY(DATE(Enero!CalendarioAño,1,25),1),"ddd") -> dom | AB38: =TEXT(WEEKDAY(DATE(Enero!CalendarioAño,1,26),1),"ddd") -> lun | AC38: =TEXT(WEEKDAY(DATE(Enero!CalendarioAño,1,27),1),"ddd") -> mar | AD38: =TEXT(WEEKDAY(DATE(Enero!CalendarioAño,1,28),1),"ddd") -> mié | AE38: =TEXT(WEEKDAY(DATE(Enero!CalendarioAño,1,29),1),"ddd") -> jue | AF38: =TEXT(WEEKDAY(DATE(Enero!CalendarioAño,1,30),1),"ddd") -> vie | AG38: =TEXT(WEEKDAY(DATE(Enero!CalendarioAño,1,31),1),"ddd") -> sáb
B39: NOMBRE Y APELLIDO | C39: 1 | D39: 2 | E39: 3 | F39: 4 | G39: 5 | H39: 6 | I39: 7 | J39: 8 | K39: 9 | L39: 10 | M39: 11 | N39: 12 | O39: 13 | P39: 14 | Q39: 15 | R39: 16 | S39: 17 | T39: 18 | U39: 19 | V39: 20 | W39: 21 | X39: 22 | Y39: 23 | Z39: 24 | AA39: 25 | AB39: 26 | AC39: 27 | AD39: 28 | AE39: 29 | AF39: 30 | AG39: 31 | AH39: Número total de días
B40: ALEJANDRO JOAQUÍN TELLO SALAS | G40: A | I40: A | N40: A | R40: A | U40: A | W40: A | AD40: A
B41: ETHAN LIAM EDUARDO CHICCHON APAZA | G41: A | K41: A | R41: A | U41: A | W41: A | AB41: A | AD41: A
B42: ALBA CAYETANA YEPEZ VELIZ | G42: A | N42: A | V42: A | X42: A | AC42: A | AG42: A
B43: AITANA POLO MERCADO | H43: A | J43: A | Q43: A | AC43: A
B44: ORLANDO GABRIEL BOCANEGRA RIVASPLATA | I44: A | K44: A | R44: A | W44: A | Y44: A | AB44: A | AD44: A
B45: RAFAEL ALESSANDRO ESPINOZA ROJAS | H45: A | U45: A | V45: A | X45: A | Y45: A
B46: DYLAN ESTEBAN CHACÓN RIVAS | I46: A | K46: A | W46: A | Y46: A | AB46: A | AD46: A
B47: PIERO VALENTINO GONZALES NÚÑEZ | I47: A | N47: A | S47: A | U47: A | AB47: A | AD47: A | AG47: A
...

Sheet Febrero
B1: ASISTENCIA DE ALUMNOS
B2: Claves de los tipos de Asistencia | C2: F | D2: FALTAS | G2: J | H2: JUSTIFICADA | K2: A | L2: ASISTENCIA | O2: R | P2: RECUPERACION | T2: E | U2: EVENTOS
B4: Enero | C4: MEGA SUPER BABY WOLF 3:00 PM/9:00 AM | AD4: 2026
C5: =TEXT(WEEKDAY(DATE(Febrero!CalendarioAño,1,5),1),"ddd") -> lun | D5: =TEXT(WEEKDAY(DATE(Febrero!CalendarioAño,1,6),1),"ddd") -> mar | E5: =TEXT(WEEKDAY(DATE(Febrero!CalendarioAño,1,7),1),"ddd") -> mié | F5: =TEXT(WEEKDAY(DATE(Febrero!CalendarioAño,1,8),1),"ddd") -> jue | G5: =TEXT(WEEKDAY(DATE(Febrero!CalendarioAño,1,9),1),"ddd") -> vie | H5: =TEXT(WEEKDAY(DATE(Febrero!CalendarioAño,1,10),1),"ddd") -> sáb | I5: =TEXT(WEEKDAY(DATE(Febrero!CalendarioAño,1,11),1),"ddd") -> dom | J5: =TEXT(WEEKDAY(DATE(Febrero!CalendarioAño,1,5),1),"ddd") -> lun | K5: =TEXT(WEEKDAY(DATE(Febrero!CalendarioAño,1,6),1),"ddd") -> mar | L5: =TEXT(WEEKDAY(DATE(Febrero!CalendarioAño,1,7),1),"ddd") -> mié | M5: =TEXT(WEEKDAY(DATE(Febrero!CalendarioAño,1,8),1),"ddd") -> jue | N5: =TEXT(WEEKDAY(DATE(Febrero!CalendarioAño,1,9),1),"ddd") -> vie | O5: =TEXT(WEEKDAY(DATE(Febrero!CalendarioAño,1,10),1),"ddd") -> sáb | P5: =TEXT(WEEKDAY(DATE(Febrero!CalendarioAño,1,11),1),"ddd") -> dom | Q5: =TEXT(WEEKDAY(DATE(Febrero!CalendarioAño,1,5),1),"ddd") -> lun | R5: =TEXT(WEEKDAY(DATE(Febrero!CalendarioAño,1,6),1),"ddd") -> mar | S5: =TEXT(WEEKDAY(DATE(Febrero!CalendarioAño,1,7),1),"ddd") -> mié | T5: =TEXT(WEEKDAY(DATE(Febrero!CalendarioAño,1,8),1),"ddd") -> jue | U5: =TEXT(WEEKDAY(DATE(Febrero!CalendarioAño,1,9),1),"ddd") -> vie | V5: =TEXT(WEEKDAY(DATE(Febrero!CalendarioAño,1,10),1),"ddd") -> sáb | W5: =TEXT(WEEKDAY(DATE(Febrero!CalendarioAño,1,11),1),"ddd") -> dom | X5: =TEXT(WEEKDAY(DATE(Febrero!CalendarioAño,1,5),1),"ddd") -> lun | Y5: =TEXT(WEEKDAY(DATE(Febrero!CalendarioAño,1,6),1),"ddd") -> mar | Z5: =TEXT(WEEKDAY(DATE(Febrero!CalendarioAño,1,7),1),"ddd") -> mié | AA5: =TEXT(WEEKDAY(DATE(Febrero!CalendarioAño,1,8),1),"ddd") -> jue | AB5: =TEXT(WEEKDAY(DATE(Febrero!CalendarioAño,1,9),1),"ddd") -> vie | AC5: =TEXT(WEEKDAY(DATE(Febrero!CalendarioAño,1,10),1),"ddd") -> sáb
B6: NOMBRE Y APELLIDO | C6: 2 | D6: 3 | E6: 4 | F6: 5 | G6: 6 | H6: 7 | I6: 8 | J6: 9 | K6: 10 | L6: 11 | M6: 12 | N6: 13 | O6: 14 | P6: 15 | Q6: 16 | R6: 17 | S6: 18 | T6: 19 | U6: 20 | V6: 21 | W6: 22 | X6: 23 | Y6: 24 | Z6: 25 | AA6: 26 | AB6: 27 | AC6: 28 | AD6: Número total de días
B8: =Febrero!MonthName&" Total" -> Enero Total | C8: =SUBTOTAL(103,Febrero!$C$7) -> 0 | D8: =SUBTOTAL(103,Febrero!$D$7) -> 0 | E8: =SUBTOTAL(103,Febrero!$E$7) -> 0 | F8: =SUBTOTAL(103,Febrero!$F$7) -> 0 | G8: =SUBTOTAL(103,Febrero!$G$7) -> 0 | H8: =SUBTOTAL(103,Febrero!$H$7) -> 0 | I8: =SUBTOTAL(103,Febrero!$I$7) -> 0 | J8: =SUBTOTAL(103,Febrero!$J$7) -> 0 | K8: =SUBTOTAL(103,Febrero!$K$7) -> 0 | L8: =SUBTOTAL(103,Febrero!$L$7) -> 0 | M8: =SUBTOTAL(103,Febrero!$M$7) -> 0 | N8: =SUBTOTAL(103,Febrero!$N$7) -> 0 | O8: =SUBTOTAL(103,Febrero!$O$7) -> 0 | P8: =SUBTOTAL(103,Febrero!$P$7) -> 0 | Q8: =SUBTOTAL(103,Febrero!$Q$7) -> 0 | R8: =SUBTOTAL(103,Febrero!$R$7) -> 0 | S8: =SUBTOTAL(103,Febrero!$S$7) -> 0 | T8: =SUBTOTAL(103,Febrero!$T$7) -> 0 | U8: =SUBTOTAL(103,Febrero!$U$7) -> 0 | V8: =SUBTOTAL(103,Febrero!$V$7) -> 0 | W8: =SUBTOTAL(103,Febrero!$W$7) -> 0 | X8: =SUBTOTAL(103,Febrero!$X$7) -> 0 | Y8: =SUBTOTAL(103,Febrero!$Y$7) -> 0 | Z8: =SUBTOTAL(103,Febrero!$Z$7) -> 0 | AA8: =SUBTOTAL(103,Febrero!$AA$7) -> 0 | AB8: =SUBTOTAL(103,Febrero!$AB$7) -> 0 | AC8: =SUBTOTAL(103,Febrero!$AC$7) -> 0
B10: Enero | C10: SUPER BABY WOLF 3:30 PM/9:30 AM | AD10: 2026
C11: =TEXT(WEEKDAY(DATE(Febrero!CalendarioAño,1,5),1),"ddd") -> lun | D11: =TEXT(WEEKDAY(DATE(Febrero!CalendarioAño,1,6),1),"ddd") -> mar | E11: =TEXT(WEEKDAY(DATE(Febrero!CalendarioAño,1,7),1),"ddd") -> mié | F11: =TEXT(WEEKDAY(DATE(Febrero!CalendarioAño,1,8),1),"ddd") -> jue | G11: =TEXT(WEEKDAY(DATE(Febrero!CalendarioAño,1,9),1),"ddd") -> vie | H11: =TEXT(WEEKDAY(DATE(Febrero!CalendarioAño,1,10),1),"ddd") -> sáb | I11: =TEXT(WEEKDAY(DATE(Febrero!CalendarioAño,1,11),1),"ddd") -> dom | J11: =TEXT(WEEKDAY(DATE(Febrero!CalendarioAño,1,5),1),"ddd") -> lun | K11: =TEXT(WEEKDAY(DATE(Febrero!CalendarioAño,1,6),1),"ddd") -> mar | L11: =TEXT(WEEKDAY(DATE(Febrero!CalendarioAño,1,7),1),"ddd") -> mié | M11: =TEXT(WEEKDAY(DATE(Febrero!CalendarioAño,1,8),1),"ddd") -> jue | N11: =TEXT(WEEKDAY(DATE(Febrero!CalendarioAño,1,9),1),"ddd") -> vie | O11: =TEXT(WEEKDAY(DATE(Febrero!CalendarioAño,1,10),1),"ddd") -> sáb | P11: =TEXT(WEEKDAY(DATE(Febrero!CalendarioAño,1,11),1),"ddd") -> dom | Q11: =TEXT(WEEKDAY(DATE(Febrero!CalendarioAño,1,5),1),"ddd") -> lun | R11: =TEXT(WEEKDAY(DATE(Febrero!CalendarioAño,1,6),1),"ddd") -> mar | S11: =TEXT(WEEKDAY(DATE(Febrero!CalendarioAño,1,7),1),"ddd") -> mié | T11: =TEXT(WEEKDAY(DATE(Febrero!CalendarioAño,1,8),1),"ddd") -> jue | U11: =TEXT(WEEKDAY(DATE(Febrero!CalendarioAño,1,9),1),"ddd") -> vie | V11: =TEXT(WEEKDAY(DATE(Febrero!CalendarioAño,1,10),1),"ddd") -> sáb | W11: =TEXT(WEEKDAY(DATE(Febrero!CalendarioAño,1,11),1),"ddd") -> dom | X11: =TEXT(WEEKDAY(DATE(Febrero!CalendarioAño,1,5),1),"ddd") -> lun | Y11: =TEXT(WEEKDAY(DATE(Febrero!CalendarioAño,1,6),1),"ddd") -> mar | Z11: =TEXT(WEEKDAY(DATE(Febrero!CalendarioAño,1,7),1),"ddd") -> mié | AA11: =TEXT(WEEKDAY(DATE(Febrero!CalendarioAño,1,8),1),"ddd") -> jue | AB11: =TEXT(WEEKDAY(DATE(Febrero!CalendarioAño,1,9),1),"ddd") -> vie | AC11: =TEXT(WEEKDAY(DATE(Febrero!CalendarioAño,1,10),1),"ddd") -> sáb
B12: NOMBRE Y APELLIDO | C12: 2 | D12: 3 | E12: 4 | F12: 5 | G12: 6 | H12: 7 | I12: 8 | J12: 9 | K12: 10 | L12: 11 | M12: 12 | N12: 13 | O12: 14 | P12: 15 | Q12: 16 | R12: 17 | S12: 18 | T12: 19 | U12: 20 | V12: 21 | W12: 22 | X12: 23 | Y12: 24 | Z12: 25 | AA12: 26 | AB12: 27 | AC12: 28 | AD12: Número total de días
B13: RAFAEL ALEJANDRO LUYO ALVARADO | C13: A | D13: A | E13: A | F13: A | G13: A | J13: A | K13: A | L13: A | M13: A | N13: A | Q13: A | R13: A | S13: A | T13: A | U13: A
B14: OLIVIA GOÑES SERNA | C14: A | G14: A | H14: A | J14: A | L14: A | S14: A | Z14: A
B15: NOHA CASTILLO PRADO | C15: A | J15: A | M15: A | Q15: A | X15: A
B16: ANIA SILVA CHÁVEZ | D16: A | F16: A | G16: A | K16: A | Q16: A | T16: A | X16: A | AA16: A
B17: ADRIANA CLAUDIA ALVARADO ALVAREZ | E17: A | G17: A | L17: A | N17: A | S17: A | U17: A | Z17: A
B18: ALESSIA VALENTINA ROJAS DÍAZ | D18: A | E18: A | M18: A | T18: A | V18: A
B19: JULEN EZEQUIEL GORAN RAMÍREZ MAQUERS | F19: A | K19: A | M19: A | O19: A | U19: A | V19: A | Y19: A | Z19: A | AA19: A
B20: ADRIEL RAZEK ALFARO HUAMANI | K20: A | M20: A | T20: A | Y20: A | AA20: A
B21: VASCO ALEJANDRO QUEVEDO OROZ | G21: A | L21: A
B22: MATTHEW GAEL ORTIZ OLAYA | D22: A
B23: LUCIANA CELESTE BERNIS SAMAME | E23: A | F23: A | K23: A | M23: A | Q23: A | R23: A
B24: ISSAC DARITH ALVARADO OLIVARES | H24: A | L24: A | U24: A
B25: ALHANNA ATHENEA HUAMANI CORTIJO | D25: A | F25: A | K25: A | M25: A | R25: A | T25: A
B26: GABRIEL ANDRÉS CASTAÑEDA CÁCERES | D26: A | F26: A | N26: A | R26: A | U26: A
B27: AARON ALESSANDRO INGA ARZAPALO | D27: A | U27: A
B28: JULIETA MALDONADO GUEVARA | C28: A | F28: A
B29: MARCELO SUAREZ FLORES | V29: A
B30: ANTONELLA ZEA ESPINOZA | J30: A | X30: A | AA30: A
B31: MATT JESÚS AURES GUTIÉRREZ | F31: A | K31: A | R31: A | T31: A | V31: A | X31: A | AA31: A
B32: YUN HE DAVID ZHANG IZQUIERDO | C32: A | E32: A | F32: A
B33: NOAH KROES | D33: A | F33: A | K33: A | R33: A
B34: GETZENN VELIT AYALA | F34: A | H34: A | K34: A | M34: A | R34: A | T34: A | Y34: A | AA34: A
B35: CATALINA MILAGROS SANDOVAL MÉNDEZ | G35: A
B36: JOAQUIN CARBAJAL ESPINOZA | H36: A | M36: A | AA36: A
B37: LIA SALAZAR CASTILLA | T37: A | X37: A
B38: PABLO STEFANO MAZUELOS LUPACA | AA38: A
B41: =Febrero!MonthName&" Total" -> Enero Total | C41: =SUBTOTAL(103,Febrero!$C$7) -> 0 | D41: =SUBTOTAL(103,Febrero!$D$7) -> 0 | E41: =SUBTOTAL(103,Febrero!$E$7) -> 0 | G41: =SUBTOTAL(103,Febrero!$G$7) -> 0 | H41: =SUBTOTAL(103,Febrero!$H$7) -> 0
B44: Enero | C44: SUPER BABY WOLF 4:00 PM /10:00 AM | AD44: 2026
C45: =TEXT(WEEKDAY(DATE(Febrero!CalendarioAño,1,5),1),"ddd") -> lun | D45: =TEXT(WEEKDAY(DATE(Febrero!CalendarioAño,1,6),1),"ddd") -> mar | E45: =TEXT(WEEKDAY(DATE(Febrero!CalendarioAño,1,7),1),"ddd") -> mié | F45: =TEXT(WEEKDAY(DATE(Febrero!CalendarioAño,1,8),1),"ddd") -> jue | G45: =TEXT(WEEKDAY(DATE(Febrero!CalendarioAño,1,9),1),"ddd") -> vie | H45: =TEXT(WEEKDAY(DATE(Febrero!CalendarioAño,1,10),1),"ddd") -> sáb | I45: =TEXT(WEEKDAY(DATE(Febrero!CalendarioAño,1,11),1),"ddd") -> dom | J45: =TEXT(WEEKDAY(DATE(Febrero!CalendarioAño,1,5),1),"ddd") -> lun | K45: =TEXT(WEEKDAY(DATE(Febrero!CalendarioAño,1,6),1),"ddd") -> mar | L45: =TEXT(WEEKDAY(DATE(Febrero!CalendarioAño,1,7),1),"ddd") -> mié | M45: =TEXT(WEEKDAY(DATE(Febrero!CalendarioAño,1,8),1),"ddd") -> jue | N45: =TEXT(WEEKDAY(DATE(Febrero!CalendarioAño,1,9),1),"ddd") -> vie | O45: =TEXT(WEEKDAY(DATE(Febrero!CalendarioAño,1,10),1),"ddd") -> sáb | P45: =TEXT(WEEKDAY(DATE(Febrero!CalendarioAño,1,11),1),"ddd") -> dom | Q45: =TEXT(WEEKDAY(DATE(Febrero!CalendarioAño,1,5),1),"ddd") -> lun | R45: =TEXT(WEEKDAY(DATE(Febrero!CalendarioAño,1,6),1),"ddd") -> mar | S45: =TEXT(WEEKDAY(DATE(Febrero!CalendarioAño,1,7),1),"ddd") -> mié | T45: =TEXT(WEEKDAY(DATE(Febrero!CalendarioAño,1,8),1),"ddd") -> jue | U45: =TEXT(WEEKDAY(DATE(Febrero!CalendarioAño,1,9),1),"ddd") -> vie | V45: =TEXT(WEEKDAY(DATE(Febrero!CalendarioAño,1,10),1),"ddd") -> sáb | W45: =TEXT(WEEKDAY(DATE(Febrero!CalendarioAño,1,11),1),"ddd") -> dom | X45: =TEXT(WEEKDAY(DATE(Febrero!CalendarioAño,1,5),1),"ddd") -> lun | Y45: =TEXT(WEEKDAY(DATE(Febrero!CalendarioAño,1,6),1),"ddd") -> mar | Z45: =TEXT(WEEKDAY(DATE(Febrero!CalendarioAño,1,7),1),"ddd") -> mié | AA45: =TEXT(WEEKDAY(DATE(Febrero!CalendarioAño,1,8),1),"ddd") -> jue | AB45: =TEXT(WEEKDAY(DATE(Febrero!CalendarioAño,1,9),1),"ddd") -> vie | AC45: =TEXT(WEEKDAY(DATE(Febrero!CalendarioAño,1,10),1),"ddd") -> sáb
B46: NOMBRE Y APELLIDO | C46: 2 | D46: 3 | E46: 4 | F46: 5 | G46: 6 | H46: 7 | I46: 8 | J46: 9 | K46: 10 | L46: 11 | M46: 12 | N46: 13 | O46: 14 | P46: 15 | Q46: 16 | R46: 17 | S46: 18 | T46: 19 | U46: 20 | V46: 21 | W46: 22 | X46: 23 | Y46: 24 | Z46: 25 | AA46: 26 | AB46: 27 | AC46: 28 | AD46: Número total de días
B47: ALEJANDRO JOAQUÍN TELLO SALAS | E47: A | G47: A | H47: A | J47: A | L47: A | Q47: A | S47: A | X47: A | Z47: A
...

Sheet Nombres de los alumnos 
B1: NOMBRES DE ALUMNOS
B3: ALUMNOS | C3: HORARIOS
B4: MARTIN HOLGADO PAZ
B5: JADEN BASTIEN RIOS YOMOND
B6: ALEJANDRO SEBASTIAN VALENCIA GARCIA
B7: ALEXANDRA ROJAS SICLLA
B8: DAVID ALONSO VELEZ FALCÓN
B9: ALMA ISABEL CASTILLO MENDOZA
B10: THOMAS ALEJANDRO MATHEY GALINDO
B11: VASCO ALVAREZ CORREA
B12: ALEXANDER ANDRE ROMERO ROJAS
B13: CAMILO ROSARIO CABRERA
B14: RAFAEL AYVAR CUEVA
B15: ALESSIO VEGARA EZETA
... B239: LUCIANA VARGAS RAMIREZ

Sheet Marzo
B1: ASISTENCIA DE ALUMNOS
B2: Claves de los tipos de Asistencia | C2: F | D2: FALTAS | G2: J | H2: JUSTIFICADA | K2: A | L2: ASISTENCIA | O2: R | P2: RECUPERACION | T2: E | U2: EVENTOS
B4: Marzo | C4: MEGA SUPER BABY WOLF 3:00 PM/9:00 AM | AH4: 2026
C5: =TEXT(WEEKDAY(DATE(Marzo!CalendarioAño,1,4),1),"ddd") -> dom | D5: =TEXT(WEEKDAY(DATE(Marzo!CalendarioAño,1,5),1),"ddd") -> lun | E5: =TEXT(WEEKDAY(DATE(Marzo!CalendarioAño,1,6),1),"ddd") -> mar | F5: =TEXT(WEEKDAY(DATE(Marzo!CalendarioAño,1,7),1),"ddd") -> mié | G5: =TEXT(WEEKDAY(DATE(Marzo!CalendarioAño,1,8),1),"ddd") -> jue | H5: =TEXT(WEEKDAY(DATE(Marzo!CalendarioAño,1,9),1),"ddd") -> vie | I5: =TEXT(WEEKDAY(DATE(Marzo!CalendarioAño,1,10),1),"ddd") -> sáb | J5: =TEXT(WEEKDAY(DATE(Marzo!CalendarioAño,1,4),1),"ddd") -> dom | K5: =TEXT(WEEKDAY(DATE(Marzo!CalendarioAño,1,5),1),"ddd") -> lun | L5: =TEXT(WEEKDAY(DATE(Marzo!CalendarioAño,1,6),1),"ddd") -> mar | M5: =TEXT(WEEKDAY(DATE(Marzo!CalendarioAño,1,7),1),"ddd") -> mié | N5: =TEXT(WEEKDAY(DATE(Marzo!CalendarioAño,1,8),1),"ddd") -> jue | O5: =TEXT(WEEKDAY(DATE(Marzo!CalendarioAño,1,9),1),"ddd") -> vie | P5: =TEXT(WEEKDAY(DATE(Marzo!CalendarioAño,1,10),1),"ddd") -> sáb | Q5: =TEXT(WEEKDAY(DATE(Marzo!CalendarioAño,1,4),1),"ddd") -> dom | R5: =TEXT(WEEKDAY(DATE(Marzo!CalendarioAño,1,5),1),"ddd") -> lun | S5: =TEXT(WEEKDAY(DATE(Marzo!CalendarioAño,1,6),1),"ddd") -> mar | T5: =TEXT(WEEKDAY(DATE(Marzo!CalendarioAño,1,7),1),"ddd") -> mié | U5: =TEXT(WEEKDAY(DATE(Marzo!CalendarioAño,1,8),1),"ddd") -> jue | V5: =TEXT(WEEKDAY(DATE(Marzo!CalendarioAño,1,9),1),"ddd") -> vie | W5: =TEXT(WEEKDAY(DATE(Marzo!CalendarioAño,1,10),1),"ddd") -> sáb | X5: =TEXT(WEEKDAY(DATE(Marzo!CalendarioAño,1,4),1),"ddd") -> dom | Y5: =TEXT(WEEKDAY(DATE(Marzo!CalendarioAño,1,5),1),"ddd") -> lun | Z5: =TEXT(WEEKDAY(DATE(Marzo!CalendarioAño,1,6),1),"ddd") -> mar | AA5: =TEXT(WEEKDAY(DATE(Marzo!CalendarioAño,1,7),1),"ddd") -> mié | AB5: =TEXT(WEEKDAY(DATE(Marzo!CalendarioAño,1,8),1),"ddd") -> jue | AC5: =TEXT(WEEKDAY(DATE(Marzo!CalendarioAño,1,9),1),"ddd") -> vie | AD5: =TEXT(WEEKDAY(DATE(Marzo!CalendarioAño,1,10),1),"ddd") -> sáb | AE5: =TEXT(WEEKDAY(DATE(Marzo!CalendarioAño,1,4),1),"ddd") -> dom | AF5: =TEXT(WEEKDAY(DATE(Marzo!CalendarioAño,1,5),1),"ddd") -> lun | AG5: =TEXT(WEEKDAY(DATE(Marzo!CalendarioAño,1,6),1),"ddd") -> mar
B6: NOMBRE Y APELLIDO | C6: 1 | D6: 2 | E6: 3 | F6: 4 | G6: 5 | H6: 6 | I6: 7 | J6: 8 | K6: 9 | L6: 10 | M6: 11 | N6: 12 | O6: 13 | P6: 14 | Q6: 15 | R6: 16 | S6: 17 | T6: 18 | U6: 19 | V6: 20 | W6: 21 | X6: 22 | Y6: 23 | Z6: 24 | AA6: 25 | AB6: 26 | AC6: 27 | AD6: 28 | AE6: 29 | AF6: 30 | AG6: 31 | AH6: Número total de días
B8: =Marzo!MonthName&" Total" -> Marzo Total | C8: =SUBTOTAL(103,Marzo!$C$7) -> 0 | D8: =SUBTOTAL(103,Marzo!$D$7) -> 0 | E8: =SUBTOTAL(103,Marzo!$E$7) -> 0 | F8: =SUBTOTAL(103,Marzo!$F$7) -> 0 | G8: =SUBTOTAL(103,Marzo!$G$7) -> 0 | H8: =SUBTOTAL(103,Marzo!$H$7) -> 0 | I8: =SUBTOTAL(103,Marzo!$I$7) -> 0 | J8: =SUBTOTAL(103,Marzo!$J$7) -> 0 | K8: =SUBTOTAL(103,Marzo!$K$7) -> 0 | L8: =SUBTOTAL(103,Marzo!$L$7) -> 0 | M8: =SUBTOTAL(103,Marzo!$M$7) -> 0 | N8: =SUBTOTAL(103,Marzo!$N$7) -> 0 | O8: =SUBTOTAL(103,Marzo!$O$7) -> 0 | P8: =SUBTOTAL(103,Marzo!$P$7) -> 0 | Q8: =SUBTOTAL(103,Marzo!$Q$7) -> 0 | R8: =SUBTOTAL(103,Marzo!$R$7) -> 0 | S8: =SUBTOTAL(103,Marzo!$S$7) -> 0 | T8: =SUBTOTAL(103,Marzo!$T$7) -> 0 | U8: =SUBTOTAL(103,Marzo!$U$7) -> 0 | V8: =SUBTOTAL(103,Marzo!$V$7) -> 0 | W8: =SUBTOTAL(103,Marzo!$W$7) -> 0 | X8: =SUBTOTAL(103,Marzo!$X$7) -> 0 | Y8: =SUBTOTAL(103,Marzo!$Y$7) -> 0 | Z8: =SUBTOTAL(103,Marzo!$Z$7) -> 0 | AA8: =SUBTOTAL(103,Marzo!$AA$7) -> 0 | AB8: =SUBTOTAL(103,Marzo!$AB$7) -> 0 | AC8: =SUBTOTAL(103,Marzo!$AC$7) -> 0 | AD8: =SUBTOTAL(103,Marzo!$AD$7) -> 0 | AE8: =SUBTOTAL(103,Marzo!$AE$7) -> 0 | AF8: =SUBTOTAL(103,Marzo!$AF$7) -> 0 | AG8: =SUBTOTAL(103,Marzo!$AG$7) -> 0
B10: Marzo | C10: SUPER BABY WOLF 3:30 PM/9:30 AM | AH10: 2026
C11: =TEXT(WEEKDAY(DATE(Marzo!CalendarioAño,1,4),1),"ddd") -> dom | D11: =TEXT(WEEKDAY(DATE(Marzo!CalendarioAño,1,5),1),"ddd") -> lun | E11: =TEXT(WEEKDAY(DATE(Marzo!CalendarioAño,1,6),1),"ddd") -> mar | F11: =TEXT(WEEKDAY(DATE(Marzo!CalendarioAño,1,7),1),"ddd") -> mié | G11: =TEXT(WEEKDAY(DATE(Marzo!CalendarioAño,1,8),1),"ddd") -> jue | H11: =TEXT(WEEKDAY(DATE(Marzo!CalendarioAño,1,9),1),"ddd") -> vie | I11: =TEXT(WEEKDAY(DATE(Marzo!CalendarioAño,1,10),1),"ddd") -> sáb | J11: =TEXT(WEEKDAY(DATE(Marzo!CalendarioAño,1,4),1),"ddd") -> dom | K11: =TEXT(WEEKDAY(DATE(Marzo!CalendarioAño,1,5),1),"ddd") -> lun | L11: =TEXT(WEEKDAY(DATE(Marzo!CalendarioAño,1,6),1),"ddd") -> mar | M11: =TEXT(WEEKDAY(DATE(Marzo!CalendarioAño,1,7),1),"ddd") -> mié | N11: =TEXT(WEEKDAY(DATE(Marzo!CalendarioAño,1,8),1),"ddd") -> jue | O11: =TEXT(WEEKDAY(DATE(Marzo!CalendarioAño,1,9),1),"ddd") -> vie | P11: =TEXT(WEEKDAY(DATE(Marzo!CalendarioAño,1,10),1),"ddd") -> sáb | Q11: =TEXT(WEEKDAY(DATE(Marzo!CalendarioAño,1,4),1),"ddd") -> dom | R11: =TEXT(WEEKDAY(DATE(Marzo!CalendarioAño,1,5),1),"ddd") -> lun | S11: =TEXT(WEEKDAY(DATE(Marzo!CalendarioAño,1,6),1),"ddd") -> mar | T11: =TEXT(WEEKDAY(DATE(Marzo!CalendarioAño,1,7),1),"ddd") -> mié | U11: =TEXT(WEEKDAY(DATE(Marzo!CalendarioAño,1,8),1),"ddd") -> jue | V11: =TEXT(WEEKDAY(DATE(Marzo!CalendarioAño,1,9),1),"ddd") -> vie | W11: =TEXT(WEEKDAY(DATE(Marzo!CalendarioAño,1,10),1),"ddd") -> sáb | X11: =TEXT(WEEKDAY(DATE(Marzo!CalendarioAño,1,4),1),"ddd") -> dom | Y11: =TEXT(WEEKDAY(DATE(Marzo!CalendarioAño,1,5),1),"ddd") -> lun | Z11: =TEXT(WEEKDAY(DATE(Marzo!CalendarioAño,1,6),1),"ddd") -> mar | AA11: =TEXT(WEEKDAY(DATE(Marzo!CalendarioAño,1,7),1),"ddd") -> mié | AB11: =TEXT(WEEKDAY(DATE(Marzo!CalendarioAño,1,8),1),"ddd") -> jue | AC11: =TEXT(WEEKDAY(DATE(Marzo!CalendarioAño,1,9),1),"ddd") -> vie | AD11: =TEXT(WEEKDAY(DATE(Marzo!CalendarioAño,1,10),1),"ddd") -> sáb | AE11: =TEXT(WEEKDAY(DATE(Marzo!CalendarioAño,1,4),1),"ddd") -> dom | AF11: =TEXT(WEEKDAY(DATE(Marzo!CalendarioAño,1,5),1),"ddd") -> lun | AG11: =TEXT(WEEKDAY(DATE(Marzo!CalendarioAño,1,6),1),"ddd") -> mar
B12: NOMBRE Y APELLIDO | C12: 1 | D12: 2 | E12: 3 | F12: 4 | G12: 5 | H12: 6 | I12: 7 | J12: 8 | K12: 9 | L12: 10 | M12: 11 | N12: 12 | O12: 13 | P12: 14 | Q12: 15 | R12: 16 | S12: 17 | T12: 18 | U12: 19 | V12: 20 | W12: 21 | X12: 22 | Y12: 23 | Z12: 24 | AA12: 25 | AB12: 26 | AC12: 27 | AD12: 28 | AE12: 29 | AF12: 30 | AG12: 31 | AH12: Número total de días
B13: RAFAEL ALEJANDRO LUYO ALVARADO | F13: A | G13: A | H13: A | K13: A | O13: A | P13: A | R13: A | S13: A | Z13: A | AA13: A | AB13: A | AC13: A | AF13: A | AG13: A
B14: OLIVIA GOÑES SERNA
B15: NOHA CASTILLO PRADO | G15: A | K15: A | R15: A | U15: A | Y15: A | AB15: A | AF15: A
B16: ANIA SILVA CHÁVEZ | E16: A | G16: A | L16: A | S16: A | Z16: A | AB16: A | AG16: A
B17: ADRIANA CLAUDIA ALVARADO ALVAREZ | G17: A | H17: A | O17: A | R17: A | T17: A | V17: A | Y17: A | AF17: A | AG17: A
B18: ALESSIA VALENTINA ROJAS DÍAZ | F18: A | H18: A | T18: A | V18: A | Z18: A | AC18: A
B19: JULEN EZEQUIEL GORAN RAMÍREZ MAQUERS | G19: A | H19: A | P19: A | R19: A | W19: A
B20: ADRIEL RAZEK ALFARO HUAMANI | G20: A
B21: VASCO ALEJANDRO QUEVEDO OROZ
B22: MATTHEW GAEL ORTIZ OLAYA
B23: LUCIANA CELESTE BERNIS SAMAME | G23: A | O23: A | S23: A | U23: A | Z23: A | AF23: A | AG23: A
B24: ISSAC DARITH ALVARADO OLIVARES | H24: A | O24: A | W24: A | AC24: A
B25: ALHANNA ATHENEA HUAMANI CORTIJO
B26: GABRIEL ANDRÉS CASTAÑEDA CÁCERES | H26: A | O26: A | Z26: A | AC26: A
B27: AARON ALESSANDRO INGA ARZAPALO | G27: A | R27: A
B28: JULIETA MALDONADO GUEVARA
B29: ANTONELLA ZEA ESPINOZA | P29: A | Y29: A | AG29: A
B30: MATT JESÚS AURES GUTIÉRREZ | E30: A | G30: A | S30: A | U30: A | Z30: A | AB30: A
B31: GETZENN VELIT AYALA | E31: A | G31: A | L31: A | U31: A | Z31: A | AD31: A
B32: GAIA EMMA MENACHO ALVAREZ | E32: A | H32: A | L32: A | S32: A | U32: A
B33: PABLO STEFANO MAZUELOS LUPACA | E33: A | S33: A | U33: A | Z33: A | AB33: A | AG33: A
B34: GABRIEL SANCHEZ CABELLO | E34: A | T34: A | W34: A | Z34: A | AB34: A | AG34: A
B35: MARCELO SUAREZ FLORES | P35: A | W35: A | AD35: A
B36: LUCA OTOYA CUSTODIO | T36: A | AA36: A | AF36: A
B37: JOAQUIN IGNACIO CARBAJAL ESPINOZA | W37: A | AD37: A
B39: =Marzo!MonthName&" Total" -> Marzo Total | C39: =SUBTOTAL(103,Marzo!$C$7) -> 0 | D39: =SUBTOTAL(103,Marzo!$D$7) -> 0 | E39: =SUBTOTAL(103,Marzo!$E$7) -> 0 | G39: =SUBTOTAL(103,Marzo!$G$7) -> 0 | H39: =SUBTOTAL(103,Marzo!$H$7) -> 0
B42: Marzo | C42: SUPER BABY WOLF 4:00 PM /10:00 AM | AH42: 2026
C43: =TEXT(WEEKDAY(DATE(Marzo!CalendarioAño,1,4),1),"ddd") -> dom | D43: =TEXT(WEEKDAY(DATE(Marzo!CalendarioAño,1,5),1),"ddd") -> lun | E43: =TEXT(WEEKDAY(DATE(Marzo!CalendarioAño,1,6),1),"ddd") -> mar | F43: =TEXT(WEEKDAY(DATE(Marzo!CalendarioAño,1,7),1),"ddd") -> mié | G43: =TEXT(WEEKDAY(DATE(Marzo!CalendarioAño,1,8),1),"ddd") -> jue | H43: =TEXT(WEEKDAY(DATE(Marzo!CalendarioAño,1,9),1),"ddd") -> vie | I43: =TEXT(WEEKDAY(DATE(Marzo!CalendarioAño,1,10),1),"ddd") -> sáb | J43: =TEXT(WEEKDAY(DATE(Marzo!CalendarioAño,1,4),1),"ddd") -> dom | K43: =TEXT(WEEKDAY(DATE(Marzo!CalendarioAño,1,5),1),"ddd") -> lun | L43: =TEXT(WEEKDAY(DATE(Marzo!CalendarioAño,1,6),1),"ddd") -> mar | M43: =TEXT(WEEKDAY(DATE(Marzo!CalendarioAño,1,7),1),"ddd") -> mié | N43: =TEXT(WEEKDAY(DATE(Marzo!CalendarioAño,1,8),1),"ddd") -> jue | O43: =TEXT(WEEKDAY(DATE(Marzo!CalendarioAño,1,9),1),"ddd") -> vie | P43: =TEXT(WEEKDAY(DATE(Marzo!CalendarioAño,1,10),1),"ddd") -> sáb | Q43: =TEXT(WEEKDAY(DATE(Marzo!CalendarioAño,1,4),1),"ddd") -> dom | R43: =TEXT(WEEKDAY(DATE(Marzo!CalendarioAño,1,5),1),"ddd") -> lun | S43: =TEXT(WEEKDAY(DATE(Marzo!CalendarioAño,1,6),1),"ddd") -> mar | T43: =TEXT(WEEKDAY(DATE(Marzo!CalendarioAño,1,7),1),"ddd") -> mié | U43: =TEXT(WEEKDAY(DATE(Marzo!CalendarioAño,1,8),1),"ddd") -> jue | V43: =TEXT(WEEKDAY(DATE(Marzo!CalendarioAño,1,9),1),"ddd") -> vie | W43: =TEXT(WEEKDAY(DATE(Marzo!CalendarioAño,1,10),1),"ddd") -> sáb | X43: =TEXT(WEEKDAY(DATE(Marzo!CalendarioAño,1,4),1),"ddd") -> dom | Y43: =TEXT(WEEKDAY(DATE(Marzo!CalendarioAño,1,5),1),"ddd") -> lun | Z43: =TEXT(WEEKDAY(DATE(Marzo!CalendarioAño,1,6),1),"ddd") -> mar | AA43: =TEXT(WEEKDAY(DATE(Marzo!CalendarioAño,1,7),1),"ddd") -> mié | AB43: =TEXT(WEEKDAY(DATE(Marzo!CalendarioAño,1,8),1),"ddd") -> jue | AC43: =TEXT(WEEKDAY(DATE(Marzo!CalendarioAño,1,9),1),"ddd") -> vie | AD43: =TEXT(WEEKDAY(DATE(Marzo!CalendarioAño,1,10),1),"ddd") -> sáb | AE43: =TEXT(WEEKDAY(DATE(Marzo!CalendarioAño,1,4),1),"ddd") -> dom | AF43: =TEXT(WEEKDAY(DATE(Marzo!CalendarioAño,1,5),1),"ddd") -> lun | AG43: =TEXT(WEEKDAY(DATE(Marzo!CalendarioAño,1,6),1),"ddd") -> mar
B44: NOMBRE Y APELLIDO | C44: 1 | D44: 2 | E44: 3 | F44: 4 | G44: 5 | H44: 6 | I44: 7 | J44: 8 | K44: 9 | L44: 10 | M44: 11 | N44: 12 | O44: 13 | P44: 14 | Q44: 15 | R44: 16 | S44: 17 | T44: 18 | U44: 19 | V44: 20 | W44: 21 | X44: 22 | Y44: 23 | Z44: 24 | AA44: 25 | AB44: 26 | AC44: 27 | AD44: 28 | AE44: 29 | AF44: 30 | AG44: 31 | AH44: Número total de días
B45: ALEJANDRO JOAQUÍN TELLO SALAS | F45: A | H45: A | K45: A | O45: A | R45: A | Y45: A | AA45: A
B46: ETHAN LIAM EDUARDO CHICCHON APAZA | E46: A | G46: A | Y46: A
...

Sheet Abril
B1: ASISTENCIA DE ALUMNOS
B2: Claves de los tipos de Asistencia | C2: F | D2: FALTAS | G2: J | H2: JUSTIFICADA | K2: A | L2: ASISTENCIA | O2: R | P2: RECUPERACION | T2: E | U2: EVENTOS
B4: Abril | C4: MEGA SUPER BABY WOLF 3:00 PM/9:00 AM | AG4: 2026
C5: =TEXT(WEEKDAY(DATE(Abril!CalendarioAño,1,7),1),"ddd") -> mié | D5: =TEXT(WEEKDAY(DATE(Abril!CalendarioAño,1,8),1),"ddd") -> jue | E5: =TEXT(WEEKDAY(DATE(Abril!CalendarioAño,1,9),1),"ddd") -> vie | F5: =TEXT(WEEKDAY(DATE(Abril!CalendarioAño,1,10),1),"ddd") -> sáb | G5: =TEXT(WEEKDAY(DATE(Abril!CalendarioAño,1,11),1),"ddd") -> dom | H5: =TEXT(WEEKDAY(DATE(Abril!CalendarioAño,1,12),1),"ddd") -> lun | I5: =TEXT(WEEKDAY(DATE(Abril!CalendarioAño,1,13),1),"ddd") -> mar | J5: =TEXT(WEEKDAY(DATE(Abril!CalendarioAño,1,14),1),"ddd") -> mié | K5: =TEXT(WEEKDAY(DATE(Abril!CalendarioAño,1,15),1),"ddd") -> jue | L5: =TEXT(WEEKDAY(DATE(Abril!CalendarioAño,1,16),1),"ddd") -> vie | M5: =TEXT(WEEKDAY(DATE(Abril!CalendarioAño,1,17),1),"ddd") -> sáb | N5: =TEXT(WEEKDAY(DATE(Abril!CalendarioAño,1,18),1),"ddd") -> dom | O5: =TEXT(WEEKDAY(DATE(Abril!CalendarioAño,1,19),1),"ddd") -> lun | P5: =TEXT(WEEKDAY(DATE(Abril!CalendarioAño,1,20),1),"ddd") -> mar | Q5: =TEXT(WEEKDAY(DATE(Abril!CalendarioAño,1,21),1),"ddd") -> mié | R5: =TEXT(WEEKDAY(DATE(Abril!CalendarioAño,1,22),1),"ddd") -> jue | S5: =TEXT(WEEKDAY(DATE(Abril!CalendarioAño,1,23),1),"ddd") -> vie | T5: =TEXT(WEEKDAY(DATE(Abril!CalendarioAño,1,24),1),"ddd") -> sáb | U5: =TEXT(WEEKDAY(DATE(Abril!CalendarioAño,1,25),1),"ddd") -> dom | V5: =TEXT(WEEKDAY(DATE(Abril!CalendarioAño,1,26),1),"ddd") -> lun | W5: =TEXT(WEEKDAY(DATE(Abril!CalendarioAño,1,27),1),"ddd") -> mar | X5: =TEXT(WEEKDAY(DATE(Abril!CalendarioAño,1,28),1),"ddd") -> mié | Y5: =TEXT(WEEKDAY(DATE(Abril!CalendarioAño,1,29),1),"ddd") -> jue | Z5: =TEXT(WEEKDAY(DATE(Abril!CalendarioAño,1,30),1),"ddd") -> vie | AA5: =TEXT(WEEKDAY(DATE(Abril!CalendarioAño,1,31),1),"ddd") -> sáb | AB5: =TEXT(WEEKDAY(DATE(Abril!CalendarioAño,1,25),1),"ddd") -> dom | AC5: =TEXT(WEEKDAY(DATE(Abril!CalendarioAño,1,26),1),"ddd") -> lun | AD5: =TEXT(WEEKDAY(DATE(Abril!CalendarioAño,1,27),1),"ddd") -> mar | AE5: =TEXT(WEEKDAY(DATE(Abril!CalendarioAño,1,28),1),"ddd") -> mié | AF5: =TEXT(WEEKDAY(DATE(Abril!CalendarioAño,1,29),1),"ddd") -> jue
B6: NOMBRE Y APELLIDO | C6: 1 | D6: 2 | E6: 3 | F6: 4 | G6: 5 | H6: 6 | I6: 7 | J6: 8 | K6: 9 | L6: 10 | M6: 11 | N6: 12 | O6: 13 | P6: 14 | Q6: 15 | R6: 16 | S6: 17 | T6: 18 | U6: 19 | V6: 20 | W6: 21 | X6: 22 | Y6: 23 | Z6: 24 | AA6: 25 | AB6: 26 | AC6: 27 | AD6: 28 | AE6: 29 | AF6: 30 | AG6: Número total de días
B8: =Abril!MonthName&" Total" -> Abril Total | C8: =SUBTOTAL(103,Abril!$C$7) -> 0 | D8: =SUBTOTAL(103,Abril!$D$7) -> 0 | E8: =SUBTOTAL(103,Abril!$E$7) -> 0 | F8: =SUBTOTAL(103,Abril!$F$7) -> 0 | G8: =SUBTOTAL(103,Abril!$G$7) -> 0 | H8: =SUBTOTAL(103,Abril!$H$7) -> 0 | I8: =SUBTOTAL(103,Abril!$I$7) -> 0 | J8: =SUBTOTAL(103,Abril!$J$7) -> 0 | K8: =SUBTOTAL(103,Abril!$K$7) -> 0 | L8: =SUBTOTAL(103,Abril!$L$7) -> 0 | M8: =SUBTOTAL(103,Abril!$M$7) -> 0 | N8: =SUBTOTAL(103,Abril!$N$7) -> 0 | O8: =SUBTOTAL(103,Abril!$O$7) -> 0 | P8: =SUBTOTAL(103,Abril!$P$7) -> 0 | Q8: =SUBTOTAL(103,Abril!$Q$7) -> 0 | R8: =SUBTOTAL(103,Abril!$R$7) -> 0 | S8: =SUBTOTAL(103,Abril!$S$7) -> 0 | T8: =SUBTOTAL(103,Abril!$T$7) -> 0 | U8: =SUBTOTAL(103,Abril!$U$7) -> 0 | V8: =SUBTOTAL(103,Abril!$V$7) -> 0 | W8: =SUBTOTAL(103,Abril!$W$7) -> 0 | X8: =SUBTOTAL(103,Abril!$X$7) -> 0 | Y8: =SUBTOTAL(103,Abril!$Y$7) -> 0 | Z8: =SUBTOTAL(103,Abril!$Z$7) -> 0 | AA8: =SUBTOTAL(103,Abril!$AA$7) -> 0 | AB8: =SUBTOTAL(103,Abril!$AB$7) -> 0 | AC8: =SUBTOTAL(103,Abril!$AC$7) -> 0 | AD8: =SUBTOTAL(103,Abril!$AD$7) -> 0 | AE8: =SUBTOTAL(103,Abril!$AE$7) -> 0 | AF8: =SUBTOTAL(103,Abril!$AF$7) -> 0
B10: Abril | C10: SUPER BABY WOLF 3:30 PM/9:30 AM | AG10: 2026
C11: =TEXT(WEEKDAY(DATE(Abril!CalendarioAño,1,7),1),"ddd") -> mié | D11: =TEXT(WEEKDAY(DATE(Abril!CalendarioAño,1,8),1),"ddd") -> jue | E11: =TEXT(WEEKDAY(DATE(Abril!CalendarioAño,1,9),1),"ddd") -> vie | F11: =TEXT(WEEKDAY(DATE(Abril!CalendarioAño,1,10),1),"ddd") -> sáb | G11: =TEXT(WEEKDAY(DATE(Abril!CalendarioAño,1,11),1),"ddd") -> dom | H11: =TEXT(WEEKDAY(DATE(Abril!CalendarioAño,1,12),1),"ddd") -> lun | I11: =TEXT(WEEKDAY(DATE(Abril!CalendarioAño,1,13),1),"ddd") -> mar | J11: =TEXT(WEEKDAY(DATE(Abril!CalendarioAño,1,14),1),"ddd") -> mié | K11: =TEXT(WEEKDAY(DATE(Abril!CalendarioAño,1,15),1),"ddd") -> jue | L11: =TEXT(WEEKDAY(DATE(Abril!CalendarioAño,1,16),1),"ddd") -> vie | M11: =TEXT(WEEKDAY(DATE(Abril!CalendarioAño,1,17),1),"ddd") -> sáb | N11: =TEXT(WEEKDAY(DATE(Abril!CalendarioAño,1,18),1),"ddd") -> dom | O11: =TEXT(WEEKDAY(DATE(Abril!CalendarioAño,1,19),1),"ddd") -> lun | P11: =TEXT(WEEKDAY(DATE(Abril!CalendarioAño,1,20),1),"ddd") -> mar | Q11: =TEXT(WEEKDAY(DATE(Abril!CalendarioAño,1,21),1),"ddd") -> mié | R11: =TEXT(WEEKDAY(DATE(Abril!CalendarioAño,1,22),1),"ddd") -> jue | S11: =TEXT(WEEKDAY(DATE(Abril!CalendarioAño,1,23),1),"ddd") -> vie | T11: =TEXT(WEEKDAY(DATE(Abril!CalendarioAño,1,24),1),"ddd") -> sáb | U11: =TEXT(WEEKDAY(DATE(Abril!CalendarioAño,1,25),1),"ddd") -> dom | V11: =TEXT(WEEKDAY(DATE(Abril!CalendarioAño,1,26),1),"ddd") -> lun | W11: =TEXT(WEEKDAY(DATE(Abril!CalendarioAño,1,27),1),"ddd") -> mar | X11: =TEXT(WEEKDAY(DATE(Abril!CalendarioAño,1,28),1),"ddd") -> mié | Y11: =TEXT(WEEKDAY(DATE(Abril!CalendarioAño,1,29),1),"ddd") -> jue | Z11: =TEXT(WEEKDAY(DATE(Abril!CalendarioAño,1,30),1),"ddd") -> vie | AA11: =TEXT(WEEKDAY(DATE(Abril!CalendarioAño,1,31),1),"ddd") -> sáb | AB11: =TEXT(WEEKDAY(DATE(Abril!CalendarioAño,1,25),1),"ddd") -> dom | AC11: =TEXT(WEEKDAY(DATE(Abril!CalendarioAño,1,26),1),"ddd") -> lun | AD11: =TEXT(WEEKDAY(DATE(Abril!CalendarioAño,1,27),1),"ddd") -> mar | AE11: =TEXT(WEEKDAY(DATE(Abril!CalendarioAño,1,28),1),"ddd") -> mié | AF11: =TEXT(WEEKDAY(DATE(Abril!CalendarioAño,1,29),1),"ddd") -> jue
B12: NOMBRE Y APELLIDO | C12: 1 | D12: 2 | E12: 3 | F12: 4 | G12: 5 | H12: 6 | I12: 7 | J12: 8 | K12: 9 | L12: 10 | M12: 11 | N12: 12 | O12: 13 | P12: 14 | Q12: 15 | R12: 16 | S12: 17 | T12: 18 | U12: 19 | V12: 20 | W12: 21 | X12: 22 | Y12: 23 | Z12: 24 | AA12: 25 | AB12: 26 | AC12: 27 | AD12: 28 | AE12: 29 | AF12: 30 | AG12: Número total de días
B13: RAFAEL ALEJANDRO LUYO ALVARADO | H13: A | I13: A | J13: A | K13: A
B14: LUCA OTOYA CUSTODIO | H14: A | J14: A | K14: A
B15: NOHA CASTILLO PRADO | H15: A
B16: ADRIANA CLAUDIA ALVARADO ALVAREZ | H16: A
B17: LUCIANA CELESTE BERNIS SAMAME | I17: A
B18: PABLO STEFANO MAZUELOS LUPACA | I18: A
B19: RAFAELA MIRANDA HUAMANCHA CAMONES | J19: A
B20: ALESSIA VALENTINA ROJAS DÍAZ | J20: A
B34: =Abril!MonthName&" Total" -> Abril Total | C34: =SUBTOTAL(103,Abril!$C$7) -> 0 | D34: =SUBTOTAL(103,Abril!$D$7) -> 0 | E34: =SUBTOTAL(103,Abril!$E$7) -> 0 | G34: =SUBTOTAL(103,Abril!$G$7) -> 0 | H34: =SUBTOTAL(103,Abril!$H$7) -> 0
B37: Abril | C37: SUPER BABY WOLF 4:00 PM /10:00 AM | AG37: 2026
C38: =TEXT(WEEKDAY(DATE(Abril!CalendarioAño,1,7),1),"ddd") -> mié | D38: =TEXT(WEEKDAY(DATE(Abril!CalendarioAño,1,8),1),"ddd") -> jue | E38: =TEXT(WEEKDAY(DATE(Abril!CalendarioAño,1,9),1),"ddd") -> vie | F38: =TEXT(WEEKDAY(DATE(Abril!CalendarioAño,1,10),1),"ddd") -> sáb | G38: =TEXT(WEEKDAY(DATE(Abril!CalendarioAño,1,11),1),"ddd") -> dom | H38: =TEXT(WEEKDAY(DATE(Abril!CalendarioAño,1,12),1),"ddd") -> lun | I38: =TEXT(WEEKDAY(DATE(Abril!CalendarioAño,1,13),1),"ddd") -> mar | J38: =TEXT(WEEKDAY(DATE(Abril!CalendarioAño,1,14),1),"ddd") -> mié | K38: =TEXT(WEEKDAY(DATE(Abril!CalendarioAño,1,15),1),"ddd") -> jue | L38: =TEXT(WEEKDAY(DATE(Abril!CalendarioAño,1,16),1),"ddd") -> vie | M38: =TEXT(WEEKDAY(DATE(Abril!CalendarioAño,1,17),1),"ddd") -> sáb | N38: =TEXT(WEEKDAY(DATE(Abril!CalendarioAño,1,18),1),"ddd") -> dom | O38: =TEXT(WEEKDAY(DATE(Abril!CalendarioAño,1,19),1),"ddd") -> lun | P38: =TEXT(WEEKDAY(DATE(Abril!CalendarioAño,1,20),1),"ddd") -> mar | Q38: =TEXT(WEEKDAY(DATE(Abril!CalendarioAño,1,21),1),"ddd") -> mié | R38: =TEXT(WEEKDAY(DATE(Abril!CalendarioAño,1,22),1),"ddd") -> jue | S38: =TEXT(WEEKDAY(DATE(Abril!CalendarioAño,1,23),1),"ddd") -> vie | T38: =TEXT(WEEKDAY(DATE(Abril!CalendarioAño,1,24),1),"ddd") -> sáb | U38: =TEXT(WEEKDAY(DATE(Abril!CalendarioAño,1,25),1),"ddd") -> dom | V38: =TEXT(WEEKDAY(DATE(Abril!CalendarioAño,1,26),1),"ddd") -> lun | W38: =TEXT(WEEKDAY(DATE(Abril!CalendarioAño,1,27),1),"ddd") -> mar | X38: =TEXT(WEEKDAY(DATE(Abril!CalendarioAño,1,28),1),"ddd") -> mié | Y38: =TEXT(WEEKDAY(DATE(Abril!CalendarioAño,1,29),1),"ddd") -> jue | Z38: =TEXT(WEEKDAY(DATE(Abril!CalendarioAño,1,30),1),"ddd") -> vie | AA38: =TEXT(WEEKDAY(DATE(Abril!CalendarioAño,1,31),1),"ddd") -> sáb | AB38: =TEXT(WEEKDAY(DATE(Abril!CalendarioAño,1,25),1),"ddd") -> dom | AC38: =TEXT(WEEKDAY(DATE(Abril!CalendarioAño,1,26),1),"ddd") -> lun | AD38: =TEXT(WEEKDAY(DATE(Abril!CalendarioAño,1,27),1),"ddd") -> mar | AE38: =TEXT(WEEKDAY(DATE(Abril!CalendarioAño,1,28),1),"ddd") -> mié | AF38: =TEXT(WEEKDAY(DATE(Abril!CalendarioAño,1,29),1),"ddd") -> jue
B39: NOMBRE Y APELLIDO | C39: 1 | D39: 2 | E39: 3 | F39: 4 | G39: 5 | H39: 6 | I39: 7 | J39: 8 | K39: 9 | L39: 10 | M39: 11 | N39: 12 | O39: 13 | P39: 14 | Q39: 15 | R39: 16 | S39: 17 | T39: 18 | U39: 19 | V39: 20 | W39: 21 | X39: 22 | Y39: 23 | Z39: 24 | AA39: 25 | AB39: 26 | AC39: 27 | AD39: 28 | AE39: 29 | AF39: 30 | AG39: Número total de días
B40: JULIAN BENJAMIN CUEVA LOAYZA | H40: A | J40: A
B41: BENJAMIN MERA | H41: A
B42: MARÍA FERNANDA ELERA REY | I42: A
B43: SANTIAGO MAJU | I43: A
B44: BENJAMIN ROMERO | I44: A
B45: AITANA POLO MERCADO | I45: A
B46: ADAEL GUTIERREZ URETA | J46: A
B47: VILMA GEORGINA PUMA ESTRADA | J47: A
B48: LUKA DEREK HUAMAN CASAS | J48: A | K48: A
B49: MATT JESÚS AURES GUTIÉRREZ | I49: A
B50: GETZENN VELIT AYALA | I50: A
B51: ANIA SILVA CHÁVEZ | I51: A
B62: =Abril!MonthName&" Total" -> Abril Total | C62: =SUBTOTAL(103,Abril!$C$7) -> 0 | D62: =SUBTOTAL(103,Abril!$D$7) -> 0 | E62: =SUBTOTAL(103,Abril!$E$7) -> 0 | G62: =SUBTOTAL(103,Abril!$G$7) -> 0
B64: Abril | C64: BABY WOLF 4:30 PM/10:30 | AG64: 2026
C65: =TEXT(WEEKDAY(DATE(Abril!CalendarioAño,1,7),1),"ddd") -> mié | D65: =TEXT(WEEKDAY(DATE(Abril!CalendarioAño,1,8),1),"ddd") -> jue | E65: =TEXT(WEEKDAY(DATE(Abril!CalendarioAño,1,9),1),"ddd") -> vie | F65: =TEXT(WEEKDAY(DATE(Abril!CalendarioAño,1,10),1),"ddd") -> sáb | G65: =TEXT(WEEKDAY(DATE(Abril!CalendarioAño,1,11),1),"ddd") -> dom | H65: =TEXT(WEEKDAY(DATE(Abril!CalendarioAño,1,12),1),"ddd") -> lun | I65: =TEXT(WEEKDAY(DATE(Abril!CalendarioAño,1,13),1),"ddd") -> mar | J65: =TEXT(WEEKDAY(DATE(Abril!CalendarioAño,1,14),1),"ddd") -> mié | K65: =TEXT(WEEKDAY(DATE(Abril!CalendarioAño,1,15),1),"ddd") -> jue | L65: =TEXT(WEEKDAY(DATE(Abril!CalendarioAño,1,16),1),"ddd") -> vie | M65: =TEXT(WEEKDAY(DATE(Abril!CalendarioAño,1,17),1),"ddd") -> sáb | N65: =TEXT(WEEKDAY(DATE(Abril!CalendarioAño,1,18),1),"ddd") -> dom | O65: =TEXT(WEEKDAY(DATE(Abril!CalendarioAño,1,19),1),"ddd") -> lun | P65: =TEXT(WEEKDAY(DATE(Abril!CalendarioAño,1,20),1),"ddd") -> mar | Q65: =TEXT(WEEKDAY(DATE(Abril!CalendarioAño,1,21),1),"ddd") -> mié | R65: =TEXT(WEEKDAY(DATE(Abril!CalendarioAño,1,22),1),"ddd") -> jue | S65: =TEXT(WEEKDAY(DATE(Abril!CalendarioAño,1,23),1),"ddd") -> vie | T65: =TEXT(WEEKDAY(DATE(Abril!CalendarioAño,1,24),1),"ddd") -> sáb | U65: =TEXT(WEEKDAY(DATE(Abril!CalendarioAño,1,25),1),"ddd") -> dom | V65: =TEXT(WEEKDAY(DATE(Abril!CalendarioAño,1,26),1),"ddd") -> lun | W65: =TEXT(WEEKDAY(DATE(Abril!CalendarioAño,1,27),1),"ddd") -> mar | X65: =TEXT(WEEKDAY(DATE(Abril!CalendarioAño,1,28),1),"ddd") -> mié | Y65: =TEXT(WEEKDAY(DATE(Abril!CalendarioAño,1,29),1),"ddd") -> jue | Z65: =TEXT(WEEKDAY(DATE(Abril!CalendarioAño,1,30),1),"ddd") -> vie | AA65: =TEXT(WEEKDAY(DATE(Abril!CalendarioAño,1,31),1),"ddd") -> sáb | AB65: =TEXT(WEEKDAY(DATE(Abril!CalendarioAño,1,25),1),"ddd") -> dom | AC65: =TEXT(WEEKDAY(DATE(Abril!CalendarioAño,1,26),1),"ddd") -> lun | AD65: =TEXT(WEEKDAY(DATE(Abril!CalendarioAño,1,27),1),"ddd") -> mar | AE65: =TEXT(WEEKDAY(DATE(Abril!CalendarioAño,1,28),1),"ddd") -> mié | AF65: =TEXT(WEEKDAY(DATE(Abril!CalendarioAño,1,29),1),"ddd") -> jue
B66: NOMBRE Y APELLIDO | C66: 1 | D66: 2 | E66: 3 | F66: 4 | G66: 5 | H66: 6 | I66: 7 | J66: 8 | K66: 9 | L66: 10 | M66: 11 | N66: 12 | O66: 13 | P66: 14 | Q66: 15 | R66: 16 | S66: 17 | T66: 18 | U66: 19 | V66: 20 | W66: 21 | X66: 22 | Y66: 23 | Z66: 24 | AA66: 25 | AB66: 26 | AC66: 27 | AD66: 28 | AE66: 29 | AF66: 30 | AG66: Número total de días
B67: RAFAELA MIRANDA HUAMANCHA CAMONES | H67: A
B68: LUKA DEREK HUAMAN CASAS | H68: A | I68: A
B69: NICOLAS ORDONEZ NORIEDA | H69: A | J69: A
...

Sheet Mayo
B1: ASISTENCIA DE ALUMNOS
B2: Claves de los tipos de Asistencia | C2: F | D2: FALTAS | G2: J | H2: JUSTIFICADA | K2: A | L2: ASISTENCIA | O2: R | P2: RECUPERACION | T2: E | U2: EVENTOS
B4: Enero | C4: MEGA SUPER BABY WOLF 3:00 PM/9:00 AM | AH4: 2026
C5: =TEXT(WEEKDAY(DATE(Mayo!CalendarioAño,1,1),1),"ddd") -> jue | D5: =TEXT(WEEKDAY(DATE(Mayo!CalendarioAño,1,2),1),"ddd") -> vie | E5: =TEXT(WEEKDAY(DATE(Mayo!CalendarioAño,1,3),1),"ddd") -> sáb | F5: =TEXT(WEEKDAY(DATE(Mayo!CalendarioAño,1,4),1),"ddd") -> dom | G5: =TEXT(WEEKDAY(DATE(Mayo!CalendarioAño,1,5),1),"ddd") -> lun | H5: =TEXT(WEEKDAY(DATE(Mayo!CalendarioAño,1,6),1),"ddd") -> mar | I5: =TEXT(WEEKDAY(DATE(Mayo!CalendarioAño,1,7),1),"ddd") -> mié | J5: =TEXT(WEEKDAY(DATE(Mayo!CalendarioAño,1,8),1),"ddd") -> jue | K5: =TEXT(WEEKDAY(DATE(Mayo!CalendarioAño,1,9),1),"ddd") -> vie | L5: =TEXT(WEEKDAY(DATE(Mayo!CalendarioAño,1,10),1),"ddd") -> sáb | M5: =TEXT(WEEKDAY(DATE(Mayo!CalendarioAño,1,11),1),"ddd") -> dom | N5: =TEXT(WEEKDAY(DATE(Mayo!CalendarioAño,1,12),1),"ddd") -> lun | O5: =TEXT(WEEKDAY(DATE(Mayo!CalendarioAño,1,13),1),"ddd") -> mar | P5: =TEXT(WEEKDAY(DATE(Mayo!CalendarioAño,1,14),1),"ddd") -> mié | Q5: =TEXT(WEEKDAY(DATE(Mayo!CalendarioAño,1,15),1),"ddd") -> jue | R5: =TEXT(WEEKDAY(DATE(Mayo!CalendarioAño,1,16),1),"ddd") -> vie | S5: =TEXT(WEEKDAY(DATE(Mayo!CalendarioAño,1,17),1),"ddd") -> sáb | T5: =TEXT(WEEKDAY(DATE(Mayo!CalendarioAño,1,18),1),"ddd") -> dom | U5: =TEXT(WEEKDAY(DATE(Mayo!CalendarioAño,1,19),1),"ddd") -> lun | V5: =TEXT(WEEKDAY(DATE(Mayo!CalendarioAño,1,20),1),"ddd") -> mar | W5: =TEXT(WEEKDAY(DATE(Mayo!CalendarioAño,1,21),1),"ddd") -> mié | X5: =TEXT(WEEKDAY(DATE(Mayo!CalendarioAño,1,22),1),"ddd") -> jue | Y5: =TEXT(WEEKDAY(DATE(Mayo!CalendarioAño,1,23),1),"ddd") -> vie | Z5: =TEXT(WEEKDAY(DATE(Mayo!CalendarioAño,1,24),1),"ddd") -> sáb | AA5: =TEXT(WEEKDAY(DATE(Mayo!CalendarioAño,1,25),1),"ddd") -> dom | AB5: =TEXT(WEEKDAY(DATE(Mayo!CalendarioAño,1,26),1),"ddd") -> lun | AC5: =TEXT(WEEKDAY(DATE(Mayo!CalendarioAño,1,27),1),"ddd") -> mar | AD5: =TEXT(WEEKDAY(DATE(Mayo!CalendarioAño,1,28),1),"ddd") -> mié | AE5: =TEXT(WEEKDAY(DATE(Mayo!CalendarioAño,1,29),1),"ddd") -> jue | AF5: =TEXT(WEEKDAY(DATE(Mayo!CalendarioAño,1,30),1),"ddd") -> vie | AG5: =TEXT(WEEKDAY(DATE(Mayo!CalendarioAño,1,31),1),"ddd") -> sáb
B6: NOMBRE Y APELLIDO | C6: 1 | D6: 2 | E6: 3 | F6: 4 | G6: 5 | H6: 6 | I6: 7 | J6: 8 | K6: 9 | L6: 10 | M6: 11 | N6: 12 | O6: 13 | P6: 14 | Q6: 15 | R6: 16 | S6: 17 | T6: 18 | U6: 19 | V6: 20 | W6: 21 | X6: 22 | Y6: 23 | Z6: 24 | AA6: 25 | AB6: 26 | AC6: 27 | AD6: 28 | AE6: 29 | AF6: 30 | AG6: 31 | AH6: Número total de días
B8: =Mayo!MonthName&" Total" -> Enero Total | C8: =SUBTOTAL(103,Mayo!$C$7) -> 0 | D8: =SUBTOTAL(103,Mayo!$D$7) -> 0 | E8: =SUBTOTAL(103,Mayo!$E$7) -> 0 | F8: =SUBTOTAL(103,Mayo!$F$7) -> 0 | G8: =SUBTOTAL(103,Mayo!$G$7) -> 0 | H8: =SUBTOTAL(103,Mayo!$H$7) -> 0 | I8: =SUBTOTAL(103,Mayo!$I$7) -> 0 | J8: =SUBTOTAL(103,Mayo!$J$7) -> 0 | K8: =SUBTOTAL(103,Mayo!$K$7) -> 0 | L8: =SUBTOTAL(103,Mayo!$L$7) -> 0 | M8: =SUBTOTAL(103,Mayo!$M$7) -> 0 | N8: =SUBTOTAL(103,Mayo!$N$7) -> 0 | O8: =SUBTOTAL(103,Mayo!$O$7) -> 0 | P8: =SUBTOTAL(103,Mayo!$P$7) -> 0 | Q8: =SUBTOTAL(103,Mayo!$Q$7) -> 0 | R8: =SUBTOTAL(103,Mayo!$R$7) -> 0 | S8: =SUBTOTAL(103,Mayo!$S$7) -> 0 | T8: =SUBTOTAL(103,Mayo!$T$7) -> 0 | U8: =SUBTOTAL(103,Mayo!$U$7) -> 0 | V8: =SUBTOTAL(103,Mayo!$V$7) -> 0 | W8: =SUBTOTAL(103,Mayo!$W$7) -> 0 | X8: =SUBTOTAL(103,Mayo!$X$7) -> 0 | Y8: =SUBTOTAL(103,Mayo!$Y$7) -> 0 | Z8: =SUBTOTAL(103,Mayo!$Z$7) -> 0 | AA8: =SUBTOTAL(103,Mayo!$AA$7) -> 0 | AB8: =SUBTOTAL(103,Mayo!$AB$7) -> 0 | AC8: =SUBTOTAL(103,Mayo!$AC$7) -> 0 | AD8: =SUBTOTAL(103,Mayo!$AD$7) -> 0 | AE8: =SUBTOTAL(103,Mayo!$AE$7) -> 0 | AF8: =SUBTOTAL(103,Mayo!$AF$7) -> 0 | AG8: =SUBTOTAL(103,Mayo!$AG$7) -> 0
B10: Enero | C10: SUPER BABY WOLF 3:30 PM/9:30 AM | AH10: 2026
C11: =TEXT(WEEKDAY(DATE(Mayo!CalendarioAño,1,1),1),"ddd") -> jue | D11: =TEXT(WEEKDAY(DATE(Mayo!CalendarioAño,1,2),1),"ddd") -> vie | E11: =TEXT(WEEKDAY(DATE(Mayo!CalendarioAño,1,3),1),"ddd") -> sáb | F11: =TEXT(WEEKDAY(DATE(Mayo!CalendarioAño,1,4),1),"ddd") -> dom | G11: =TEXT(WEEKDAY(DATE(Mayo!CalendarioAño,1,5),1),"ddd") -> lun | H11: =TEXT(WEEKDAY(DATE(Mayo!CalendarioAño,1,6),1),"ddd") -> mar | I11: =TEXT(WEEKDAY(DATE(Mayo!CalendarioAño,1,7),1),"ddd") -> mié | J11: =TEXT(WEEKDAY(DATE(Mayo!CalendarioAño,1,8),1),"ddd") -> jue | K11: =TEXT(WEEKDAY(DATE(Mayo!CalendarioAño,1,9),1),"ddd") -> vie | L11: =TEXT(WEEKDAY(DATE(Mayo!CalendarioAño,1,10),1),"ddd") -> sáb | M11: =TEXT(WEEKDAY(DATE(Mayo!CalendarioAño,1,11),1),"ddd") -> dom | N11: =TEXT(WEEKDAY(DATE(Mayo!CalendarioAño,1,12),1),"ddd") -> lun | O11: =TEXT(WEEKDAY(DATE(Mayo!CalendarioAño,1,13),1),"ddd") -> mar | P11: =TEXT(WEEKDAY(DATE(Mayo!CalendarioAño,1,14),1),"ddd") -> mié | Q11: =TEXT(WEEKDAY(DATE(Mayo!CalendarioAño,1,15),1),"ddd") -> jue | R11: =TEXT(WEEKDAY(DATE(Mayo!CalendarioAño,1,16),1),"ddd") -> vie | S11: =TEXT(WEEKDAY(DATE(Mayo!CalendarioAño,1,17),1),"ddd") -> sáb | T11: =TEXT(WEEKDAY(DATE(Mayo!CalendarioAño,1,18),1),"ddd") -> dom | U11: =TEXT(WEEKDAY(DATE(Mayo!CalendarioAño,1,19),1),"ddd") -> lun | V11: =TEXT(WEEKDAY(DATE(Mayo!CalendarioAño,1,20),1),"ddd") -> mar | W11: =TEXT(WEEKDAY(DATE(Mayo!CalendarioAño,1,21),1),"ddd") -> mié | X11: =TEXT(WEEKDAY(DATE(Mayo!CalendarioAño,1,22),1),"ddd") -> jue | Y11: =TEXT(WEEKDAY(DATE(Mayo!CalendarioAño,1,23),1),"ddd") -> vie | Z11: =TEXT(WEEKDAY(DATE(Mayo!CalendarioAño,1,24),1),"ddd") -> sáb | AA11: =TEXT(WEEKDAY(DATE(Mayo!CalendarioAño,1,25),1),"ddd") -> dom | AB11: =TEXT(WEEKDAY(DATE(Mayo!CalendarioAño,1,26),1),"ddd") -> lun | AC11: =TEXT(WEEKDAY(DATE(Mayo!CalendarioAño,1,27),1),"ddd") -> mar | AD11: =TEXT(WEEKDAY(DATE(Mayo!CalendarioAño,1,28),1),"ddd") -> mié | AE11: =TEXT(WEEKDAY(DATE(Mayo!CalendarioAño,1,29),1),"ddd") -> jue | AF11: =TEXT(WEEKDAY(DATE(Mayo!CalendarioAño,1,30),1),"ddd") -> vie | AG11: =TEXT(WEEKDAY(DATE(Mayo!CalendarioAño,1,31),1),"ddd") -> sáb
B12: NOMBRE Y APELLIDO | C12: 1 | D12: 2 | E12: 3 | F12: 4 | G12: 5 | H12: 6 | I12: 7 | J12: 8 | K12: 9 | L12: 10 | M12: 11 | N12: 12 | O12: 13 | P12: 14 | Q12: 15 | R12: 16 | S12: 17 | T12: 18 | U12: 19 | V12: 20 | W12: 21 | X12: 22 | Y12: 23 | Z12: 24 | AA12: 25 | AB12: 26 | AC12: 27 | AD12: 28 | AE12: 29 | AF12: 30 | AG12: 31 | AH12: Número total de días
B34: =Mayo!MonthName&" Total" -> Enero Total | C34: =SUBTOTAL(103,Mayo!$C$7) -> 0 | D34: =SUBTOTAL(103,Mayo!$D$7) -> 0 | E34: =SUBTOTAL(103,Mayo!$E$7) -> 0 | G34: =SUBTOTAL(103,Mayo!$G$7) -> 0 | H34: =SUBTOTAL(103,Mayo!$H$7) -> 0
B37: Enero | C37: SUPER BABY WOLF 4:00 PM /10:00 AM | AH37: 2026
C38: =TEXT(WEEKDAY(DATE(Mayo!CalendarioAño,1,1),1),"ddd") -> jue | D38: =TEXT(WEEKDAY(DATE(Mayo!CalendarioAño,1,2),1),"ddd") -> vie | E38: =TEXT(WEEKDAY(DATE(Mayo!CalendarioAño,1,3),1),"ddd") -> sáb | F38: =TEXT(WEEKDAY(DATE(Mayo!CalendarioAño,1,4),1),"ddd") -> dom | G38: =TEXT(WEEKDAY(DATE(Mayo!CalendarioAño,1,5),1),"ddd") -> lun | H38: =TEXT(WEEKDAY(DATE(Mayo!CalendarioAño,1,6),1),"ddd") -> mar | I38: =TEXT(WEEKDAY(DATE(Mayo!CalendarioAño,1,7),1),"ddd") -> mié | J38: =TEXT(WEEKDAY(DATE(Mayo!CalendarioAño,1,8),1),"ddd") -> jue | K38: =TEXT(WEEKDAY(DATE(Mayo!CalendarioAño,1,9),1),"ddd") -> vie | L38: =TEXT(WEEKDAY(DATE(Mayo!CalendarioAño,1,10),1),"ddd") -> sáb | M38: =TEXT(WEEKDAY(DATE(Mayo!CalendarioAño,1,11),1),"ddd") -> dom | N38: =TEXT(WEEKDAY(DATE(Mayo!CalendarioAño,1,12),1),"ddd") -> lun | O38: =TEXT(WEEKDAY(DATE(Mayo!CalendarioAño,1,13),1),"ddd") -> mar | P38: =TEXT(WEEKDAY(DATE(Mayo!CalendarioAño,1,14),1),"ddd") -> mié | Q38: =TEXT(WEEKDAY(DATE(Mayo!CalendarioAño,1,15),1),"ddd") -> jue | R38: =TEXT(WEEKDAY(DATE(Mayo!CalendarioAño,1,16),1),"ddd") -> vie | S38: =TEXT(WEEKDAY(DATE(Mayo!CalendarioAño,1,17),1),"ddd") -> sáb | T38: =TEXT(WEEKDAY(DATE(Mayo!CalendarioAño,1,18),1),"ddd") -> dom | U38: =TEXT(WEEKDAY(DATE(Mayo!CalendarioAño,1,19),1),"ddd") -> lun | V38: =TEXT(WEEKDAY(DATE(Mayo!CalendarioAño,1,20),1),"ddd") -> mar | W38: =TEXT(WEEKDAY(DATE(Mayo!CalendarioAño,1,21),1),"ddd") -> mié | X38: =TEXT(WEEKDAY(DATE(Mayo!CalendarioAño,1,22),1),"ddd") -> jue | Y38: =TEXT(WEEKDAY(DATE(Mayo!CalendarioAño,1,23),1),"ddd") -> vie | Z38: =TEXT(WEEKDAY(DATE(Mayo!CalendarioAño,1,24),1),"ddd") -> sáb | AA38: =TEXT(WEEKDAY(DATE(Mayo!CalendarioAño,1,25),1),"ddd") -> dom | AB38: =TEXT(WEEKDAY(DATE(Mayo!CalendarioAño,1,26),1),"ddd") -> lun | AC38: =TEXT(WEEKDAY(DATE(Mayo!CalendarioAño,1,27),1),"ddd") -> mar | AD38: =TEXT(WEEKDAY(DATE(Mayo!CalendarioAño,1,28),1),"ddd") -> mié | AE38: =TEXT(WEEKDAY(DATE(Mayo!CalendarioAño,1,29),1),"ddd") -> jue | AF38: =TEXT(WEEKDAY(DATE(Mayo!CalendarioAño,1,30),1),"ddd") -> vie | AG38: =TEXT(WEEKDAY(DATE(Mayo!CalendarioAño,1,31),1),"ddd") -> sáb
B39: NOMBRE Y APELLIDO | C39: 1 | D39: 2 | E39: 3 | F39: 4 | G39: 5 | H39: 6 | I39: 7 | J39: 8 | K39: 9 | L39: 10 | M39: 11 | N39: 12 | O39: 13 | P39: 14 | Q39: 15 | R39: 16 | S39: 17 | T39: 18 | U39: 19 | V39: 20 | W39: 21 | X39: 22 | Y39: 23 | Z39: 24 | AA39: 25 | AB39: 26 | AC39: 27 | AD39: 28 | AE39: 29 | AF39: 30 | AG39: 31 | AH39: Número total de días
B62: =Mayo!MonthName&" Total" -> Enero Total | C62: =SUBTOTAL(103,Mayo!$C$7) -> 0 | D62: =SUBTOTAL(103,Mayo!$D$7) -> 0 | E62: =SUBTOTAL(103,Mayo!$E$7) -> 0 | G62: =SUBTOTAL(103,Mayo!$G$7) -> 0
B64: Enero | C64: BABY WOLF 4:30 PM/10:30 | AH64: 2026
C65: =TEXT(WEEKDAY(DATE(Mayo!CalendarioAño,1,1),1),"ddd") -> jue | D65: =TEXT(WEEKDAY(DATE(Mayo!CalendarioAño,1,2),1),"ddd") -> vie | E65: =TEXT(WEEKDAY(DATE(Mayo!CalendarioAño,1,3),1),"ddd") -> sáb | F65: =TEXT(WEEKDAY(DATE(Mayo!CalendarioAño,1,4),1),"ddd") -> dom | G65: =TEXT(WEEKDAY(DATE(Mayo!CalendarioAño,1,5),1),"ddd") -> lun | H65: =TEXT(WEEKDAY(DATE(Mayo!CalendarioAño,1,6),1),"ddd") -> mar | I65: =TEXT(WEEKDAY(DATE(Mayo!CalendarioAño,1,7),1),"ddd") -> mié | J65: =TEXT(WEEKDAY(DATE(Mayo!CalendarioAño,1,8),1),"ddd") -> jue | K65: =TEXT(WEEKDAY(DATE(Mayo!CalendarioAño,1,9),1),"ddd") -> vie | L65: =TEXT(WEEKDAY(DATE(Mayo!CalendarioAño,1,10),1),"ddd") -> sáb | M65: =TEXT(WEEKDAY(DATE(Mayo!CalendarioAño,1,11),1),"ddd") -> dom | N65: =TEXT(WEEKDAY(DATE(Mayo!CalendarioAño,1,12),1),"ddd") -> lun | O65: =TEXT(WEEKDAY(DATE(Mayo!CalendarioAño,1,13),1),"ddd") -> mar | P65: =TEXT(WEEKDAY(DATE(Mayo!CalendarioAño,1,14),1),"ddd") -> mié | Q65: =TEXT(WEEKDAY(DATE(Mayo!CalendarioAño,1,15),1),"ddd") -> jue | R65: =TEXT(WEEKDAY(DATE(Mayo!CalendarioAño,1,16),1),"ddd") -> vie | S65: =TEXT(WEEKDAY(DATE(Mayo!CalendarioAño,1,17),1),"ddd") -> sáb | T65: =TEXT(WEEKDAY(DATE(Mayo!CalendarioAño,1,18),1),"ddd") -> dom | U65: =TEXT(WEEKDAY(DATE(Mayo!CalendarioAño,1,19),1),"ddd") -> lun | V65: =TEXT(WEEKDAY(DATE(Mayo!CalendarioAño,1,20),1),"ddd") -> mar | W65: =TEXT(WEEKDAY(DATE(Mayo!CalendarioAño,1,21),1),"ddd") -> mié | X65: =TEXT(WEEKDAY(DATE(Mayo!CalendarioAño,1,22),1),"ddd") -> jue | Y65: =TEXT(WEEKDAY(DATE(Mayo!CalendarioAño,1,23),1),"ddd") -> vie | Z65: =TEXT(WEEKDAY(DATE(Mayo!CalendarioAño,1,24),1),"ddd") -> sáb | AA65: =TEXT(WEEKDAY(DATE(Mayo!CalendarioAño,1,25),1),"ddd") -> dom | AB65: =TEXT(WEEKDAY(DATE(Mayo!CalendarioAño,1,26),1),"ddd") -> lun | AC65: =TEXT(WEEKDAY(DATE(Mayo!CalendarioAño,1,27),1),"ddd") -> mar | AD65: =TEXT(WEEKDAY(DATE(Mayo!CalendarioAño,1,28),1),"ddd") -> mié | AE65: =TEXT(WEEKDAY(DATE(Mayo!CalendarioAño,1,29),1),"ddd") -> jue | AF65: =TEXT(WEEKDAY(DATE(Mayo!CalendarioAño,1,30),1),"ddd") -> vie | AG65: =TEXT(WEEKDAY(DATE(Mayo!CalendarioAño,1,31),1),"ddd") -> sáb
